Workbook

Sheet Instructions
A1: THE LANDRY FAMILY EQUITY INVESTMENT OPERATING SYSTEM — STOCK SCORING & PORTFOLIO RISK WORKBOOK
A3: Companion workbook to Landry System v1.0. Aligned to: Version 1.0 (49 Hard Rules, Parts 1–12).
A4: If the Word document's rule numbers ever change in a future revision, check this line and the rule
A5: references throughout this workbook before relying on them.
A7: HOW TO USE THIS WORKBOOK
A8: 1. Market Data tab — enter or refresh price, volume, market cap, P/E, 52-week range, and dividend
A9: yield for each tracked ticker. Blue cells only. See that tab's note on optional live-data refresh.
A10: 2. Scoring tab — during a scoring session, enter each Tier 1/2/3 indicator's score (1–5) and Confidence
A11: tag (H/M/L) per Part 2's rubrics. The Composite Score, decision classification, and hard-rule flags
A12: (Rules 1–4) calculate automatically.
A13: 3. Dashboard tab — read-only summary of every tracked stock, sortable by Composite Score.
A14: 4. Price History / Returns (Calc) / Correlation Matrix tabs — enter monthly closing prices for up to 12
... A35: See the Schema Reference tab (last tab) for the exact column layout of every tab -- built for handoff to Claude Code or any future programmatic access.

Sheet Action Items
A1: ACTION ITEMS — everything requiring your decision, pulled live from every other tab. Everything else in this workbook is reference; this is what to open.
A2: Refresh by opening the workbook (F9 recalculates); all cells below are live formulas, nothing here is typed.
A4: 1. WATCH LIST — Rules 31-34 (see Watch List Tracker tab for detail)
A5: Deadlines passed (sell required within 30 days): | E5: =COUNTIF('Watch List Tracker'!K3:K22,"*SELL WITHIN 30 DAYS*") -> 0
A6: Deadlines approaching (within 14 days): | E6: =COUNTIF('Watch List Tracker'!K3:K22,"DEADLINE APPROACHING") -> 0
A7: Recovered — ready to remove/reclassify: | E7: =COUNTIF('Watch List Tracker'!K3:K22,"*RECOVERED*") -> 0
A9: 2. ACTIVE SELL TRIGGERS — Rules 21-30 (see Holding Monitor tab for detail)
A10: Holdings with action required within 30 days: | E10: =COUNTIF('Holding Monitor'!AB4:AB23,"*ACTION REQUIRED*") -> 0
A11: Holdings under Hold Through (monitor only, no action): | E11: =COUNTIF('Holding Monitor'!AB4:AB23,"*Hold Through*") -> 0
A13: 3. CORRELATION CAP — Rule 36 (see Correlation Matrix tab for detail)
A14: Rule 36 status: | E14: ='Correlation Matrix'!B17
A15: Positions exceeding cap: | E15: ='Correlation Matrix'!B16
A17: 4. PORTFOLIO DRAWDOWN STATUS — Rule 37 (see Portfolio Drawdown Log tab for detail)
A18: Most recent recorded status: | E18: =IFERROR(INDEX('Portfolio Drawdown Log'!E3:E42,COUNT('Portfolio Drawdown Log'!D3:D42)),"No entries yet")
A19: Most recent drawdown %: | E19: =IFERROR(INDEX('Portfolio Drawdown Log'!D3:D42,COUNT('Portfolio Drawdown Log'!D3:D42)),"")
A20: Required cash floor at this level: | E20: =IFERROR(INDEX('Portfolio Drawdown Log'!F3:F42,COUNT('Portfolio Drawdown Log'!D3:D42)),"")
A22: 5. CANDIDATE SCORING FLAGS — Rules 1-4 (see Scoring tab for detail)
A23: Candidates failing the Tier 1 floor, 3.0 (Rule 1): | E23: =COUNTIF(Scoring!AH3:AH27,"FAIL") -> 3
A24: Candidates auto-classified Avoid (Rule 3): | E24: =COUNTIF(Scoring!AJ3:AJ27,"AVOID") -> 3
A25: Candidates flagged for mandatory Tier 1 review (Rule 2): | E25: =COUNTIF(Scoring!AI3:AI27,"REVIEW") -> 2
A26: Candidates capped at Buy despite Strong Buy score (Rule 4): | E26: =COUNTIF(Scoring!AK3:AK27,"CAP AT BUY") -> 0
A27: 6. ENTRY AUTHORIZATION — Rules 5-13 (see Entry Checklist tab for detail)
A28: Candidates NOT authorized to enter (failing one or more Entry Rules): | E28: =COUNTIF('Entry Checklist'!Q3:Q27,"NO*") -> 0
A29: Candidates authorized, staged at reduced size (50%, per Rules 8-9): | E29: =COUNTIF('Entry Checklist'!H3:H27,"*50%*") -> 0

Sheet Current Positions
A1: Combined current positions, both accounts, as of 08/05/2026 (JT ULTRA, Fidelity) and 08/04/2026 (Self-Directed, Chase — cash sweep custodied at Schwab, swept to VMFXX for yield). Source: uploaded brokerage exports, aggregated by ticker. Update this tab at each quarterly/annual review; use it with Part 5 sizing modifiers and the Holding Monitor tab to prescribe classifications and follow-up actions. | O1: TAX-LOSS CARRYFORWARD (update annually)
A2: Account | B2: Ticker | C2: Description | D2: Asset Class | E2: Quantity | F2: Price ($) | G2: Market Value ($) | H2: Cost Basis ($) | I2: Unrealized G/L ($) | J2: Unrealized G/L (%) | K2: % of Account | L2: % of Combined Portfolio | M2: Classification / Notes (fill at review) | O2: Short-Term Loss Carryforward:
A3: JT ULTRA (Fidelity) | B3: ADBE | C3: Adobe Inc. | D3: Equity | E3: 45 | F3: 259.32 | G3: =E3*F3 -> 11669.4 | H3: 13836.24 | I3: =G3-H3 -> -2166.84 | J3: =IF(H3=0,"",G3/H3-1) -> -0.15660613 | K3: =G3/SUM(G3:G14) -> 0.028908948 | L3: =G3/SUM(G3:G14,G17:G35) -> 0.016652986 | O3: Long-Term Loss Carryforward:
A4: JT ULTRA (Fidelity) | B4: ANET | C4: Arista Networks | D4: Equity | E4: 70 | F4: 197.31 | G4: =E4*F4 -> 13811.7 | H4: 10182.2 | I4: =G4-H4 -> 3629.5 | J4: =IF(H4=0,"",G4/H4-1) -> 0.35645538 | K4: =G4/SUM(G3:G14) -> 0.03421613 | L4: =G4/SUM(G3:G14,G17:G35) -> 0.019710186
A5: JT ULTRA (Fidelity) | B5: ASML | C5: ASML Holding | D5: Equity | E5: 7 | F5: 1678.22 | G5: =E5*F5 -> 11747.54 | H5: 9989.88 | I5: =G5-H5 -> 1757.66 | J5: =IF(H5=0,"",G5/H5-1) -> 0.17594406 | K5: =G5/SUM(G3:G14) -> 0.029102526 | L5: =G5/SUM(G3:G14,G17:G35) -> 0.016764497
A6: JT ULTRA (Fidelity) | B6: CRWD | C6: CrowdStrike Holdings | D6: Equity | E6: 40 | F6: 209.86 | G6: =E6*F6 -> 8394.4 | H6: 4991.35 | I6: =G6-H6 -> 3403.05 | J6: =IF(H6=0,"",G6/H6-1) -> 0.6817895 | K6: =G6/SUM(G3:G14) -> 0.020795694 | L6: =G6/SUM(G3:G14,G17:G35) -> 0.01197935
A7: JT ULTRA (Fidelity) | B7: KLAC | C7: KLA Corporation | D7: Equity | E7: 100 | F7: 192.8 | G7: =E7*F7 -> 19280 | H7: 15412.54 | I7: =G7-H7 -> 3867.46 | J7: =IF(H7=0,"",G7/H7-1) -> 0.25092944 | K7: =G7/SUM(G3:G14) -> 0.047762911 | L7: =G7/SUM(G3:G14,G17:G35) -> 0.027513803
A8: JT ULTRA (Fidelity) | B8: MU | C8: Micron Technology | D8: Equity | E8: 7 | F8: 893.19 | G8: =E8*F8 -> 6252.33 | H8: 5836.11 | I8: =G8-H8 -> 416.22 | J8: =IF(H8=0,"",G8/H8-1) -> 0.071318053 | K8: =G8/SUM(G3:G14) -> 0.015489081 | L8: =G8/SUM(G3:G14,G17:G35) -> 0.008922478
A9: JT ULTRA (Fidelity) | B9: NVDA | C9: NVIDIA Corporation | D9: Equity | E9: 155 | F9: 219.22 | G9: =E9*F9 -> 33979.1 | H9: 26639.79 | I9: =G9-H9 -> 7339.31 | J9: =IF(H9=0,"",G9/H9-1) -> 0.2755018 | K9: =G9/SUM(G3:G14) -> 0.084177423 | L9: =G9/SUM(G3:G14,G17:G35) -> 0.048490366
A10: JT ULTRA (Fidelity) | B10: PLTR | C10: Palantir Technologies | D10: Equity | E10: 70 | F10: 158.43 | G10: =E10*F10 -> 11090.1 | H10: 11612.3 | I10: =G10-H10 -> -522.2 | J10: =IF(H10=0,"",G10/H10-1) -> -0.044969558 | K10: =G10/SUM(G3:G14) -> 0.027473831 | L10: =G10/SUM(G3:G14,G17:G35) -> 0.015826288
A11: JT ULTRA (Fidelity) | B11: TSM | C11: Taiwan Semiconductor | D11: Equity | E11: 25 | F11: 414 | G11: =E11*F11 -> 10350 | H11: 6069.64 | I11: =G11-H11 -> 4280.36 | J11: =IF(H11=0,"",G11/H11-1) -> 0.70520822 | K11: =G11/SUM(G3:G14) -> 0.025640359 | L11: =G11/SUM(G3:G14,G17:G35) -> 0.014770117
A12: JT ULTRA (Fidelity) | B12: VRT | C12: Vertiv Holdings | D12: Equity | E12: 30 | F12: 277.94 | G12: =E12*F12 -> 8338.2 | H12: 7876.8 | I12: =G12-H12 -> 461.4 | J12: =IF(H12=0,"",G12/H12-1) -> 0.058577087 | K12: =G12/SUM(G3:G14) -> 0.020656468 | L12: =G12/SUM(G3:G14,G17:G35) -> 0.011899149
A13: JT ULTRA (Fidelity) | B13: FZDXX | C13: Fidelity Money Market Premium | D13: Cash | E13: 249948.16 | F13: 1 | G13: =E13*F13 -> 249948.16 | H13: 249948.16 | I13: =G13-H13 -> 0 | J13: =IF(H13=0,"",G13/H13-1) -> 0 | K13: =G13/SUM(G3:G14) -> 0.61920393 | L13: =G13/SUM(G3:G14,G17:G35) -> 0.35669214
A14: JT ULTRA (Fidelity) | B14: FZFXX | C14: Fidelity Core Money Market | D14: Cash | E14: 18799.56 | F14: 1 | G14: =E14*F14 -> 18799.56 | H14: 18799.56 | I14: =G14-H14 -> 0 | J14: =IF(H14=0,"",G14/H14-1) -> 0 | K14: =G14/SUM(G3:G14) -> 0.046572703 | L14: =G14/SUM(G3:G14,G17:G35) -> 0.026828184
C15: JT ULTRA (Fidelity) SUBTOTAL | G15: =SUM(G3:G14) -> 403660.49 | H15: =SUM(H3:H14) -> 381194.57 | I15: =SUM(I3:I14) -> 22465.92
A17: Self-Directed (Chase) | B17: VMFXX | C17: Vanguard Federal Money Market | D17: Cash | E17: 75832.09 | F17: 1 | G17: =E17*F17 -> 75832.09 | H17: 75832.09 | I17: =G17-H17 -> 0 | J17: =IF(H17=0,"",G17/H17-1) -> 0 | K17: =G17/SUM(G17:G35) -> 0.25525926 | L17: =G17/SUM(G3:G14,G17:G35) -> 0.10821728
A18: Self-Directed (Chase) | B18: JEPQ | C18: JPMorgan Nasdaq Equity Premium Income ETF | D18: Alternative Assets | E18: 840.4376 | F18: 59.56 | G18: =E18*F18 -> 50056.463 | H18: 42412.88 | I18: =G18-H18 -> 7643.5835 | J18: =IF(H18=0,"",G18/H18-1) -> 0.18021845 | K18: =G18/SUM(G17:G35) -> 0.16849563 | L18: =G18/SUM(G3:G14,G17:G35) -> 0.071433801
A19: Self-Directed (Chase) | B19: AVUV | C19: Avantis US Small Cap Value ETF | D19: Equity | E19: 206.4216 | F19: 128.74 | G19: =E19*F19 -> 26574.717 | H19: 20598.51 | I19: =G19-H19 -> 5976.2068 | J19: =IF(H19=0,"",G19/H19-1) -> 0.29012811 | K19: =G19/SUM(G17:G35) -> 0.089453458 | L19: =G19/SUM(G3:G14,G17:G35) -> 0.037923834
A20: Self-Directed (Chase) | B20: CALF | C20: Pacer US Small Cap Cash Cows ETF | D20: Equity | E20: 409.5467 | F20: 56.12 | G20: =E20*F20 -> 22983.761 | H20: 19073.09 | I20: =G20-H20 -> 3910.6708 | J20: =IF(H20=0,"",G20/H20-1) -> 0.20503604 | K20: =G20/SUM(G17:G35) -> 0.0773659 | L20: =G20/SUM(G3:G14,G17:G35) -> 0.032799309
A21: Self-Directed (Chase) | B21: HELO | C21: JPMorgan Hedged Equity Laddered Overlay ETF | D21: Alternative Assets | E21: 300 | F21: 69.59 | G21: =E21*F21 -> 20877 | H21: 16782 | I21: =G21-H21 -> 4095 | J21: =IF(H21=0,"",G21/H21-1) -> 0.24401144 | K21: =G21/SUM(G17:G35) -> 0.070274308 | L21: =G21/SUM(G3:G14,G17:G35) -> 0.029792825
A22: Self-Directed (Chase) | B22: AVGO | C22: Broadcom Inc. | D22: Equity | E22: 35.0759 | F22: 418.16 | G22: =E22*F22 -> 14667.338 | H22: 12653.43 | I22: =G22-H22 -> 2013.9083 | J22: =IF(H22=0,"",G22/H22-1) -> 0.15915909 | K22: =G22/SUM(G17:G35) -> 0.049371895 | L22: =G22/SUM(G3:G14,G17:G35) -> 0.020931237
A23: Self-Directed (Chase) | B23: NVDA | C23: NVIDIA Corporation | D23: Equity | E23: 59.0219 | F23: 211.87 | G23: =E23*F23 -> 12504.97 | H23: 11377.73 | I23: =G23-H23 -> 1127.24 | J23: =IF(H23=0,"",G23/H23-1) -> 0.09907424 | K23: =G23/SUM(G17:G35) -> 0.042093122 | L23: =G23/SUM(G3:G14,G17:G35) -> 0.017845398
A24: Self-Directed (Chase) | B24: VRTX | C24: Vertex Pharmaceuticals | D24: Equity | E24: 25 | F24: 478.7 | G24: =E24*F24 -> 11967.5 | H24: 11348.3 | I24: =G24-H24 -> 619.2 | J24: =IF(H24=0,"",G24/H24-1) -> 0.054563239 | K24: =G24/SUM(G17:G35) -> 0.040283939 | L24: =G24/SUM(G3:G14,G17:G35) -> 0.017078394 | M24: HOLD -- re-scored 75.6 BUY 8/7/26; original Avoid was based on bad FCF source data, corrected
A25: Self-Directed (Chase) | B25: SPMO | C25: Invesco S&P 500 Momentum ETF | D25: Equity | E25: 76.9374 | F25: 151.16 | G25: =E25*F25 -> 11629.857 | H25: 9318.79 | I25: =G25-H25 -> 2311.0674 | J25: =IF(H25=0,"",G25/H25-1) -> 0.2480008 | K25: =G25/SUM(G17:G35) -> 0.039147396 | L25: =G25/SUM(G3:G14,G17:G35) -> 0.016596556
A26: Self-Directed (Chase) | B26: VFLO | C26: Vanguard US Multifactor ETF | D26: Equity | E26: 200 | F26: 50.5 | G26: =E26*F26 -> 10100 | H26: 9257 | I26: =G26-H26 -> 843 | J26: =IF(H26=0,"",G26/H26-1) -> 0.09106622 | K26: =G26/SUM(G17:G35) -> 0.033997725 | L26: =G26/SUM(G3:G14,G17:G35) -> 0.014413351
A27: Self-Directed (Chase) | B27: ANET | C27: Arista Networks | D27: Equity | E27: 50 | F27: 190.51 | G27: =E27*F27 -> 9525.5 | H27: 7394.5 | I27: =G27-H27 -> 2131 | J27: =IF(H27=0,"",G27/H27-1) -> 0.28818717 | K27: =G27/SUM(G17:G35) -> 0.032063894 | L27: =G27/SUM(G3:G14,G17:G35) -> 0.013593503
A28: Self-Directed (Chase) | B28: CRWD | C28: CrowdStrike Holdings | D28: Equity | E28: 45 | F28: 211.22 | G28: =E28*F28 -> 9504.9 | H28: 7099.31 | I28: =G28-H28 -> 2405.59 | J28: =IF(H28=0,"",G28/H28-1) -> 0.33884842 | K28: =G28/SUM(G17:G35) -> 0.031994553 | L28: =G28/SUM(G3:G14,G17:G35) -> 0.013564105
A29: Self-Directed (Chase) | B29: PLD | C29: Prologis Inc. | D29: Equity | E29: 61.4484 | F29: 139.06 | G29: =E29*F29 -> 8545.0145 | H29: 7630.55 | I29: =G29-H29 -> 914.4645 | J29: =IF(H29=0,"",G29/H29-1) -> 0.11984254 | K29: =G29/SUM(G17:G35) -> 0.028763471 | L29: =G29/SUM(G3:G14,G17:G35) -> 0.012194287
A30: Self-Directed (Chase) | B30: SFM | C30: Sprouts Farmers Market | D30: Equity | E30: 0 | F30: 86.07 | G30: =E30*F30 -> 0 | H30: 0 | I30: =G30-H30 -> 0 | J30: =IF(H30=0,"",G30/H30-1) | K30: =G30/SUM(G17:G35) -> 0 | L30: =G30/SUM(G3:G14,G17:G35) -> 0 | M30: SOLD 08/07/26 -- confirmed: -65 sh, $5,601.58 proceeds. Rule 3 Avoid. Proceeds added to VMFXX (row 17).
A31: Self-Directed (Chase) | B31: TSLA | C31: Tesla Inc. | D31: Equity | E31: 0 | F31: 327.35 | G31: =E31*F31 -> 0 | H31: 0 | I31: =G31-H31 -> 0 | J31: =IF(H31=0,"",G31/H31-1) | K31: =G31/SUM(G17:G35) -> 0 | L31: =G31/SUM(G3:G14,G17:G35) -> 0 | M31: SOLD 08/07/26 -- confirmed: -15 sh, $4,783.25 proceeds. Rule 3 Avoid. Proceeds added to VMFXX (row 17).
A32: Self-Directed (Chase) | B32: VGT | C32: Vanguard Information Technology ETF | D32: Equity | E32: 40.1779 | F32: 120.16 | G32: =E32*F32 -> 4827.7765 | H32: 3643.46 | I32: =G32-H32 -> 1184.3165 | J32: =IF(H32=0,"",G32/H32-1) -> 0.32505269 | K32: =G32/SUM(G17:G35) -> 0.016250834 | L32: =G32/SUM(G3:G14,G17:G35) -> 0.0068895483
A33: Self-Directed (Chase) | B33: QACDS | C33: Schwab Cash Features (Sweep) | D33: Cash | E33: 4228.61 | F33: 1 | G33: =E33*F33 -> 4228.61 | H33: 4228.61 | I33: =G33-H33 -> 0 | J33: =IF(H33=0,"",G33/H33-1) -> 0 | K33: =G33/SUM(G17:G35) -> 0.014233972 | L33: =G33/SUM(G3:G14,G17:G35) -> 0.0060344991
A34: Self-Directed (Chase) | B34: ONON | C34: On Holding AG | D34: Equity | E34: 0 | F34: 37.61 | G34: =E34*F34 -> 0 | H34: 0 | I34: =G34-H34 -> 0 | J34: =IF(H34=0,"",G34/H34-1) | K34: =G34/SUM(G17:G35) -> 0 | L34: =G34/SUM(G3:G14,G17:G35) -> 0 | M34: SOLD 08/07/26 -- confirmed: -100 sh, $3,764.92 proceeds. Rule 3 Avoid. Proceeds added to VMFXX (row 17).
A35: Self-Directed (Chase) | B35: PLTR | C35: Palantir Technologies | D35: Equity | E35: 20 | F35: 162.66 | G35: =E35*F35 -> 3253.2 | H35: 3178 | I35: =G35-H35 -> 75.2 | J35: =IF(H35=0,"",G35/H35-1) -> 0.023662681 | K35: =G35/SUM(G17:G35) -> 0.010950634 | L35: =G35/SUM(G3:G14,G17:G35) -> 0.0046425261
C36: Self-Directed (Chase) SUBTOTAL | G36: =SUM(G17:G35) -> 297078.7 | H36: =SUM(H17:H35) -> 261828.25 | I36: =SUM(I17:I35) -> 35250.448
C38: COMBINED PORTFOLIO TOTAL | G38: =SUM(G3:G14)+SUM(G17:G35) -> 700739.19 | H38: =SUM(H3:H14)+SUM(H17:H35) -> 643022.82 | I38: =SUM(I3:I14)+SUM(I17:I35) -> 57716.368
A40: NOTE: JT ULTRA's ASML/PLTR/MU quantities reflect trims already executed from the earlier rebalance session; SWAN is not currently held in this export (flagging in case that wasn't intentional). Several Self-Directed (Chase) tickers (JEPQ, AVUV, CALF, HELO, SPMO, VFLO, VGT, VRTX, PLD, SFM, ONON, TSLA) have not yet been run through the Scoring tab — that's the natural next step before classifying them.

Sheet Monitor & Recheck Triggers
A1: Recheck triggers for every name that's been scored, not just Watch List holdings. Update Current Price, Insider Activity, and Analyst Shift by hand for now (or during Claude Code automation later); Recheck Status calculates automatically from all signals together.
A2: Ticker | B2: Category | C2: Last Score Date | D2: Last Composite | E2: Last Tier 1 Wtd Avg | F2: Last Decision | G2: Price at Last Score | H2: Current Price | I2: % Price Change | J2: Next/Last Earnings Date | K2: Insider Activity? (Y/N) | L2: Insider Note | M2: Analyst Shift? (Y/N) | N2: Days Since Last Score | O2: Recheck Status | P2: Notes
A3: ADBE | B3: Owned | C3: 46240 | D3: 85.8 | E3: 4.57 | F3: STRONG BUY | G3: 259.32 | I3: =IF(OR(G3="",H3=""),"",H3/G3-1) | N3: =IF(C3="","",TODAY()-C3) -> 0 | O3: =IF(A3="","",IF(N3>180,"DUE — STALE (>180 days)",IF(J3<>"",IF(ABS(J3-TODAY())<=7,"DUE — EARNINGS WINDOW",IF(I3<>"",IF(ABS(I3)>=0.2,"DUE — PRICE MOVE ±20%",IF(K3="Y","DUE — INSIDER ACTIVITY",IF(I3<>"",IF(ABS(I3)>=0.15,"WATCH — PRICE MOVE ±15%",IF(M3="Y","WATCH — ANALYST SHIFT","Monitor Only")),IF(M3="Y","WATCH — ANALYST SHIFT","Monitor Only")))),IF(K3="Y","DUE — INSIDER ACTIVITY",IF(I3<>"",IF(ABS(I3)>=0.15,"WATCH — PRICE MOVE ±15%",IF(M3="Y","WATCH — ANALYST SHIFT","Monitor Only")),IF(M3="Y","WATCH — ANALYST SHIFT","Monitor Only"))))),IF(I3<>"",IF(ABS(I3)>=0.2,"DUE — PRICE MOVE ±20%",IF(K3="Y","DUE — INSIDER ACTIVITY",IF(I3<>"",IF(ABS(I3)>=0.15,"WATCH — PRICE MOVE ±15%",IF(M3="Y","WATCH — ANALYST SHIFT","Monitor Only")),IF(M3="Y","WATCH — ANALYST SHIFT","Monitor Only")))),IF(K3="Y","DUE — INSIDER ACTIVITY",IF(I3<>"",IF(ABS(I3)>=0.15,"WATCH — PRICE MOVE ±15%",IF(M3="Y","WATCH — ANALYST SHIFT","Monitor Only")),IF(M3="Y","WATCH — ANALYST SHIFT","Monitor Only"))))))) -> Monitor Only
A4: ANET | B4: Owned | C4: 46240 | D4: 85 | E4: 4.57 | F4: STRONG BUY | G4: 190.51 | I4: =IF(OR(G4="",H4=""),"",H4/G4-1) | N4: =IF(C4="","",TODAY()-C4) -> 0 | O4: =IF(A4="","",IF(N4>180,"DUE — STALE (>180 days)",IF(J4<>"",IF(ABS(J4-TODAY())<=7,"DUE — EARNINGS WINDOW",IF(I4<>"",IF(ABS(I4)>=0.2,"DUE — PRICE MOVE ±20%",IF(K4="Y","DUE — INSIDER ACTIVITY",IF(I4<>"",IF(ABS(I4)>=0.15,"WATCH — PRICE MOVE ±15%",IF(M4="Y","WATCH — ANALYST SHIFT","Monitor Only")),IF(M4="Y","WATCH — ANALYST SHIFT","Monitor Only")))),IF(K4="Y","DUE — INSIDER ACTIVITY",IF(I4<>"",IF(ABS(I4)>=0.15,"WATCH — PRICE MOVE ±15%",IF(M4="Y","WATCH — ANALYST SHIFT","Monitor Only")),IF(M4="Y","WATCH — ANALYST SHIFT","Monitor Only"))))),IF(I4<>"",IF(ABS(I4)>=0.2,"DUE — PRICE MOVE ±20%",IF(K4="Y","DUE — INSIDER ACTIVITY",IF(I4<>"",IF(ABS(I4)>=0.15,"WATCH — PRICE MOVE ±15%",IF(M4="Y","WATCH — ANALYST SHIFT","Monitor Only")),IF(M4="Y","WATCH — ANALYST SHIFT","Monitor Only")))),IF(K4="Y","DUE — INSIDER ACTIVITY",IF(I4<>"",IF(ABS(I4)>=0.15,"WATCH — PRICE MOVE ±15%",IF(M4="Y","WATCH — ANALYST SHIFT","Monitor Only")),IF(M4="Y","WATCH — ANALYST SHIFT","Monitor Only"))))))) -> Monitor Only
A5: ASML | B5: Owned | C5: 46240 | D5: 73.2 | E5: 3.57 | F5: BUY | G5: 1678.22 | I5: =IF(OR(G5="",H5=""),"",H5/G5-1) | N5: =IF(C5="","",TODAY()-C5) -> 0 | O5: =IF(A5="","",IF(N5>180,"DUE — STALE (>180 days)",IF(J5<>"",IF(ABS(J5-TODAY())<=7,"DUE — EARNINGS WINDOW",IF(I5<>"",IF(ABS(I5)>=0.2,"DUE — PRICE MOVE ±20%",IF(K5="Y","DUE — INSIDER ACTIVITY",IF(I5<>"",IF(ABS(I5)>=0.15,"WATCH — PRICE MOVE ±15%",IF(M5="Y","WATCH — ANALYST SHIFT","Monitor Only")),IF(M5="Y","WATCH — ANALYST SHIFT","Monitor Only")))),IF(K5="Y","DUE — INSIDER ACTIVITY",IF(I5<>"",IF(ABS(I5)>=0.15,"WATCH — PRICE MOVE ±15%",IF(M5="Y","WATCH — ANALYST SHIFT","Monitor Only")),IF(M5="Y","WATCH — ANALYST SHIFT","Monitor Only"))))),IF(I5<>"",IF(ABS(I5)>=0.2,"DUE — PRICE MOVE ±20%",IF(K5="Y","DUE — INSIDER ACTIVITY",IF(I5<>"",IF(ABS(I5)>=0.15,"WATCH — PRICE MOVE ±15%",IF(M5="Y","WATCH — ANALYST SHIFT","Monitor Only")),IF(M5="Y","WATCH — ANALYST SHIFT","Monitor Only")))),IF(K5="Y","DUE — INSIDER ACTIVITY",IF(I5<>"",IF(ABS(I5)>=0.15,"WATCH — PRICE MOVE ±15%",IF(M5="Y","WATCH — ANALYST SHIFT","Monitor Only")),IF(M5="Y","WATCH — ANALYST SHIFT","Monitor Only"))))))) -> Monitor Only
A6: CRWD | B6: Owned | C6: 46240 | D6: 70.4 | E6: 4 | F6: BUY | G6: 211.22 | I6: =IF(OR(G6="",H6=""),"",H6/G6-1) | N6: =IF(C6="","",TODAY()-C6) -> 0 | O6: =IF(A6="","",IF(N6>180,"DUE — STALE (>180 days)",IF(J6<>"",IF(ABS(J6-TODAY())<=7,"DUE — EARNINGS WINDOW",IF(I6<>"",IF(ABS(I6)>=0.2,"DUE — PRICE MOVE ±20%",IF(K6="Y","DUE — INSIDER ACTIVITY",IF(I6<>"",IF(ABS(I6)>=0.15,"WATCH — PRICE MOVE ±15%",IF(M6="Y","WATCH — ANALYST SHIFT","Monitor Only")),IF(M6="Y","WATCH — ANALYST SHIFT","Monitor Only")))),IF(K6="Y","DUE — INSIDER ACTIVITY",IF(I6<>"",IF(ABS(I6)>=0.15,"WATCH — PRICE MOVE ±15%",IF(M6="Y","WATCH — ANALYST SHIFT","Monitor Only")),IF(M6="Y","WATCH — ANALYST SHIFT","Monitor Only"))))),IF(I6<>"",IF(ABS(I6)>=0.2,"DUE — PRICE MOVE ±20%",IF(K6="Y","DUE — INSIDER ACTIVITY",IF(I6<>"",IF(ABS(I6)>=0.15,"WATCH — PRICE MOVE ±15%",IF(M6="Y","WATCH — ANALYST SHIFT","Monitor Only")),IF(M6="Y","WATCH — ANALYST SHIFT","Monitor Only")))),IF(K6="Y","DUE — INSIDER ACTIVITY",IF(I6<>"",IF(ABS(I6)>=0.15,"WATCH — PRICE MOVE ±15%",IF(M6="Y","WATCH — ANALYST SHIFT","Monitor Only")),IF(M6="Y","WATCH — ANALYST SHIFT","Monitor Only"))))))) -> Monitor Only
A7: KLAC | B7: Owned | C7: 46240 | D7: 68.6 | E7: 3.43 | F7: BUY | G7: 192.8 | I7: =IF(OR(G7="",H7=""),"",H7/G7-1) | N7: =IF(C7="","",TODAY()-C7) -> 0 | O7: =IF(A7="","",IF(N7>180,"DUE — STALE (>180 days)",IF(J7<>"",IF(ABS(J7-TODAY())<=7,"DUE — EARNINGS WINDOW",IF(I7<>"",IF(ABS(I7)>=0.2,"DUE — PRICE MOVE ±20%",IF(K7="Y","DUE — INSIDER ACTIVITY",IF(I7<>"",IF(ABS(I7)>=0.15,"WATCH — PRICE MOVE ±15%",IF(M7="Y","WATCH — ANALYST SHIFT","Monitor Only")),IF(M7="Y","WATCH — ANALYST SHIFT","Monitor Only")))),IF(K7="Y","DUE — INSIDER ACTIVITY",IF(I7<>"",IF(ABS(I7)>=0.15,"WATCH — PRICE MOVE ±15%",IF(M7="Y","WATCH — ANALYST SHIFT","Monitor Only")),IF(M7="Y","WATCH — ANALYST SHIFT","Monitor Only"))))),IF(I7<>"",IF(ABS(I7)>=0.2,"DUE — PRICE MOVE ±20%",IF(K7="Y","DUE — INSIDER ACTIVITY",IF(I7<>"",IF(ABS(I7)>=0.15,"WATCH — PRICE MOVE ±15%",IF(M7="Y","WATCH — ANALYST SHIFT","Monitor Only")),IF(M7="Y","WATCH — ANALYST SHIFT","Monitor Only")))),IF(K7="Y","DUE — INSIDER ACTIVITY",IF(I7<>"",IF(ABS(I7)>=0.15,"WATCH — PRICE MOVE ±15%",IF(M7="Y","WATCH — ANALYST SHIFT","Monitor Only")),IF(M7="Y","WATCH — ANALYST SHIFT","Monitor Only"))))))) -> Monitor Only
A8: MU | B8: Owned | C8: 46240 | D8: 71.8 | E8: 3.64 | F8: BUY | G8: 893.19 | I8: =IF(OR(G8="",H8=""),"",H8/G8-1) | N8: =IF(C8="","",TODAY()-C8) -> 0 | O8: =IF(A8="","",IF(N8>180,"DUE — STALE (>180 days)",IF(J8<>"",IF(ABS(J8-TODAY())<=7,"DUE — EARNINGS WINDOW",IF(I8<>"",IF(ABS(I8)>=0.2,"DUE — PRICE MOVE ±20%",IF(K8="Y","DUE — INSIDER ACTIVITY",IF(I8<>"",IF(ABS(I8)>=0.15,"WATCH — PRICE MOVE ±15%",IF(M8="Y","WATCH — ANALYST SHIFT","Monitor Only")),IF(M8="Y","WATCH — ANALYST SHIFT","Monitor Only")))),IF(K8="Y","DUE — INSIDER ACTIVITY",IF(I8<>"",IF(ABS(I8)>=0.15,"WATCH — PRICE MOVE ±15%",IF(M8="Y","WATCH — ANALYST SHIFT","Monitor Only")),IF(M8="Y","WATCH — ANALYST SHIFT","Monitor Only"))))),IF(I8<>"",IF(ABS(I8)>=0.2,"DUE — PRICE MOVE ±20%",IF(K8="Y","DUE — INSIDER ACTIVITY",IF(I8<>"",IF(ABS(I8)>=0.15,"WATCH — PRICE MOVE ±15%",IF(M8="Y","WATCH — ANALYST SHIFT","Monitor Only")),IF(M8="Y","WATCH — ANALYST SHIFT","Monitor Only")))),IF(K8="Y","DUE — INSIDER ACTIVITY",IF(I8<>"",IF(ABS(I8)>=0.15,"WATCH — PRICE MOVE ±15%",IF(M8="Y","WATCH — ANALYST SHIFT","Monitor Only")),IF(M8="Y","WATCH — ANALYST SHIFT","Monitor Only"))))))) -> Monitor Only
A9: NVDA | B9: Owned | C9: 46240 | D9: 93.2 | E9: 4.57 | F9: STRONG BUY | G9: 211.87 | I9: =IF(OR(G9="",H9=""),"",H9/G9-1) | N9: =IF(C9="","",TODAY()-C9) -> 0 | O9: =IF(A9="","",IF(N9>180,"DUE — STALE (>180 days)",IF(J9<>"",IF(ABS(J9-TODAY())<=7,"DUE — EARNINGS WINDOW",IF(I9<>"",IF(ABS(I9)>=0.2,"DUE — PRICE MOVE ±20%",IF(K9="Y","DUE — INSIDER ACTIVITY",IF(I9<>"",IF(ABS(I9)>=0.15,"WATCH — PRICE MOVE ±15%",IF(M9="Y","WATCH — ANALYST SHIFT","Monitor Only")),IF(M9="Y","WATCH — ANALYST SHIFT","Monitor Only")))),IF(K9="Y","DUE — INSIDER ACTIVITY",IF(I9<>"",IF(ABS(I9)>=0.15,"WATCH — PRICE MOVE ±15%",IF(M9="Y","WATCH — ANALYST SHIFT","Monitor Only")),IF(M9="Y","WATCH — ANALYST SHIFT","Monitor Only"))))),IF(I9<>"",IF(ABS(I9)>=0.2,"DUE — PRICE MOVE ±20%",IF(K9="Y","DUE — INSIDER ACTIVITY",IF(I9<>"",IF(ABS(I9)>=0.15,"WATCH — PRICE MOVE ±15%",IF(M9="Y","WATCH — ANALYST SHIFT","Monitor Only")),IF(M9="Y","WATCH — ANALYST SHIFT","Monitor Only")))),IF(K9="Y","DUE — INSIDER ACTIVITY",IF(I9<>"",IF(ABS(I9)>=0.15,"WATCH — PRICE MOVE ±15%",IF(M9="Y","WATCH — ANALYST SHIFT","Monitor Only")),IF(M9="Y","WATCH — ANALYST SHIFT","Monitor Only"))))))) -> Monitor Only
A10: PLTR | B10: Owned | C10: 46240 | D10: 75.2 | E10: 4 | F10: BUY | G10: 162.66 | I10: =IF(OR(G10="",H10=""),"",H10/G10-1) | N10: =IF(C10="","",TODAY()-C10) -> 0 | O10: =IF(A10="","",IF(N10>180,"DUE — STALE (>180 days)",IF(J10<>"",IF(ABS(J10-TODAY())<=7,"DUE — EARNINGS WINDOW",IF(I10<>"",IF(ABS(I10)>=0.2,"DUE — PRICE MOVE ±20%",IF(K10="Y","DUE — INSIDER ACTIVITY",IF(I10<>"",IF(ABS(I10)>=0.15,"WATCH — PRICE MOVE ±15%",IF(M10="Y","WATCH — ANALYST SHIFT","Monitor Only")),IF(M10="Y","WATCH — ANALYST SHIFT","Monitor Only")))),IF(K10="Y","DUE — INSIDER ACTIVITY",IF(I10<>"",IF(ABS(I10)>=0.15,"WATCH — PRICE MOVE ±15%",IF(M10="Y","WATCH — ANALYST SHIFT","Monitor Only")),IF(M10="Y","WATCH — ANALYST SHIFT","Monitor Only"))))),IF(I10<>"",IF(ABS(I10)>=0.2,"DUE — PRICE MOVE ±20%",IF(K10="Y","DUE — INSIDER ACTIVITY",IF(I10<>"",IF(ABS(I10)>=0.15,"WATCH — PRICE MOVE ±15%",IF(M10="Y","WATCH — ANALYST SHIFT","Monitor Only")),IF(M10="Y","WATCH — ANALYST SHIFT","Monitor Only")))),IF(K10="Y","DUE — INSIDER ACTIVITY",IF(I10<>"",IF(ABS(I10)>=0.15,"WATCH — PRICE MOVE ±15%",IF(M10="Y","WATCH — ANALYST SHIFT","Monitor Only")),IF(M10="Y","WATCH — ANALYST SHIFT","Monitor Only"))))))) -> Monitor Only
A11: TSM | B11: Owned | C11: 46240 | D11: 81 | E11: 4 | F11: STRONG BUY | G11: 414 | I11: =IF(OR(G11="",H11=""),"",H11/G11-1) | N11: =IF(C11="","",TODAY()-C11) -> 0 | O11: =IF(A11="","",IF(N11>180,"DUE — STALE (>180 days)",IF(J11<>"",IF(ABS(J11-TODAY())<=7,"DUE — EARNINGS WINDOW",IF(I11<>"",IF(ABS(I11)>=0.2,"DUE — PRICE MOVE ±20%",IF(K11="Y","DUE — INSIDER ACTIVITY",IF(I11<>"",IF(ABS(I11)>=0.15,"WATCH — PRICE MOVE ±15%",IF(M11="Y","WATCH — ANALYST SHIFT","Monitor Only")),IF(M11="Y","WATCH — ANALYST SHIFT","Monitor Only")))),IF(K11="Y","DUE — INSIDER ACTIVITY",IF(I11<>"",IF(ABS(I11)>=0.15,"WATCH — PRICE MOVE ±15%",IF(M11="Y","WATCH — ANALYST SHIFT","Monitor Only")),IF(M11="Y","WATCH — ANALYST SHIFT","Monitor Only"))))),IF(I11<>"",IF(ABS(I11)>=0.2,"DUE — PRICE MOVE ±20%",IF(K11="Y","DUE — INSIDER ACTIVITY",IF(I11<>"",IF(ABS(I11)>=0.15,"WATCH — PRICE MOVE ±15%",IF(M11="Y","WATCH — ANALYST SHIFT","Monitor Only")),IF(M11="Y","WATCH — ANALYST SHIFT","Monitor Only")))),IF(K11="Y","DUE — INSIDER ACTIVITY",IF(I11<>"",IF(ABS(I11)>=0.15,"WATCH — PRICE MOVE ±15%",IF(M11="Y","WATCH — ANALYST SHIFT","Monitor Only")),IF(M11="Y","WATCH — ANALYST SHIFT","Monitor Only"))))))) -> Monitor Only
A12: VRT | B12: Owned | C12: 46240 | D12: 82.8 | E12: 4.36 | F12: STRONG BUY | G12: 277.94 | I12: =IF(OR(G12="",H12=""),"",H12/G12-1) | N12: =IF(C12="","",TODAY()-C12) -> 0 | O12: =IF(A12="","",IF(N12>180,"DUE — STALE (>180 days)",IF(J12<>"",IF(ABS(J12-TODAY())<=7,"DUE — EARNINGS WINDOW",IF(I12<>"",IF(ABS(I12)>=0.2,"DUE — PRICE MOVE ±20%",IF(K12="Y","DUE — INSIDER ACTIVITY",IF(I12<>"",IF(ABS(I12)>=0.15,"WATCH — PRICE MOVE ±15%",IF(M12="Y","WATCH — ANALYST SHIFT","Monitor Only")),IF(M12="Y","WATCH — ANALYST SHIFT","Monitor Only")))),IF(K12="Y","DUE — INSIDER ACTIVITY",IF(I12<>"",IF(ABS(I12)>=0.15,"WATCH — PRICE MOVE ±15%",IF(M12="Y","WATCH — ANALYST SHIFT","Monitor Only")),IF(M12="Y","WATCH — ANALYST SHIFT","Monitor Only"))))),IF(I12<>"",IF(ABS(I12)>=0.2,"DUE — PRICE MOVE ±20%",IF(K12="Y","DUE — INSIDER ACTIVITY",IF(I12<>"",IF(ABS(I12)>=0.15,"WATCH — PRICE MOVE ±15%",IF(M12="Y","WATCH — ANALYST SHIFT","Monitor Only")),IF(M12="Y","WATCH — ANALYST SHIFT","Monitor Only")))),IF(K12="Y","DUE — INSIDER ACTIVITY",IF(I12<>"",IF(ABS(I12)>=0.15,"WATCH — PRICE MOVE ±15%",IF(M12="Y","WATCH — ANALYST SHIFT","Monitor Only")),IF(M12="Y","WATCH — ANALYST SHIFT","Monitor Only"))))))) -> Monitor Only
A13: AVGO | B13: Owned | C13: 46240 | D13: 80.8 | E13: 4.07 | F13: STRONG BUY | G13: 418.16 | I13: =IF(OR(G13="",H13=""),"",H13/G13-1) | N13: =IF(C13="","",TODAY()-C13) -> 0 | O13: =IF(A13="","",IF(N13>180,"DUE — STALE (>180 days)",IF(J13<>"",IF(ABS(J13-TODAY())<=7,"DUE — EARNINGS WINDOW",IF(I13<>"",IF(ABS(I13)>=0.2,"DUE — PRICE MOVE ±20%",IF(K13="Y","DUE — INSIDER ACTIVITY",IF(I13<>"",IF(ABS(I13)>=0.15,"WATCH — PRICE MOVE ±15%",IF(M13="Y","WATCH — ANALYST SHIFT","Monitor Only")),IF(M13="Y","WATCH — ANALYST SHIFT","Monitor Only")))),IF(K13="Y","DUE — INSIDER ACTIVITY",IF(I13<>"",IF(ABS(I13)>=0.15,"WATCH — PRICE MOVE ±15%",IF(M13="Y","WATCH — ANALYST SHIFT","Monitor Only")),IF(M13="Y","WATCH — ANALYST SHIFT","Monitor Only"))))),IF(I13<>"",IF(ABS(I13)>=0.2,"DUE — PRICE MOVE ±20%",IF(K13="Y","DUE — INSIDER ACTIVITY",IF(I13<>"",IF(ABS(I13)>=0.15,"WATCH — PRICE MOVE ±15%",IF(M13="Y","WATCH — ANALYST SHIFT","Monitor Only")),IF(M13="Y","WATCH — ANALYST SHIFT","Monitor Only")))),IF(K13="Y","DUE — INSIDER ACTIVITY",IF(I13<>"",IF(ABS(I13)>=0.15,"WATCH — PRICE MOVE ±15%",IF(M13="Y","WATCH — ANALYST SHIFT","Monitor Only")),IF(M13="Y","WATCH — ANALYST SHIFT","Monitor Only"))))))) -> Monitor Only
A14: PLD | B14: Owned | C14: 46240 | D14: 82 | E14: 4.36 | F14: STRONG BUY | G14: 139.06 | I14: =IF(OR(G14="",H14=""),"",H14/G14-1) | N14: =IF(C14="","",TODAY()-C14) -> 0 | O14: =IF(A14="","",IF(N14>180,"DUE — STALE (>180 days)",IF(J14<>"",IF(ABS(J14-TODAY())<=7,"DUE — EARNINGS WINDOW",IF(I14<>"",IF(ABS(I14)>=0.2,"DUE — PRICE MOVE ±20%",IF(K14="Y","DUE — INSIDER ACTIVITY",IF(I14<>"",IF(ABS(I14)>=0.15,"WATCH — PRICE MOVE ±15%",IF(M14="Y","WATCH — ANALYST SHIFT","Monitor Only")),IF(M14="Y","WATCH — ANALYST SHIFT","Monitor Only")))),IF(K14="Y","DUE — INSIDER ACTIVITY",IF(I14<>"",IF(ABS(I14)>=0.15,"WATCH — PRICE MOVE ±15%",IF(M14="Y","WATCH — ANALYST SHIFT","Monitor Only")),IF(M14="Y","WATCH — ANALYST SHIFT","Monitor Only"))))),IF(I14<>"",IF(ABS(I14)>=0.2,"DUE — PRICE MOVE ±20%",IF(K14="Y","DUE — INSIDER ACTIVITY",IF(I14<>"",IF(ABS(I14)>=0.15,"WATCH — PRICE MOVE ±15%",IF(M14="Y","WATCH — ANALYST SHIFT","Monitor Only")),IF(M14="Y","WATCH — ANALYST SHIFT","Monitor Only")))),IF(K14="Y","DUE — INSIDER ACTIVITY",IF(I14<>"",IF(ABS(I14)>=0.15,"WATCH — PRICE MOVE ±15%",IF(M14="Y","WATCH — ANALYST SHIFT","Monitor Only")),IF(M14="Y","WATCH — ANALYST SHIFT","Monitor Only"))))))) -> Monitor Only
A15: VRTX | B15: Owned | C15: 46241 | D15: 75.6 | E15: 3.79 | F15: BUY | G15: 478.7 | I15: =IF(OR(G15="",H15=""),"",H15/G15-1) | N15: =IF(C15="","",TODAY()-C15) -> -1 | O15: =IF(A15="","",IF(N15>180,"DUE — STALE (>180 days)",IF(J15<>"",IF(ABS(J15-TODAY())<=7,"DUE — EARNINGS WINDOW",IF(I15<>"",IF(ABS(I15)>=0.2,"DUE — PRICE MOVE ±20%",IF(K15="Y","DUE — INSIDER ACTIVITY",IF(I15<>"",IF(ABS(I15)>=0.15,"WATCH — PRICE MOVE ±15%",IF(M15="Y","WATCH — ANALYST SHIFT","Monitor Only")),IF(M15="Y","WATCH — ANALYST SHIFT","Monitor Only")))),IF(K15="Y","DUE — INSIDER ACTIVITY",IF(I15<>"",IF(ABS(I15)>=0.15,"WATCH — PRICE MOVE ±15%",IF(M15="Y","WATCH — ANALYST SHIFT","Monitor Only")),IF(M15="Y","WATCH — ANALYST SHIFT","Monitor Only"))))),IF(I15<>"",IF(ABS(I15)>=0.2,"DUE — PRICE MOVE ±20%",IF(K15="Y","DUE — INSIDER ACTIVITY",IF(I15<>"",IF(ABS(I15)>=0.15,"WATCH — PRICE MOVE ±15%",IF(M15="Y","WATCH — ANALYST SHIFT","Monitor Only")),IF(M15="Y","WATCH — ANALYST SHIFT","Monitor Only")))),IF(K15="Y","DUE — INSIDER ACTIVITY",IF(I15<>"",IF(ABS(I15)>=0.15,"WATCH — PRICE MOVE ±15%",IF(M15="Y","WATCH — ANALYST SHIFT","Monitor Only")),IF(M15="Y","WATCH — ANALYST SHIFT","Monitor Only"))))))) -> Monitor Only | P15: Re-scored 8/7/26: original Avoid was bad source data, corrected. See Journal.
A16: SFM | B16: Closed | C16: 46240 | E16: 1.86 | F16: AVOID | G16: 86.07 | I16: =IF(OR(G16="",H16=""),"",H16/G16-1) | N16: =IF(C16="","",TODAY()-C16) -> 0 | O16: =IF(A16="","",IF(N16>180,"DUE — STALE (>180 days)",IF(J16<>"",IF(ABS(J16-TODAY())<=7,"DUE — EARNINGS WINDOW",IF(I16<>"",IF(ABS(I16)>=0.2,"DUE — PRICE MOVE ±20%",IF(K16="Y","DUE — INSIDER ACTIVITY",IF(I16<>"",IF(ABS(I16)>=0.15,"WATCH — PRICE MOVE ±15%",IF(M16="Y","WATCH — ANALYST SHIFT","Monitor Only")),IF(M16="Y","WATCH — ANALYST SHIFT","Monitor Only")))),IF(K16="Y","DUE — INSIDER ACTIVITY",IF(I16<>"",IF(ABS(I16)>=0.15,"WATCH — PRICE MOVE ±15%",IF(M16="Y","WATCH — ANALYST SHIFT","Monitor Only")),IF(M16="Y","WATCH — ANALYST SHIFT","Monitor Only"))))),IF(I16<>"",IF(ABS(I16)>=0.2,"DUE — PRICE MOVE ±20%",IF(K16="Y","DUE — INSIDER ACTIVITY",IF(I16<>"",IF(ABS(I16)>=0.15,"WATCH — PRICE MOVE ±15%",IF(M16="Y","WATCH — ANALYST SHIFT","Monitor Only")),IF(M16="Y","WATCH — ANALYST SHIFT","Monitor Only")))),IF(K16="Y","DUE — INSIDER ACTIVITY",IF(I16<>"",IF(ABS(I16)>=0.15,"WATCH — PRICE MOVE ±15%",IF(M16="Y","WATCH — ANALYST SHIFT","Monitor Only")),IF(M16="Y","WATCH — ANALYST SHIFT","Monitor Only"))))))) -> Monitor Only | P16: Sold 08/07/26, confirmed. No longer an active recheck target.
A17: TSLA | B17: Closed | C17: 46240 | E17: 1.93 | F17: AVOID | G17: 327.35 | I17: =IF(OR(G17="",H17=""),"",H17/G17-1) | N17: =IF(C17="","",TODAY()-C17) -> 0 | O17: =IF(A17="","",IF(N17>180,"DUE — STALE (>180 days)",IF(J17<>"",IF(ABS(J17-TODAY())<=7,"DUE — EARNINGS WINDOW",IF(I17<>"",IF(ABS(I17)>=0.2,"DUE — PRICE MOVE ±20%",IF(K17="Y","DUE — INSIDER ACTIVITY",IF(I17<>"",IF(ABS(I17)>=0.15,"WATCH — PRICE MOVE ±15%",IF(M17="Y","WATCH — ANALYST SHIFT","Monitor Only")),IF(M17="Y","WATCH — ANALYST SHIFT","Monitor Only")))),IF(K17="Y","DUE — INSIDER ACTIVITY",IF(I17<>"",IF(ABS(I17)>=0.15,"WATCH — PRICE MOVE ±15%",IF(M17="Y","WATCH — ANALYST SHIFT","Monitor Only")),IF(M17="Y","WATCH — ANALYST SHIFT","Monitor Only"))))),IF(I17<>"",IF(ABS(I17)>=0.2,"DUE — PRICE MOVE ±20%",IF(K17="Y","DUE — INSIDER ACTIVITY",IF(I17<>"",IF(ABS(I17)>=0.15,"WATCH — PRICE MOVE ±15%",IF(M17="Y","WATCH — ANALYST SHIFT","Monitor Only")),IF(M17="Y","WATCH — ANALYST SHIFT","Monitor Only")))),IF(K17="Y","DUE — INSIDER ACTIVITY",IF(I17<>"",IF(ABS(I17)>=0.15,"WATCH — PRICE MOVE ±15%",IF(M17="Y","WATCH — ANALYST SHIFT","Monitor Only")),IF(M17="Y","WATCH — ANALYST SHIFT","Monitor Only"))))))) -> Monitor Only | P17: Sold 08/07/26, confirmed. No longer an active recheck target.
A18: ONON | B18: Closed | C18: 46240 | E18: 2.64 | F18: AVOID | G18: 37.61 | I18: =IF(OR(G18="",H18=""),"",H18/G18-1) | N18: =IF(C18="","",TODAY()-C18) -> 0 | O18: =IF(A18="","",IF(N18>180,"DUE — STALE (>180 days)",IF(J18<>"",IF(ABS(J18-TODAY())<=7,"DUE — EARNINGS WINDOW",IF(I18<>"",IF(ABS(I18)>=0.2,"DUE — PRICE MOVE ±20%",IF(K18="Y","DUE — INSIDER ACTIVITY",IF(I18<>"",IF(ABS(I18)>=0.15,"WATCH — PRICE MOVE ±15%",IF(M18="Y","WATCH — ANALYST SHIFT","Monitor Only")),IF(M18="Y","WATCH — ANALYST SHIFT","Monitor Only")))),IF(K18="Y","DUE — INSIDER ACTIVITY",IF(I18<>"",IF(ABS(I18)>=0.15,"WATCH — PRICE MOVE ±15%",IF(M18="Y","WATCH — ANALYST SHIFT","Monitor Only")),IF(M18="Y","WATCH — ANALYST SHIFT","Monitor Only"))))),IF(I18<>"",IF(ABS(I18)>=0.2,"DUE — PRICE MOVE ±20%",IF(K18="Y","DUE — INSIDER ACTIVITY",IF(I18<>"",IF(ABS(I18)>=0.15,"WATCH — PRICE MOVE ±15%",IF(M18="Y","WATCH — ANALYST SHIFT","Monitor Only")),IF(M18="Y","WATCH — ANALYST SHIFT","Monitor Only")))),IF(K18="Y","DUE — INSIDER ACTIVITY",IF(I18<>"",IF(ABS(I18)>=0.15,"WATCH — PRICE MOVE ±15%",IF(M18="Y","WATCH — ANALYST SHIFT","Monitor Only")),IF(M18="Y","WATCH — ANALYST SHIFT","Monitor Only"))))))) -> Monitor Only | P18: Sold 08/07/26, confirmed. No longer an active recheck target.
I19: =IF(OR(G19="",H19=""),"",H19/G19-1) | N19: =IF(C19="","",TODAY()-C19) | O19: =IF(A19="","",IF(N19>180,"DUE — STALE (>180 days)",IF(J19<>"",IF(ABS(J19-TODAY())<=7,"DUE — EARNINGS WINDOW",IF(I19<>"",IF(ABS(I19)>=0.2,"DUE — PRICE MOVE ±20%",IF(K19="Y","DUE — INSIDER ACTIVITY",IF(I19<>"",IF(ABS(I19)>=0.15,"WATCH — PRICE MOVE ±15%",IF(M19="Y","WATCH — ANALYST SHIFT","Monitor Only")),IF(M19="Y","WATCH — ANALYST SHIFT","Monitor Only")))),IF(K19="Y","DUE — INSIDER ACTIVITY",IF(I19<>"",IF(ABS(I19)>=0.15,"WATCH — PRICE MOVE ±15%",IF(M19="Y","WATCH — ANALYST SHIFT","Monitor Only")),IF(M19="Y","WATCH — ANALYST SHIFT","Monitor Only"))))),IF(I19<>"",IF(ABS(I19)>=0.2,"DUE — PRICE MOVE ±20%",IF(K19="Y","DUE — INSIDER ACTIVITY",IF(I19<>"",IF(ABS(I19)>=0.15,"WATCH — PRICE MOVE ±15%",IF(M19="Y","WATCH — ANALYST SHIFT","Monitor Only")),IF(M19="Y","WATCH — ANALYST SHIFT","Monitor Only")))),IF(K19="Y","DUE — INSIDER ACTIVITY",IF(I19<>"",IF(ABS(I19)>=0.15,"WATCH — PRICE MOVE ±15%",IF(M19="Y","WATCH — ANALYST SHIFT","Monitor Only")),IF(M19="Y","WATCH — ANALYST SHIFT","Monitor Only")))))))
I20: =IF(OR(G20="",H20=""),"",H20/G20-1) | N20: =IF(C20="","",TODAY()-C20) | O20: =IF(A20="","",IF(N20>180,"DUE — STALE (>180 days)",IF(J20<>"",IF(ABS(J20-TODAY())<=7,"DUE — EARNINGS WINDOW",IF(I20<>"",IF(ABS(I20)>=0.2,"DUE — PRICE MOVE ±20%",IF(K20="Y","DUE — INSIDER ACTIVITY",IF(I20<>"",IF(ABS(I20)>=0.15,"WATCH — PRICE MOVE ±15%",IF(M20="Y","WATCH — ANALYST SHIFT","Monitor Only")),IF(M20="Y","WATCH — ANALYST SHIFT","Monitor Only")))),IF(K20="Y","DUE — INSIDER ACTIVITY",IF(I20<>"",IF(ABS(I20)>=0.15,"WATCH — PRICE MOVE ±15%",IF(M20="Y","WATCH — ANALYST SHIFT","Monitor Only")),IF(M20="Y","WATCH — ANALYST SHIFT","Monitor Only"))))),IF(I20<>"",IF(ABS(I20)>=0.2,"DUE — PRICE MOVE ±20%",IF(K20="Y","DUE — INSIDER ACTIVITY",IF(I20<>"",IF(ABS(I20)>=0.15,"WATCH — PRICE MOVE ±15%",IF(M20="Y","WATCH — ANALYST SHIFT","Monitor Only")),IF(M20="Y","WATCH — ANALYST SHIFT","Monitor Only")))),IF(K20="Y","DUE — INSIDER ACTIVITY",IF(I20<>"",IF(ABS(I20)>=0.15,"WATCH — PRICE MOVE ±15%",IF(M20="Y","WATCH — ANALYST SHIFT","Monitor Only")),IF(M20="Y","WATCH — ANALYST SHIFT","Monitor Only")))))))
I21: =IF(OR(G21="",H21=""),"",H21/G21-1) | N21: =IF(C21="","",TODAY()-C21) | O21: =IF(A21="","",IF(N21>180,"DUE — STALE (>180 days)",IF(J21<>"",IF(ABS(J21-TODAY())<=7,"DUE — EARNINGS WINDOW",IF(I21<>"",IF(ABS(I21)>=0.2,"DUE — PRICE MOVE ±20%",IF(K21="Y","DUE — INSIDER ACTIVITY",IF(I21<>"",IF(ABS(I21)>=0.15,"WATCH — PRICE MOVE ±15%",IF(M21="Y","WATCH — ANALYST SHIFT","Monitor Only")),IF(M21="Y","WATCH — ANALYST SHIFT","Monitor Only")))),IF(K21="Y","DUE — INSIDER ACTIVITY",IF(I21<>"",IF(ABS(I21)>=0.15,"WATCH — PRICE MOVE ±15%",IF(M21="Y","WATCH — ANALYST SHIFT","Monitor Only")),IF(M21="Y","WATCH — ANALYST SHIFT","Monitor Only"))))),IF(I21<>"",IF(ABS(I21)>=0.2,"DUE — PRICE MOVE ±20%",IF(K21="Y","DUE — INSIDER ACTIVITY",IF(I21<>"",IF(ABS(I21)>=0.15,"WATCH — PRICE MOVE ±15%",IF(M21="Y","WATCH — ANALYST SHIFT","Monitor Only")),IF(M21="Y","WATCH — ANALYST SHIFT","Monitor Only")))),IF(K21="Y","DUE — INSIDER ACTIVITY",IF(I21<>"",IF(ABS(I21)>=0.15,"WATCH — PRICE MOVE ±15%",IF(M21="Y","WATCH — ANALYST SHIFT","Monitor Only")),IF(M21="Y","WATCH — ANALYST SHIFT","Monitor Only")))))))
I22: =IF(OR(G22="",H22=""),"",H22/G22-1) | N22: =IF(C22="","",TODAY()-C22) | O22: =IF(A22="","",IF(N22>180,"DUE — STALE (>180 days)",IF(J22<>"",IF(ABS(J22-TODAY())<=7,"DUE — EARNINGS WINDOW",IF(I22<>"",IF(ABS(I22)>=0.2,"DUE — PRICE MOVE ±20%",IF(K22="Y","DUE — INSIDER ACTIVITY",IF(I22<>"",IF(ABS(I22)>=0.15,"WATCH — PRICE MOVE ±15%",IF(M22="Y","WATCH — ANALYST SHIFT","Monitor Only")),IF(M22="Y","WATCH — ANALYST SHIFT","Monitor Only")))),IF(K22="Y","DUE — INSIDER ACTIVITY",IF(I22<>"",IF(ABS(I22)>=0.15,"WATCH — PRICE MOVE ±15%",IF(M22="Y","WATCH — ANALYST SHIFT","Monitor Only")),IF(M22="Y","WATCH — ANALYST SHIFT","Monitor Only"))))),IF(I22<>"",IF(ABS(I22)>=0.2,"DUE — PRICE MOVE ±20%",IF(K22="Y","DUE — INSIDER ACTIVITY",IF(I22<>"",IF(ABS(I22)>=0.15,"WATCH — PRICE MOVE ±15%",IF(M22="Y","WATCH — ANALYST SHIFT","Monitor Only")),IF(M22="Y","WATCH — ANALYST SHIFT","Monitor Only")))),IF(K22="Y","DUE — INSIDER ACTIVITY",IF(I22<>"",IF(ABS(I22)>=0.15,"WATCH — PRICE MOVE ±15%",IF(M22="Y","WATCH — ANALYST SHIFT","Monitor Only")),IF(M22="Y","WATCH — ANALYST SHIFT","Monitor Only")))))))
I23: =IF(OR(G23="",H23=""),"",H23/G23-1) | N23: =IF(C23="","",TODAY()-C23) | O23: =IF(A23="","",IF(N23>180,"DUE — STALE (>180 days)",IF(J23<>"",IF(ABS(J23-TODAY())<=7,"DUE — EARNINGS WINDOW",IF(I23<>"",IF(ABS(I23)>=0.2,"DUE — PRICE MOVE ±20%",IF(K23="Y","DUE — INSIDER ACTIVITY",IF(I23<>"",IF(ABS(I23)>=0.15,"WATCH — PRICE MOVE ±15%",IF(M23="Y","WATCH — ANALYST SHIFT","Monitor Only")),IF(M23="Y","WATCH — ANALYST SHIFT","Monitor Only")))),IF(K23="Y","DUE — INSIDER ACTIVITY",IF(I23<>"",IF(ABS(I23)>=0.15,"WATCH — PRICE MOVE ±15%",IF(M23="Y","WATCH — ANALYST SHIFT","Monitor Only")),IF(M23="Y","WATCH — ANALYST SHIFT","Monitor Only"))))),IF(I23<>"",IF(ABS(I23)>=0.2,"DUE — PRICE MOVE ±20%",IF(K23="Y","DUE — INSIDER ACTIVITY",IF(I23<>"",IF(ABS(I23)>=0.15,"WATCH — PRICE MOVE ±15%",IF(M23="Y","WATCH — ANALYST SHIFT","Monitor Only")),IF(M23="Y","WATCH — ANALYST SHIFT","Monitor Only")))),IF(K23="Y","DUE — INSIDER ACTIVITY",IF(I23<>"",IF(ABS(I23)>=0.15,"WATCH — PRICE MOVE ±15%",IF(M23="Y","WATCH — ANALYST SHIFT","Monitor Only")),IF(M23="Y","WATCH — ANALYST SHIFT","Monitor Only")))))))
I24: =IF(OR(G24="",H24=""),"",H24/G24-1) | N24: =IF(C24="","",TODAY()-C24) | O24: =IF(A24="","",IF(N24>180,"DUE — STALE (>180 days)",IF(J24<>"",IF(ABS(J24-TODAY())<=7,"DUE — EARNINGS WINDOW",IF(I24<>"",IF(ABS(I24)>=0.2,"DUE — PRICE MOVE ±20%",IF(K24="Y","DUE — INSIDER ACTIVITY",IF(I24<>"",IF(ABS(I24)>=0.15,"WATCH — PRICE MOVE ±15%",IF(M24="Y","WATCH — ANALYST SHIFT","Monitor Only")),IF(M24="Y","WATCH — ANALYST SHIFT","Monitor Only")))),IF(K24="Y","DUE — INSIDER ACTIVITY",IF(I24<>"",IF(ABS(I24)>=0.15,"WATCH — PRICE MOVE ±15%",IF(M24="Y","WATCH — ANALYST SHIFT","Monitor Only")),IF(M24="Y","WATCH — ANALYST SHIFT","Monitor Only"))))),IF(I24<>"",IF(ABS(I24)>=0.2,"DUE — PRICE MOVE ±20%",IF(K24="Y","DUE — INSIDER ACTIVITY",IF(I24<>"",IF(ABS(I24)>=0.15,"WATCH — PRICE MOVE ±15%",IF(M24="Y","WATCH — ANALYST SHIFT","Monitor Only")),IF(M24="Y","WATCH — ANALYST SHIFT","Monitor Only")))),IF(K24="Y","DUE — INSIDER ACTIVITY",IF(I24<>"",IF(ABS(I24)>=0.15,"WATCH — PRICE MOVE ±15%",IF(M24="Y","WATCH — ANALYST SHIFT","Monitor Only")),IF(M24="Y","WATCH — ANALYST SHIFT","Monitor Only")))))))
I25: =IF(OR(G25="",H25=""),"",H25/G25-1) | N25: =IF(C25="","",TODAY()-C25) | O25: =IF(A25="","",IF(N25>180,"DUE — STALE (>180 days)",IF(J25<>"",IF(ABS(J25-TODAY())<=7,"DUE — EARNINGS WINDOW",IF(I25<>"",IF(ABS(I25)>=0.2,"DUE — PRICE MOVE ±20%",IF(K25="Y","DUE — INSIDER ACTIVITY",IF(I25<>"",IF(ABS(I25)>=0.15,"WATCH — PRICE MOVE ±15%",IF(M25="Y","WATCH — ANALYST SHIFT","Monitor Only")),IF(M25="Y","WATCH — ANALYST SHIFT","Monitor Only")))),IF(K25="Y","DUE — INSIDER ACTIVITY",IF(I25<>"",IF(ABS(I25)>=0.15,"WATCH — PRICE MOVE ±15%",IF(M25="Y","WATCH — ANALYST SHIFT","Monitor Only")),IF(M25="Y","WATCH — ANALYST SHIFT","Monitor Only"))))),IF(I25<>"",IF(ABS(I25)>=0.2,"DUE — PRICE MOVE ±20%",IF(K25="Y","DUE — INSIDER ACTIVITY",IF(I25<>"",IF(ABS(I25)>=0.15,"WATCH — PRICE MOVE ±15%",IF(M25="Y","WATCH — ANALYST SHIFT","Monitor Only")),IF(M25="Y","WATCH — ANALYST SHIFT","Monitor Only")))),IF(K25="Y","DUE — INSIDER ACTIVITY",IF(I25<>"",IF(ABS(I25)>=0.15,"WATCH — PRICE MOVE ±15%",IF(M25="Y","WATCH — ANALYST SHIFT","Monitor Only")),IF(M25="Y","WATCH — ANALYST SHIFT","Monitor Only")))))))
I26: =IF(OR(G26="",H26=""),"",H26/G26-1) | N26: =IF(C26="","",TODAY()-C26) | O26: =IF(A26="","",IF(N26>180,"DUE — STALE (>180 days)",IF(J26<>"",IF(ABS(J26-TODAY())<=7,"DUE — EARNINGS WINDOW",IF(I26<>"",IF(ABS(I26)>=0.2,"DUE — PRICE MOVE ±20%",IF(K26="Y","DUE — INSIDER ACTIVITY",IF(I26<>"",IF(ABS(I26)>=0.15,"WATCH — PRICE MOVE ±15%",IF(M26="Y","WATCH — ANALYST SHIFT","Monitor Only")),IF(M26="Y","WATCH — ANALYST SHIFT","Monitor Only")))),IF(K26="Y","DUE — INSIDER ACTIVITY",IF(I26<>"",IF(ABS(I26)>=0.15,"WATCH — PRICE MOVE ±15%",IF(M26="Y","WATCH — ANALYST SHIFT","Monitor Only")),IF(M26="Y","WATCH — ANALYST SHIFT","Monitor Only"))))),IF(I26<>"",IF(ABS(I26)>=0.2,"DUE — PRICE MOVE ±20%",IF(K26="Y","DUE — INSIDER ACTIVITY",IF(I26<>"",IF(ABS(I26)>=0.15,"WATCH — PRICE MOVE ±15%",IF(M26="Y","WATCH — ANALYST SHIFT","Monitor Only")),IF(M26="Y","WATCH — ANALYST SHIFT","Monitor Only")))),IF(K26="Y","DUE — INSIDER ACTIVITY",IF(I26<>"",IF(ABS(I26)>=0.15,"WATCH — PRICE MOVE ±15%",IF(M26="Y","WATCH — ANALYST SHIFT","Monitor Only")),IF(M26="Y","WATCH — ANALYST SHIFT","Monitor Only")))))))
I27: =IF(OR(G27="",H27=""),"",H27/G27-1) | N27: =IF(C27="","",TODAY()-C27) | O27: =IF(A27="","",IF(N27>180,"DUE — STALE (>180 days)",IF(J27<>"",IF(ABS(J27-TODAY())<=7,"DUE — EARNINGS WINDOW",IF(I27<>"",IF(ABS(I27)>=0.2,"DUE — PRICE MOVE ±20%",IF(K27="Y","DUE — INSIDER ACTIVITY",IF(I27<>"",IF(ABS(I27)>=0.15,"WATCH — PRICE MOVE ±15%",IF(M27="Y","WATCH — ANALYST SHIFT","Monitor Only")),IF(M27="Y","WATCH — ANALYST SHIFT","Monitor Only")))),IF(K27="Y","DUE — INSIDER ACTIVITY",IF(I27<>"",IF(ABS(I27)>=0.15,"WATCH — PRICE MOVE ±15%",IF(M27="Y","WATCH — ANALYST SHIFT","Monitor Only")),IF(M27="Y","WATCH — ANALYST SHIFT","Monitor Only"))))),IF(I27<>"",IF(ABS(I27)>=0.2,"DUE — PRICE MOVE ±20%",IF(K27="Y","DUE — INSIDER ACTIVITY",IF(I27<>"",IF(ABS(I27)>=0.15,"WATCH — PRICE MOVE ±15%",IF(M27="Y","WATCH — ANALYST SHIFT","Monitor Only")),IF(M27="Y","WATCH — ANALYST SHIFT","Monitor Only")))),IF(K27="Y","DUE — INSIDER ACTIVITY",IF(I27<>"",IF(ABS(I27)>=0.15,"WATCH — PRICE MOVE ±15%",IF(M27="Y","WATCH — ANALYST SHIFT","Monitor Only")),IF(M27="Y","WATCH — ANALYST SHIFT","Monitor Only")))))))
I28: =IF(OR(G28="",H28=""),"",H28/G28-1) | N28: =IF(C28="","",TODAY()-C28) | O28: =IF(A28="","",IF(N28>180,"DUE — STALE (>180 days)",IF(J28<>"",IF(ABS(J28-TODAY())<=7,"DUE — EARNINGS WINDOW",IF(I28<>"",IF(ABS(I28)>=0.2,"DUE — PRICE MOVE ±20%",IF(K28="Y","DUE — INSIDER ACTIVITY",IF(I28<>"",IF(ABS(I28)>=0.15,"WATCH — PRICE MOVE ±15%",IF(M28="Y","WATCH — ANALYST SHIFT","Monitor Only")),IF(M28="Y","WATCH — ANALYST SHIFT","Monitor Only")))),IF(K28="Y","DUE — INSIDER ACTIVITY",IF(I28<>"",IF(ABS(I28)>=0.15,"WATCH — PRICE MOVE ±15%",IF(M28="Y","WATCH — ANALYST SHIFT","Monitor Only")),IF(M28="Y","WATCH — ANALYST SHIFT","Monitor Only"))))),IF(I28<>"",IF(ABS(I28)>=0.2,"DUE — PRICE MOVE ±20%",IF(K28="Y","DUE — INSIDER ACTIVITY",IF(I28<>"",IF(ABS(I28)>=0.15,"WATCH — PRICE MOVE ±15%",IF(M28="Y","WATCH — ANALYST SHIFT","Monitor Only")),IF(M28="Y","WATCH — ANALYST SHIFT","Monitor Only")))),IF(K28="Y","DUE — INSIDER ACTIVITY",IF(I28<>"",IF(ABS(I28)>=0.15,"WATCH — PRICE MOVE ±15%",IF(M28="Y","WATCH — ANALYST SHIFT","Monitor Only")),IF(M28="Y","WATCH — ANALYST SHIFT","Monitor Only")))))))
I29: =IF(OR(G29="",H29=""),"",H29/G29-1) | N29: =IF(C29="","",TODAY()-C29) | O29: =IF(A29="","",IF(N29>180,"DUE — STALE (>180 days)",IF(J29<>"",IF(ABS(J29-TODAY())<=7,"DUE — EARNINGS WINDOW",IF(I29<>"",IF(ABS(I29)>=0.2,"DUE — PRICE MOVE ±20%",IF(K29="Y","DUE — INSIDER ACTIVITY",IF(I29<>"",IF(ABS(I29)>=0.15,"WATCH — PRICE MOVE ±15%",IF(M29="Y","WATCH — ANALYST SHIFT","Monitor Only")),IF(M29="Y","WATCH — ANALYST SHIFT","Monitor Only")))),IF(K29="Y","DUE — INSIDER ACTIVITY",IF(I29<>"",IF(ABS(I29)>=0.15,"WATCH — PRICE MOVE ±15%",IF(M29="Y","WATCH — ANALYST SHIFT","Monitor Only")),IF(M29="Y","WATCH — ANALYST SHIFT","Monitor Only"))))),IF(I29<>"",IF(ABS(I29)>=0.2,"DUE — PRICE MOVE ±20%",IF(K29="Y","DUE — INSIDER ACTIVITY",IF(I29<>"",IF(ABS(I29)>=0.15,"WATCH — PRICE MOVE ±15%",IF(M29="Y","WATCH — ANALYST SHIFT","Monitor Only")),IF(M29="Y","WATCH — ANALYST SHIFT","Monitor Only")))),IF(K29="Y","DUE — INSIDER ACTIVITY",IF(I29<>"",IF(ABS(I29)>=0.15,"WATCH — PRICE MOVE ±15%",IF(M29="Y","WATCH — ANALYST SHIFT","Monitor Only")),IF(M29="Y","WATCH — ANALYST SHIFT","Monitor Only")))))))
I30: =IF(OR(G30="",H30=""),"",H30/G30-1) | N30: =IF(C30="","",TODAY()-C30) | O30: =IF(A30="","",IF(N30>180,"DUE — STALE (>180 days)",IF(J30<>"",IF(ABS(J30-TODAY())<=7,"DUE — EARNINGS WINDOW",IF(I30<>"",IF(ABS(I30)>=0.2,"DUE — PRICE MOVE ±20%",IF(K30="Y","DUE — INSIDER ACTIVITY",IF(I30<>"",IF(ABS(I30)>=0.15,"WATCH — PRICE MOVE ±15%",IF(M30="Y","WATCH — ANALYST SHIFT","Monitor Only")),IF(M30="Y","WATCH — ANALYST SHIFT","Monitor Only")))),IF(K30="Y","DUE — INSIDER ACTIVITY",IF(I30<>"",IF(ABS(I30)>=0.15,"WATCH — PRICE MOVE ±15%",IF(M30="Y","WATCH — ANALYST SHIFT","Monitor Only")),IF(M30="Y","WATCH — ANALYST SHIFT","Monitor Only"))))),IF(I30<>"",IF(ABS(I30)>=0.2,"DUE — PRICE MOVE ±20%",IF(K30="Y","DUE — INSIDER ACTIVITY",IF(I30<>"",IF(ABS(I30)>=0.15,"WATCH — PRICE MOVE ±15%",IF(M30="Y","WATCH — ANALYST SHIFT","Monitor Only")),IF(M30="Y","WATCH — ANALYST SHIFT","Monitor Only")))),IF(K30="Y","DUE — INSIDER ACTIVITY",IF(I30<>"",IF(ABS(I30)>=0.15,"WATCH — PRICE MOVE ±15%",IF(M30="Y","WATCH — ANALYST SHIFT","Monitor Only")),IF(M30="Y","WATCH — ANALYST SHIFT","Monitor Only")))))))
... I42: =IF(OR(G42="",H42=""),"",H42/G42-1) | N42: =IF(C42="","",TODAY()-C42) | O42: =IF(A42="","",IF(N42>180,"DUE — STALE (>180 days)",IF(J42<>"",IF(ABS(J42-TODAY())<=7,"DUE — EARNINGS WINDOW",IF(I42<>"",IF(ABS(I42)>=0.2,"DUE — PRICE MOVE ±20%",IF(K42="Y","DUE — INSIDER ACTIVITY",IF(I42<>"",IF(ABS(I42)>=0.15,"WATCH — PRICE MOVE ±15%",IF(M42="Y","WATCH — ANALYST SHIFT","Monitor Only")),IF(M42="Y","WATCH — ANALYST SHIFT","Monitor Only")))),IF(K42="Y","DUE — INSIDER ACTIVITY",IF(I42<>"",IF(ABS(I42)>=0.15,"WATCH — PRICE MOVE ±15%",IF(M42="Y","WATCH — ANALYST SHIFT","Monitor Only")),IF(M42="Y","WATCH — ANALYST SHIFT","Monitor Only"))))),IF(I42<>"",IF(ABS(I42)>=0.2,"DUE — PRICE MOVE ±20%",IF(K42="Y","DUE — INSIDER ACTIVITY",IF(I42<>"",IF(ABS(I42)>=0.15,"WATCH — PRICE MOVE ±15%",IF(M42="Y","WATCH — ANALYST SHIFT","Monitor Only")),IF(M42="Y","WATCH — ANALYST SHIFT","Monitor Only")))),IF(K42="Y","DUE — INSIDER ACTIVITY",IF(I42<>"",IF(ABS(I42)>=0.15,"WATCH — PRICE MOVE ±15%",IF(M42="Y","WATCH — ANALYST SHIFT","Monitor Only")),IF(M42="Y","WATCH — ANALYST SHIFT","Monitor Only")))))))

Sheet Price History
A1: Weekly closing price ($), week-ending Friday (Rule 36: weekly total returns, 24-month target, 12-month minimum, 36-month max). Enter ticker in row 2 header, prices below. Blue = input.
A2: Week Ending | B2: ADBE | C2: ANET | D2: ASML | E2: AVGO | F2: CRWD | G2: KLAC | H2: MU | I2: NVDA | J2: PLD | K2: PLTR | L2: TSM | M2: VRT | N2: VRTX | O2: Ticker 14 | P2: Ticker 15 | Q2: Ticker 16
A3: 45149 | B3: 508.45 | C3: 43.74 | D3: 661.78 | E3: 82.98 | F3: 37.06 | G3: 47.9 | H3: 64.37 | I3: 40.85 | J3: 123.51 | K3: 15.41 | L3: 91.99 | M3: 33.51 | N3: 349.86
A4: 45156 | B4: 508.13 | C4: 45.14 | D4: 655.33 | E4: 82.58 | F4: 36.7 | G4: 47.8 | H4: 63.59 | I4: 43.3 | J4: 121.47 | K4: 14.4 | L4: 91.1 | M4: 33.97 | N4: 344.82
A5: 45163 | B5: 525.06 | C5: 45.23 | D5: 651.01 | E5: 85.18 | F5: 37.4 | G5: 48.17 | H5: 63.72 | I5: 46.02 | J5: 122.66 | K5: 14.53 | L5: 93.1 | M5: 37.5 | N5: 350.06
A6: 45170 | B6: 563.21 | C6: 49.34 | D6: 662.52 | E6: 87.25 | F6: 40.31 | G6: 50.7 | H6: 70.39 | I6: 48.51 | J6: 124.59 | K6: 15.18 | L6: 93.19 | M6: 39.87 | N6: 351.1
A7: 45177 | B7: 560.36 | C7: 49.12 | D7: 627.86 | E7: 85.76 | F7: 42.02 | G7: 49.77 | H7: 70.18 | I7: 45.57 | J7: 122.48 | K7: 15.13 | L7: 89.64 | M7: 39.2 | N7: 343.05
A8: 45184 | B8: 528.89 | C8: 46.18 | D8: 596.66 | E8: 85.17 | F8: 41.36 | G8: 45.42 | H8: 69.88 | I8: 43.9 | J8: 123.18 | K8: 15.33 | L8: 89.25 | M8: 38.17 | N8: 348.9
A9: 45191 | B9: 512.9 | C9: 45.09 | D9: 587.1 | E9: 82.91 | F9: 40.64 | G9: 45.18 | H9: 68.88 | I9: 41.61 | J9: 114.07 | K9: 14.13 | L9: 85.64 | M9: 36.45 | N9: 349.53
A10: 45198 | B10: 509.9 | C10: 45.98 | D10: 588.66 | E10: 83.06 | F10: 41.85 | G10: 45.87 | H10: 68.03 | I10: 43.5 | J10: 112.21 | K10: 16 | L10: 86.9 | M10: 37.2 | N10: 347.74
A11: 45205 | B11: 526.68 | C11: 48.51 | D11: 597.36 | E11: 84.53 | F11: 44.17 | G11: 46.81 | H11: 69.96 | I11: 45.76 | J11: 108.91 | K11: 16.61 | L11: 89.29 | M11: 39.77 | N11: 360.62
A12: 45212 | B12: 548.76 | C12: 47.46 | D12: 599.75 | E12: 88.32 | F12: 46.43 | G12: 48.68 | H12: 69.21 | I12: 45.46 | J12: 109.65 | K12: 17.36 | L12: 90.46 | M12: 39.1 | N12: 371
A13: 45219 | B13: 540.96 | C13: 46.53 | D13: 580.1 | E13: 85.36 | F13: 44.69 | G13: 46.24 | H13: 67.22 | I13: 41.39 | J13: 102.43 | K13: 16.11 | L13: 91.31 | M13: 36.74 | N13: 361.86
A14: 45226 | B14: 508.12 | C14: 44.05 | D14: 590 | E14: 83.84 | F14: 43.21 | G14: 45.79 | H14: 65.65 | I14: 40.5 | J14: 97.32 | K14: 15.07 | L14: 85.99 | M14: 36.42 | N14: 355.28
... A158: 46234 | B158: 250.41 | C158: 180.35 | D158: 1629 | E158: 389.28 | F158: 190.86 | G158: 182.82 | H158: 823.03 | I158: 200.75 | J158: 144.61 | K158: 123.06 | L158: 404.25 | M158: 241.57 | N158: 477.1

Sheet Dashboard
A1: Ticker | B1: Company | C1: Date Scored | D1: Tier 1 Wtd Avg | E1: Composite Score | F1: Decision | G1: Rule 1 | H1: Rule 2 | I1: Rule 3 | J1: Rule 4
A2: =IF(Scoring!A3="","",Scoring!A3) -> MU | B2: =IF(Scoring!B3="","",Scoring!B3) -> Micron Technology | C2: =IF(Scoring!C3="","",Scoring!C3) -> 46240 | D2: =IF(Scoring!N3="","",Scoring!N3) -> 3.6428571 | E2: =IF(Scoring!AF3="","",Scoring!AF3) -> 71.8 | F2: =IF(Scoring!AG3="","",Scoring!AG3) -> BUY | G2: =IF(Scoring!AH3="","",Scoring!AH3) -> OK | H2: =IF(Scoring!AI3="","",Scoring!AI3) -> OK | I2: =IF(Scoring!AJ3="","",Scoring!AJ3) -> OK | J2: =IF(Scoring!AK3="","",Scoring!AK3) -> OK
A3: =IF(Scoring!A4="","",Scoring!A4) -> AVGO | B3: =IF(Scoring!B4="","",Scoring!B4) -> Broadcom Inc. | C3: =IF(Scoring!C4="","",Scoring!C4) -> 46240 | D3: =IF(Scoring!N4="","",Scoring!N4) -> 4.0714286 | E3: =IF(Scoring!AF4="","",Scoring!AF4) -> 80.8 | F3: =IF(Scoring!AG4="","",Scoring!AG4) -> STRONG BUY | G3: =IF(Scoring!AH4="","",Scoring!AH4) -> OK | H3: =IF(Scoring!AI4="","",Scoring!AI4) -> OK | I3: =IF(Scoring!AJ4="","",Scoring!AJ4) -> OK | J3: =IF(Scoring!AK4="","",Scoring!AK4) -> OK
A4: =IF(Scoring!A5="","",Scoring!A5) -> PLTR | B4: =IF(Scoring!B5="","",Scoring!B5) -> Palantir Technologies | C4: =IF(Scoring!C5="","",Scoring!C5) -> 46240 | D4: =IF(Scoring!N5="","",Scoring!N5) -> 4 | E4: =IF(Scoring!AF5="","",Scoring!AF5) -> 75.2 | F4: =IF(Scoring!AG5="","",Scoring!AG5) -> BUY | G4: =IF(Scoring!AH5="","",Scoring!AH5) -> OK | H4: =IF(Scoring!AI5="","",Scoring!AI5) -> OK | I4: =IF(Scoring!AJ5="","",Scoring!AJ5) -> OK | J4: =IF(Scoring!AK5="","",Scoring!AK5) -> OK
A5: =IF(Scoring!A6="","",Scoring!A6) -> NVDA | B5: =IF(Scoring!B6="","",Scoring!B6) -> NVIDIA Corporation | C5: =IF(Scoring!C6="","",Scoring!C6) -> 46240 | D5: =IF(Scoring!N6="","",Scoring!N6) -> 4.5714286 | E5: =IF(Scoring!AF6="","",Scoring!AF6) -> 93.2 | F5: =IF(Scoring!AG6="","",Scoring!AG6) -> STRONG BUY | G5: =IF(Scoring!AH6="","",Scoring!AH6) -> OK | H5: =IF(Scoring!AI6="","",Scoring!AI6) -> OK | I5: =IF(Scoring!AJ6="","",Scoring!AJ6) -> OK | J5: =IF(Scoring!AK6="","",Scoring!AK6) -> OK
A6: =IF(Scoring!A7="","",Scoring!A7) -> VRTX | B6: =IF(Scoring!B7="","",Scoring!B7) -> Vertex Pharmaceuticals | C6: =IF(Scoring!C7="","",Scoring!C7) -> 46241 | D6: =IF(Scoring!N7="","",Scoring!N7) -> 3.7857143 | E6: =IF(Scoring!AF7="","",Scoring!AF7) -> 75.6 | F6: =IF(Scoring!AG7="","",Scoring!AG7) -> BUY | G6: =IF(Scoring!AH7="","",Scoring!AH7) -> OK | H6: =IF(Scoring!AI7="","",Scoring!AI7) -> OK | I6: =IF(Scoring!AJ7="","",Scoring!AJ7) -> OK | J6: =IF(Scoring!AK7="","",Scoring!AK7) -> OK
A7: =IF(Scoring!A8="","",Scoring!A8) -> PLD | B7: =IF(Scoring!B8="","",Scoring!B8) -> Prologis Inc. (REIT-adapted) | C7: =IF(Scoring!C8="","",Scoring!C8) -> 46240 | D7: =IF(Scoring!N8="","",Scoring!N8) -> 4.3571429 | E7: =IF(Scoring!AF8="","",Scoring!AF8) -> 82 | F7: =IF(Scoring!AG8="","",Scoring!AG8) -> STRONG BUY | G7: =IF(Scoring!AH8="","",Scoring!AH8) -> OK | H7: =IF(Scoring!AI8="","",Scoring!AI8) -> OK | I7: =IF(Scoring!AJ8="","",Scoring!AJ8) -> OK | J7: =IF(Scoring!AK8="","",Scoring!AK8) -> OK
A8: =IF(Scoring!A9="","",Scoring!A9) -> SFM | B8: =IF(Scoring!B9="","",Scoring!B9) -> Sprouts Farmers Market | C8: =IF(Scoring!C9="","",Scoring!C9) -> 46240 | D8: =IF(Scoring!N9="","",Scoring!N9) -> 1.8571429 | E8: =IF(Scoring!AF9="","",Scoring!AF9) | F8: =IF(Scoring!AG9="","",Scoring!AG9) | G8: =IF(Scoring!AH9="","",Scoring!AH9) -> FAIL | H8: =IF(Scoring!AI9="","",Scoring!AI9) -> REVIEW | I8: =IF(Scoring!AJ9="","",Scoring!AJ9) -> AVOID | J8: =IF(Scoring!AK9="","",Scoring!AK9) -> OK
A9: =IF(Scoring!A10="","",Scoring!A10) -> ONON | B9: =IF(Scoring!B10="","",Scoring!B10) -> On Holding AG | C9: =IF(Scoring!C10="","",Scoring!C10) -> 46240 | D9: =IF(Scoring!N10="","",Scoring!N10) -> 2.6428571 | E9: =IF(Scoring!AF10="","",Scoring!AF10) | F9: =IF(Scoring!AG10="","",Scoring!AG10) | G9: =IF(Scoring!AH10="","",Scoring!AH10) -> FAIL | H9: =IF(Scoring!AI10="","",Scoring!AI10) -> OK | I9: =IF(Scoring!AJ10="","",Scoring!AJ10) -> AVOID | J9: =IF(Scoring!AK10="","",Scoring!AK10) -> OK
A10: =IF(Scoring!A11="","",Scoring!A11) -> TSLA | B10: =IF(Scoring!B11="","",Scoring!B11) -> Tesla Inc. | C10: =IF(Scoring!C11="","",Scoring!C11) -> 46240 | D10: =IF(Scoring!N11="","",Scoring!N11) -> 1.9285714 | E10: =IF(Scoring!AF11="","",Scoring!AF11) | F10: =IF(Scoring!AG11="","",Scoring!AG11) | G10: =IF(Scoring!AH11="","",Scoring!AH11) -> FAIL | H10: =IF(Scoring!AI11="","",Scoring!AI11) -> REVIEW | I10: =IF(Scoring!AJ11="","",Scoring!AJ11) -> AVOID | J10: =IF(Scoring!AK11="","",Scoring!AK11) -> OK
A11: =IF(Scoring!A12="","",Scoring!A12) -> ADBE | B11: =IF(Scoring!B12="","",Scoring!B12) -> Adobe Inc. | C11: =IF(Scoring!C12="","",Scoring!C12) -> 46240 | D11: =IF(Scoring!N12="","",Scoring!N12) -> 4.5714286 | E11: =IF(Scoring!AF12="","",Scoring!AF12) -> 85.8 | F11: =IF(Scoring!AG12="","",Scoring!AG12) -> STRONG BUY | G11: =IF(Scoring!AH12="","",Scoring!AH12) -> OK | H11: =IF(Scoring!AI12="","",Scoring!AI12) -> OK | I11: =IF(Scoring!AJ12="","",Scoring!AJ12) -> OK | J11: =IF(Scoring!AK12="","",Scoring!AK12) -> OK
A12: =IF(Scoring!A13="","",Scoring!A13) -> ANET | B12: =IF(Scoring!B13="","",Scoring!B13) -> Arista Networks | C12: =IF(Scoring!C13="","",Scoring!C13) -> 46240 | D12: =IF(Scoring!N13="","",Scoring!N13) -> 4.5714286 | E12: =IF(Scoring!AF13="","",Scoring!AF13) -> 85 | F12: =IF(Scoring!AG13="","",Scoring!AG13) -> STRONG BUY | G12: =IF(Scoring!AH13="","",Scoring!AH13) -> OK | H12: =IF(Scoring!AI13="","",Scoring!AI13) -> OK | I12: =IF(Scoring!AJ13="","",Scoring!AJ13) -> OK | J12: =IF(Scoring!AK13="","",Scoring!AK13) -> OK
A13: =IF(Scoring!A14="","",Scoring!A14) -> ASML | B13: =IF(Scoring!B14="","",Scoring!B14) -> ASML Holding | C13: =IF(Scoring!C14="","",Scoring!C14) -> 46240 | D13: =IF(Scoring!N14="","",Scoring!N14) -> 3.5714286 | E13: =IF(Scoring!AF14="","",Scoring!AF14) -> 73.2 | F13: =IF(Scoring!AG14="","",Scoring!AG14) -> BUY | G13: =IF(Scoring!AH14="","",Scoring!AH14) -> OK | H13: =IF(Scoring!AI14="","",Scoring!AI14) -> OK | I13: =IF(Scoring!AJ14="","",Scoring!AJ14) -> OK | J13: =IF(Scoring!AK14="","",Scoring!AK14) -> OK
... A26: =IF(Scoring!A27="","",Scoring!A27) | B26: =IF(Scoring!B27="","",Scoring!B27) | C26: =IF(Scoring!C27="","",Scoring!C27) | D26: =IF(Scoring!N27="","",Scoring!N27) | E26: =IF(Scoring!AF27="","",Scoring!AF27) | F26: =IF(Scoring!AG27="","",Scoring!AG27) | G26: =IF(Scoring!AH27="","",Scoring!AH27) | H26: =IF(Scoring!AI27="","",Scoring!AI27) | I26: =IF(Scoring!AJ27="","",Scoring!AJ27) | J26: =IF(Scoring!AK27="","",Scoring!AK27)
A28: This tab mirrors the Scoring tab automatically — do not type here. You can sort this tab directly (Data > Sort by Composite Score); Excel moves whole rows, so each row's links stay correct.

Sheet Scoring
D1: TIER 1 — 70% of Decision | P1: TIER 2 — 25% of Decision | Y1: TIER 3 — 5% of Decision | AH1: RULE FLAGS (1–4)
A2: Ticker | B2: Company | C2: Date Scored | D2: FCF Yield & Trend (20%) Score | E2: Conf (H/M/L) | F2: Rev Growth Consist. (15%) Score | G2: Conf (H/M/L) | H2: Moat Quality (15%) Score | I2: Conf (H/M/L) | J2: Rev Visibility (10%) Score | K2: Conf (H/M/L) | L2: FCF Margin Trend (10%) Score | M2: Conf (H/M/L) | N2: Tier 1 Wtd Avg (÷0.70) | O2: Tier 1 Contrib. | P2: Mgmt Quality & Cap Alloc (8%) Score | Q2: Conf (H/M/L) | R2: ROIC vs WACC (6%) Score | S2: Conf (H/M/L) | T2: Rel Strength vs SPY (3%) Score | U2: Conf (H/M/L) | V2: Valuation Multiples (8%) Score | W2: Conf (H/M/L) | X2: Tier 2 Contrib. | Y2: Technical Trend (2%) Score | Z2: Conf (H/M/L) | AA2: Analyst Consensus (2%) Score | AB2: Conf (H/M/L) | AC2: Volume & Accum. (1%) Score | AD2: Conf (H/M/L) | AE2: Tier 3 Contrib. | AF2: Composite Score | AG2: Decision | AH2: Rule 1 Tier1<3.0 | AI2: Rule 2 Any=1 | AJ2: Rule 3 2+≤2=Avoid | AK2: Rule 4 2+Low=Cap Buy
