Workbook

Sheet Instructions
A1: THE LANDRY FAMILY EQUITY INVESTMENT OPERATING SYSTEM — STOCK SCORING & PORTFOLIO RISK WORKBOOK
A3: Companion workbook to Landry System v1.03. Aligned to: Version 1.03 (50 Hard Rules, Parts 1–12).
A4: If the Word document's rule numbers ever change in a future revision, check this line and the rule
A5: references throughout this workbook before relying on them.
A7: HOW TO USE THIS WORKBOOK
A8: 1. Market Data tab — enter or refresh price, volume, market cap, P/E, 52-week range, and dividend
A9: yield for each tracked ticker. Blue cells only. See that tab's note on optional live-data refresh.
A10: 2. Scoring tab — during a scoring session, enter each Tier 1/2/3 indicator's score (1–5) and Confidence
A11: tag (H/M/L) per Part 2's rubrics. The Composite Score, decision classification, and hard-rule flags
A12: (Rules 1–4) calculate automatically.
A13: 3. Dashboard tab — read-only summary of every tracked stock, sortable by Composite Score.
A14: 4. Price History / Returns (Calc) / Correlation Matrix tabs — enter weekly closing prices for current
... A59: a partial current week resamples to a misleading "Friday" label before Friday actually happens.

Sheet Action Items
A1: ACTION ITEMS — everything requiring your decision, pulled live from every other tab. Everything else in this workbook is reference; this is what to open.
A2: Refresh by opening the workbook (F9 recalculates); all cells below are live formulas, nothing here is typed.
A4: 1. WATCH LIST — Rules 31-34 (see Watch List Tracker tab for detail)
A5: Deadlines passed (sell required within 30 days): | E5: =COUNTIF('Watch List Tracker'!K3:K22,"*SELL WITHIN 30 DAYS*") -> 0
A6: Deadlines approaching (within 14 days): | E6: =COUNTIF('Watch List Tracker'!K3:K22,"DEADLINE APPROACHING") -> 0
A7: Recovered — ready to remove/reclassify: | E7: =COUNTIF('Watch List Tracker'!K3:K22,"*RECOVERED*") -> 0
A9: 2. ACTIVE SELL TRIGGERS — Rules 21-30 (see Holding Monitor tab for detail)
A10: Holdings with action required within 30 days: | E10: =COUNTIF('Holding Monitor'!AB4:AB23,"*ACTION REQUIRED*") -> 0
A11: Holdings under Hold Through (monitor only, no action): | E11: =COUNTIF('Holding Monitor'!AB4:AB23,"*Hold Through*") -> 0
A13: 3. CORRELATION CAP — Rule 36 (see Correlation Matrix tab for detail)
A14: Rule 36 status: | E14: ='Correlation Matrix'!J3 -> REVIEW REQUIRED
A15: Positions exceeding cap: | E15: ='Correlation Matrix'!J2 -> 5
A17: 4. PORTFOLIO DRAWDOWN STATUS — Rule 37 (see Portfolio Drawdown Log tab for detail)
A18: Most recent recorded status: | E18: =IFERROR(INDEX('Portfolio Drawdown Log'!E3:E42,COUNT('Portfolio Drawdown Log'!D3:D42)),"No entries yet") -> Normal
A19: Most recent drawdown %: | E19: =IFERROR(INDEX('Portfolio Drawdown Log'!D3:D42,COUNT('Portfolio Drawdown Log'!D3:D42)),"") -> 0
A20: Required cash floor at this level: | E20: =IFERROR(INDEX('Portfolio Drawdown Log'!F3:F42,COUNT('Portfolio Drawdown Log'!D3:D42)),"") -> 5-15%
A22: 5. CANDIDATE SCORING FLAGS — Rules 1-4 (see Scoring tab for detail)
A23: Candidates failing the Tier 1 floor, 3.0 (Rule 1): | E23: =COUNTIF(Scoring!AH3:AH60,"FAIL") -> 19
A24: Candidates auto-classified Avoid (Rule 3): | E24: =COUNTIF(Scoring!AJ3:AJ60,"AVOID") -> 23
A25: Candidates flagged for mandatory Tier 1 review (Rule 2): | E25: =COUNTIF(Scoring!AI3:AI60,"REVIEW") -> 14
A26: Candidates capped at Buy despite Strong Buy score (Rule 4): | E26: =COUNTIF(Scoring!AK3:AK60,"CAP AT BUY") -> 0
A27: 6. ENTRY AUTHORIZATION — Rules 5-13 (see Entry Checklist tab for detail)
A28: Candidates NOT authorized to enter (failing one or more Entry Rules): | E28: =COUNTIF('Entry Checklist'!R3:R47,"NO*") -> 1
A29: Candidates authorized, staged at reduced size (50%, per Rules 8-9): | E29: =COUNTIF('Entry Checklist'!H3:H47,"*50%*") -> 0
A31: 7. PIOTROSKI CROSS-CHECKS -- RETIRED 9/11/26. Tested on an 8-ticker diagnostic batch, dropped as redundant for how this system is actually used (see Journal row 42-43). Historical data left in place at Scoring cols AN-AS as a record of the experiment; no longer live-tallied here.
A32: Candidates flagged LOW CONF on Accruals (CFO does not exceed Net Income): | E32: =COUNTIF(Scoring!AP3:AP60,"LOW CONF") -> 2
A33: Candidates with Debt/FCF trending up year-over-year: | E33: =COUNTIF(Scoring!AS3:AS60,"Increased") -> 5

Sheet Current Positions
A1: Combined current positions, both accounts, as of 09/08/2026 (DCA-TRANCHE-2 executed) -- JT ULTRA (Fidelity); Self-Directed, Chase — cash sweep custodied at Schwab, swept to VMFXX for yield. Source: uploaded brokerage exports + confirmed trade executions, aggregated by ticker. Update this tab at each quarterly/annual review; use it with Part 5 sizing modifiers and the Holding Monitor tab to prescribe classifications and follow-up actions. | O1: TAX-LOSS CARRYFORWARD (update annually)
A2: Account | B2: Ticker | C2: Description | D2: Asset Class | E2: Quantity | F2: Price ($) | G2: Market Value ($) | H2: Cost Basis ($) | I2: Unrealized G/L ($) | J2: Unrealized G/L (%) | K2: % of Account | L2: % of Combined Portfolio | M2: Classification / Notes (fill at review) | O2: Short-Term Loss Carryforward:
A3: JT ULTRA (Fidelity) | B3: ADBE | C3: Adobe Inc. | D3: Equity | E3: 65 | F3: =IF(IFERROR(INDEX('Monitor & Recheck Triggers'!$H$3:$H$48,MATCH($B3,'Monitor & Recheck Triggers'!$A$3:$A$48,0)),"")="",266.51,INDEX('Monitor & Recheck Triggers'!$H$3:$H$48,MATCH($B3,'Monitor & Recheck Triggers'!$A$3:$A$48,0))) -> 266.51 | G3: =E3*F3 -> 17323.15 | H3: 19163.84 | I3: =G3-H3 -> -1840.69 | J3: =IF(H3=0,"",G3/H3-1) -> -0.096050165 | K3: =IFERROR(G3/SUM(G3:G23),"") -> 0.037012962 | L3: =IFERROR(G3/(SUM(G3:G23,G27:G46)),"") -> 0.022304598 | M3: BOUGHT +20sh 8/7/26 @ $266.38 -- DCA tranche 1 diversifier add | O3: Long-Term Loss Carryforward:
A4: JT ULTRA (Fidelity) | B4: ANET | C4: Arista Networks | D4: Equity | E4: 70 | F4: =IF(IFERROR(INDEX('Monitor & Recheck Triggers'!$H$3:$H$48,MATCH($B4,'Monitor & Recheck Triggers'!$A$3:$A$48,0)),"")="",193.78,INDEX('Monitor & Recheck Triggers'!$H$3:$H$48,MATCH($B4,'Monitor & Recheck Triggers'!$A$3:$A$48,0))) -> 193.78 | G4: =E4*F4 -> 13564.6 | H4: 10182.2 | I4: =G4-H4 -> 3382.4 | J4: =IF(H4=0,"",G4/H4-1) -> 0.33218754 | K4: =IFERROR(G4/SUM(G3:G23),"") -> 0.028982375 | L4: =IFERROR(G4/(SUM(G3:G23,G27:G46)),"") -> 0.017465239
A5: JT ULTRA (Fidelity) | B5: ASML | C5: ASML Holding | D5: Equity | E5: 7 | F5: =IF(IFERROR(INDEX('Monitor & Recheck Triggers'!$H$3:$H$48,MATCH($B5,'Monitor & Recheck Triggers'!$A$3:$A$48,0)),"")="",1714.88,INDEX('Monitor & Recheck Triggers'!$H$3:$H$48,MATCH($B5,'Monitor & Recheck Triggers'!$A$3:$A$48,0))) -> 1714.88 | G5: =E5*F5 -> 12004.16 | H5: 9989.88 | I5: =G5-H5 -> 2014.28 | J5: =IF(H5=0,"",G5/H5-1) -> 0.20163205 | K5: =IFERROR(G5/SUM(G3:G23),"") -> 0.02564831 | L5: =IFERROR(G5/(SUM(G3:G23,G27:G46)),"") -> 0.015456079
A6: JT ULTRA (Fidelity) | B6: CRWD | C6: CrowdStrike Holdings | D6: Equity | E6: 40 | F6: =IF(IFERROR(INDEX('Monitor & Recheck Triggers'!$H$3:$H$48,MATCH($B6,'Monitor & Recheck Triggers'!$A$3:$A$48,0)),"")="",213.1,INDEX('Monitor & Recheck Triggers'!$H$3:$H$48,MATCH($B6,'Monitor & Recheck Triggers'!$A$3:$A$48,0))) -> 213.1 | G6: =E6*F6 -> 8524 | H6: 4991.35 | I6: =G6-H6 -> 3532.65 | J6: =IF(H6=0,"",G6/H6-1) -> 0.70775442 | K6: =IFERROR(G6/SUM(G3:G23),"") -> 0.018212536 | L6: =IFERROR(G6/(SUM(G3:G23,G27:G46)),"") -> 0.010975163
A7: JT ULTRA (Fidelity) | B7: KLAC | C7: KLA Corporation | D7: Equity | E7: 100 | F7: =IF(IFERROR(INDEX('Monitor & Recheck Triggers'!$H$3:$H$48,MATCH($B7,'Monitor & Recheck Triggers'!$A$3:$A$48,0)),"")="",185.6,INDEX('Monitor & Recheck Triggers'!$H$3:$H$48,MATCH($B7,'Monitor & Recheck Triggers'!$A$3:$A$48,0))) -> 185.6 | G7: =E7*F7 -> 18560 | H7: 15412.54 | I7: =G7-H7 -> 3147.46 | J7: =IF(H7=0,"",G7/H7-1) -> 0.20421423 | K7: =IFERROR(G7/SUM(G3:G23),"") -> 0.039655639 | L7: =IFERROR(G7/(SUM(G3:G23,G27:G46)),"") -> 0.023897117
A8: JT ULTRA (Fidelity) | B8: MU | C8: Micron Technology | D8: Equity | E8: 7 | F8: =IF(IFERROR(INDEX('Monitor & Recheck Triggers'!$H$3:$H$48,MATCH($B8,'Monitor & Recheck Triggers'!$A$3:$A$48,0)),"")="",1016.59,INDEX('Monitor & Recheck Triggers'!$H$3:$H$48,MATCH($B8,'Monitor & Recheck Triggers'!$A$3:$A$48,0))) -> 1016.59 | G8: =E8*F8 -> 7116.13 | H8: 5836.11 | I8: =G8-H8 -> 1280.02 | J8: =IF(H8=0,"",G8/H8-1) -> 0.2193276 | K8: =IFERROR(G8/SUM(G3:G23),"") -> 0.015204455 | L8: =IFERROR(G8/(SUM(G3:G23,G27:G46)),"") -> 0.0091624457
A9: JT ULTRA (Fidelity) | B9: NVDA | C9: NVIDIA Corporation | D9: Equity | E9: 155 | F9: =IF(IFERROR(INDEX('Monitor & Recheck Triggers'!$H$3:$H$48,MATCH($B9,'Monitor & Recheck Triggers'!$A$3:$A$48,0)),"")="",230.36,INDEX('Monitor & Recheck Triggers'!$H$3:$H$48,MATCH($B9,'Monitor & Recheck Triggers'!$A$3:$A$48,0))) -> 230.36 | G9: =E9*F9 -> 35705.8 | H9: 26639.79 | I9: =G9-H9 -> 9066.01 | J9: =IF(H9=0,"",G9/H9-1) -> 0.34031837 | K9: =IFERROR(G9/SUM(G3:G23),"") -> 0.076289672 | L9: =IFERROR(G9/(SUM(G3:G23,G27:G46)),"") -> 0.045973367
A10: JT ULTRA (Fidelity) | B10: PLTR | C10: Palantir Technologies | D10: Equity | E10: 70 | F10: =IF(IFERROR(INDEX('Monitor & Recheck Triggers'!$H$3:$H$48,MATCH($B10,'Monitor & Recheck Triggers'!$A$3:$A$48,0)),"")="",174.33,INDEX('Monitor & Recheck Triggers'!$H$3:$H$48,MATCH($B10,'Monitor & Recheck Triggers'!$A$3:$A$48,0))) -> 174.33 | G10: =E10*F10 -> 12203.1 | H10: 11612.3 | I10: =G10-H10 -> 590.8 | J10: =IF(H10=0,"",G10/H10-1) -> 0.050877087 | K10: =IFERROR(G10/SUM(G3:G23),"") -> 0.026073369 | L10: =IFERROR(G10/(SUM(G3:G23,G27:G46)),"") -> 0.015712226
A11: JT ULTRA (Fidelity) | B11: TSM | C11: Taiwan Semiconductor | D11: Equity | E11: 25 | F11: =IF(IFERROR(INDEX('Monitor & Recheck Triggers'!$H$3:$H$48,MATCH($B11,'Monitor & Recheck Triggers'!$A$3:$A$48,0)),"")="",428.91,INDEX('Monitor & Recheck Triggers'!$H$3:$H$48,MATCH($B11,'Monitor & Recheck Triggers'!$A$3:$A$48,0))) -> 428.91 | G11: =E11*F11 -> 10722.75 | H11: 6069.64 | I11: =G11-H11 -> 4653.11 | J11: =IF(H11=0,"",G11/H11-1) -> 0.76662043 | K11: =IFERROR(G11/SUM(G3:G23),"") -> 0.022910426 | L11: =IFERROR(G11/(SUM(G3:G23,G27:G46)),"") -> 0.013806186
A12: JT ULTRA (Fidelity) | B12: VRT | C12: Vertiv Holdings | D12: Equity | E12: 30 | F12: =IF(IFERROR(INDEX('Monitor & Recheck Triggers'!$H$3:$H$48,MATCH($B12,'Monitor & Recheck Triggers'!$A$3:$A$48,0)),"")="",280.53,INDEX('Monitor & Recheck Triggers'!$H$3:$H$48,MATCH($B12,'Monitor & Recheck Triggers'!$A$3:$A$48,0))) -> 280.53 | G12: =E12*F12 -> 8415.9 | H12: 7876.8 | I12: =G12-H12 -> 539.1 | J12: =IF(H12=0,"",G12/H12-1) -> 0.068441499 | K12: =IFERROR(G12/SUM(G3:G23),"") -> 0.017981567 | L12: =IFERROR(G12/(SUM(G3:G23,G27:G46)),"") -> 0.010835978
A13: JT ULTRA (Fidelity) | B13: V | C13: Visa Inc. | D13: Equity | E13: 50 | F13: =IF(IFERROR(INDEX('Monitor & Recheck Triggers'!$H$3:$H$48,MATCH($B13,'Monitor & Recheck Triggers'!$A$3:$A$48,0)),"")="",367.68,INDEX('Monitor & Recheck Triggers'!$H$3:$H$48,MATCH($B13,'Monitor & Recheck Triggers'!$A$3:$A$48,0))) -> 367.68 | G13: =E13*F13 -> 18384 | H13: 18448.63 | I13: =G13-H13 -> -64.63 | J13: =IF(H13=0,"",G13/H13-1) -> -0.0035032412 | K13: =IFERROR(G13/SUM(G3:G23),"") -> 0.039279594 | L13: =IFERROR(G13/(SUM(G3:G23,G27:G46)),"") -> 0.023670506 | M13: NEW position 9/8/26 -- DCA-TRANCHE-2, opened per Entry Checklist authorization (Composite 86.4, STRONG BUY). 2 lots: 25sh @ $368.38 + 25sh @ $369.565.
A14: JT ULTRA (Fidelity) | B14: FZDXX | C14: Fidelity Money Market Premium | D14: Cash | E14: 92777.34 | F14: 1 | G14: =E14*F14 -> 92777.34 | H14: 137296.09 | I14: =G14-H14 -> -44518.75 | J14: =IF(H14=0,"",G14/H14-1) -> -0.32425359 | K14: =IFERROR(G14/SUM(G3:G23),"") -> 0.19822978 | L14: =IFERROR(G14/(SUM(G3:G23,G27:G46)),"") -> 0.11945641
A15: JT ULTRA (Fidelity) | B15: FZFXX | C15: Fidelity Core Money Market | D15: Cash | E15: 0 | F15: 1 | G15: =E15*F15 -> 0 | H15: 23 | I15: =G15-H15 -> -23 | J15: =IF(H15=0,"",G15/H15-1) -> -1 | K15: =IFERROR(G15/SUM(G3:G23),"") -> 0 | L15: =IFERROR(G15/(SUM(G3:G23,G27:G46)),"") -> 0
A16: JT ULTRA (Fidelity) | B16: DVY | C16: iShares Select Dividend ETF | D16: Equity | E16: 150 | F16: =IF(IFERROR(INDEX('Monitor & Recheck Triggers'!$H$3:$H$48,MATCH($B16,'Monitor & Recheck Triggers'!$A$3:$A$48,0)),"")="",164.25,INDEX('Monitor & Recheck Triggers'!$H$3:$H$48,MATCH($B16,'Monitor & Recheck Triggers'!$A$3:$A$48,0))) -> 164.25 | G16: =E16*F16 -> 24637.5 | H16: 24518.25 | I16: =G16-H16 -> 119.25 | J16: =IF(H16=0,"",G16/H16-1) -> 0.004863724 | K16: =IFERROR(G16/SUM(G3:G23),"") -> 0.052640938 | L16: =IFERROR(G16/(SUM(G3:G23,G27:G46)),"") -> 0.031722264 | M16: NEW position since 8/5/26 -- cash/dry powder per Alan 9/7/26, not a scored Landry position.
A17: JT ULTRA (Fidelity) | B17: VFLO | C17: VictoryShares Free Cash Flow ETF | D17: Equity | E17: 451.304 | F17: =IF(IFERROR(INDEX('Monitor & Recheck Triggers'!$H$3:$H$48,MATCH($B17,'Monitor & Recheck Triggers'!$A$3:$A$48,0)),"")="",55.29,INDEX('Monitor & Recheck Triggers'!$H$3:$H$48,MATCH($B17,'Monitor & Recheck Triggers'!$A$3:$A$48,0))) -> 55.29 | G17: =E17*F17 -> 24952.598 | H17: 24999.99 | I17: =G17-H17 -> -47.39184 | J17: =IF(H17=0,"",G17/H17-1) -> -0.0018956744 | K17: =IFERROR(G17/SUM(G3:G23),"") -> 0.053314182 | L17: =IFERROR(G17/(SUM(G3:G23,G27:G46)),"") -> 0.032127972 | M17: NEW to this account since 8/5/26 (already held in Self-Directed) -- cash/dry powder per Alan 9/7/26, not a scored Landry position.
A18: JT ULTRA (Fidelity) | B18: SCHD | C18: Schwab US Dividend Equity ETF | D18: Equity | E18: 700 | F18: =IF(IFERROR(INDEX('Monitor & Recheck Triggers'!$H$3:$H$48,MATCH($B18,'Monitor & Recheck Triggers'!$A$3:$A$48,0)),"")="",34.8,INDEX('Monitor & Recheck Triggers'!$H$3:$H$48,MATCH($B18,'Monitor & Recheck Triggers'!$A$3:$A$48,0))) -> 34.8 | G18: =E18*F18 -> 24360 | H18: 24377.5 | I18: =G18-H18 -> -17.5 | J18: =IF(H18=0,"",G18/H18-1) -> -0.00071787509 | K18: =IFERROR(G18/SUM(G3:G23),"") -> 0.052048026 | L18: =IFERROR(G18/(SUM(G3:G23,G27:G46)),"") -> 0.031364966 | M18: NEW position since 8/5/26 -- cash/dry powder per Alan 9/7/26, not a scored Landry position.
A19: JT ULTRA (Fidelity) | B19: VYM | C19: Vanguard High Dividend Yield ETF | D19: Equity | E19: 150 | F19: =IF(IFERROR(INDEX('Monitor & Recheck Triggers'!$H$3:$H$48,MATCH($B19,'Monitor & Recheck Triggers'!$A$3:$A$48,0)),"")="",164.23,INDEX('Monitor & Recheck Triggers'!$H$3:$H$48,MATCH($B19,'Monitor & Recheck Triggers'!$A$3:$A$48,0))) -> 164.23 | G19: =E19*F19 -> 24634.5 | H19: 24598.5 | I19: =G19-H19 -> 36 | J19: =IF(H19=0,"",G19/H19-1) -> 0.0014635039 | K19: =IFERROR(G19/SUM(G3:G23),"") -> 0.052634528 | L19: =IFERROR(G19/(SUM(G3:G23,G27:G46)),"") -> 0.031718401 | M19: NEW position since 8/5/26 -- cash/dry powder per Alan 9/7/26, not a scored Landry position.
A20: JT ULTRA (Fidelity) | B20: MLPI | C20: NEOS MLP & Energy Income ETF | D20: Equity | E20: 1000 | F20: =IF(IFERROR(INDEX('Monitor & Recheck Triggers'!$H$3:$H$48,MATCH($B20,'Monitor & Recheck Triggers'!$A$3:$A$48,0)),"")="",54.63,INDEX('Monitor & Recheck Triggers'!$H$3:$H$48,MATCH($B20,'Monitor & Recheck Triggers'!$A$3:$A$48,0))) -> 54.63 | G20: =E20*F20 -> 54630 | H20: 53709 | I20: =G20-H20 -> 921 | J20: =IF(H20=0,"",G20/H20-1) -> 0.017147964 | K20: =IFERROR(G20/SUM(G3:G23),"") -> 0.11672347 | L20: =IFERROR(G20/(SUM(G3:G23,G27:G46)),"") -> 0.070339413 | M20: NEW position since 8/5/26 -- cash/dry powder per Alan 9/7/26, not a scored Landry position.
A21: JT ULTRA (Fidelity) | B21: SPMO | C21: Invesco S&P 500 Momentum ETF | D21: Equity | E21: 100 | F21: =IF(IFERROR(INDEX('Monitor & Recheck Triggers'!$H$3:$H$48,MATCH($B21,'Monitor & Recheck Triggers'!$A$3:$A$48,0)),"")="",149.72,INDEX('Monitor & Recheck Triggers'!$H$3:$H$48,MATCH($B21,'Monitor & Recheck Triggers'!$A$3:$A$48,0))) -> 149.72 | G21: =E21*F21 -> 14972 | H21: 14696.99 | I21: =G21-H21 -> 275.01 | J21: =IF(H21=0,"",G21/H21-1) -> 0.018711995 | K21: =IFERROR(G21/SUM(G3:G23),"") -> 0.031989452 | L21: =IFERROR(G21/(SUM(G3:G23,G27:G46)),"") -> 0.019277351 | M21: NEW to this account since 8/5/26 (already held in Self-Directed) -- cash/dry powder per Alan 9/7/26, not a scored Landry position.
A22: JT ULTRA (Fidelity) | B22: GE | C22: GE Aerospace | D22: Equity | E22: 75 | F22: =IF(IFERROR(INDEX('Monitor & Recheck Triggers'!$H$3:$H$48,MATCH($B22,'Monitor & Recheck Triggers'!$A$3:$A$48,0)),"")="",314.71,INDEX('Monitor & Recheck Triggers'!$H$3:$H$48,MATCH($B22,'Monitor & Recheck Triggers'!$A$3:$A$48,0))) -> 314.71 | G22: =E22*F22 -> 23603.25 | H22: 23603.25 | I22: =G22-H22 -> 0 | J22: =IF(H22=0,"",G22/H22-1) -> 0 | K22: =IFERROR(G22/SUM(G3:G23),"") -> 0.05043114 | L22: =IFERROR(G22/(SUM(G3:G23,G27:G46)),"") -> 0.030390605 | M22: NEW position 9/30/26 -- DCA-CATCHUP-1, opened per Composite 84.2 STRONG BUY (rescored 9/13/26, reconfirmed fresh 9/29/26, zero Tier 1 drift). 75sh @ $314.71.
A23: JT ULTRA (Fidelity) | B23: NFLX | C23: Netflix, Inc. | D23: Equity | E23: 300 | F23: =IF(IFERROR(INDEX('Monitor & Recheck Triggers'!$H$3:$H$48,MATCH($B23,'Monitor & Recheck Triggers'!$A$3:$A$48,0)),"")="",69.795,INDEX('Monitor & Recheck Triggers'!$H$3:$H$48,MATCH($B23,'Monitor & Recheck Triggers'!$A$3:$A$48,0))) -> 69.795 | G23: =E23*F23 -> 20938.5 | H23: 20938.5 | I23: =G23-H23 -> 0 | J23: =IF(H23=0,"",G23/H23-1) -> 0 | K23: =IFERROR(G23/SUM(G3:G23),"") -> 0.044737586 | L23: =IFERROR(G23/(SUM(G3:G23,G27:G46)),"") -> 0.026959579 | M23: NEW position 9/30/26 -- DCA-CATCHUP-1, opened per Composite 83.8 STRONG BUY (rescored 9/13/26, reconfirmed fresh 9/29/26, zero Tier 1 drift). 300sh @ $69.795.
A24: Positions | B24: =SUBTOTAL(103,B3:B23) -> 21 | C24: JT ULTRA (Fidelity) SUBTOTAL | G24: =SUM(G3:G23) -> 468029.28 | H24: =SUM(H3:H23) -> 484984.15 | I24: =SUM(I3:I23) -> -16954.872 | J24: =CurrentPositionsTable[[#This Row],[Unrealized G/L ($)]]/CurrentPositionsTable[[#This Row],[Cost Basis ($)]] -> -0.034959641 | K24: =SUM(K3:K23) -> 1 | L24: =SUM(L3:L23) -> 0.60261587
I25: Excluding Cash | J25: =I24/(H24-H14-H13) -> -0.051497088
A27: Self-Directed (Chase) | B27: VMFXX | C27: Vanguard Federal Money Market | D27: Cash | E27: 36854.47 | F27: 1 | G27: =E27*F27 -> 36854.47 | H27: 36854.47 | I27: =G27-H27 -> 0 | J27: =IF(H27=0,"",G27/H27-1) -> 0 | K27: =IFERROR(G27/SUM(G27:G46),"") -> 0.11941178 | L27: =IFERROR(G27/(SUM(G3:G23,G27:G46)),"") -> 0.047452348
A28: Self-Directed (Chase) | B28: JEPQ | C28: JPMorgan Nasdaq Equity Premium Income ETF | D28: Alternative Assets | E28: 850.35693 | F28: =IF(IFERROR(INDEX('Monitor & Recheck Triggers'!$H$3:$H$48,MATCH($B28,'Monitor & Recheck Triggers'!$A$3:$A$48,0)),"")="",59.87,INDEX('Monitor & Recheck Triggers'!$H$3:$H$48,MATCH($B28,'Monitor & Recheck Triggers'!$A$3:$A$48,0))) -> 59.87 | G28: =E28*F28 -> 50910.869 | H28: 43005.36 | I28: =G28-H28 -> 7905.5094 | J28: =IF(H28=0,"",G28/H28-1) -> 0.18382614 | K28: =IFERROR(G28/SUM(G27:G46),"") -> 0.16495578 | L28: =IFERROR(G28/(SUM(G3:G23,G27:G46)),"") -> 0.065550809 | M28: Qty 840.4->850.4sh since 8/5, likely DRIP reinvestment. Reclassified as cash/dry powder per Alan 9/7/26, not a scored Landry position.
A29: Self-Directed (Chase) | B29: AVUV | C29: Avantis US Small Cap Value ETF | D29: Equity | E29: 400.00001 | F29: =IF(IFERROR(INDEX('Monitor & Recheck Triggers'!$H$3:$H$48,MATCH($B29,'Monitor & Recheck Triggers'!$A$3:$A$48,0)),"")="",126.93,INDEX('Monitor & Recheck Triggers'!$H$3:$H$48,MATCH($B29,'Monitor & Recheck Triggers'!$A$3:$A$48,0))) -> 126.93 | G29: =E29*F29 -> 50772.001 | H29: 45116.29 | I29: =G29-H29 -> 5655.7113 | J29: =IF(H29=0,"",G29/H29-1) -> 0.12535852 | K29: =IFERROR(G29/SUM(G27:G46),"") -> 0.16450583 | L29: =IFERROR(G29/(SUM(G3:G23,G27:G46)),"") -> 0.065372007 | M29: BOUGHT +193.58sh 8/7/26 @ $126.66 -- consolidation target from CALF
A30: Self-Directed (Chase) | B30: CALF | C30: Pacer US Small Cap Cash Cows ETF | D30: Equity | E30: 0 | F30: =IF(IFERROR(INDEX('Monitor & Recheck Triggers'!$H$3:$H$48,MATCH($B30,'Monitor & Recheck Triggers'!$A$3:$A$48,0)),"")="",56.12,INDEX('Monitor & Recheck Triggers'!$H$3:$H$48,MATCH($B30,'Monitor & Recheck Triggers'!$A$3:$A$48,0))) -> 56.12 | G30: =E30*F30 -> 0 | H30: 0 | I30: =G30-H30 -> 0 | J30: =IF(H30=0,"",G30/H30-1) | K30: =IFERROR(G30/SUM(G27:G46),"") -> 0 | L30: =IFERROR(G30/(SUM(G3:G23,G27:G46)),"") -> 0 | M30: SOLD 8/7/26 -- confirmed: -409.55sh, $23,016.52 proceeds. Consolidated into AVUV.
A31: Self-Directed (Chase) | B31: HELO | C31: JPMorgan Hedged Equity Laddered Overlay ETF | D31: Alternative Assets | E31: 500 | F31: =IF(IFERROR(INDEX('Monitor & Recheck Triggers'!$H$3:$H$48,MATCH($B31,'Monitor & Recheck Triggers'!$A$3:$A$48,0)),"")="",69.72,INDEX('Monitor & Recheck Triggers'!$H$3:$H$48,MATCH($B31,'Monitor & Recheck Triggers'!$A$3:$A$48,0))) -> 69.72 | G31: =E31*F31 -> 34860 | H31: 30666 | I31: =G31-H31 -> 4194 | J31: =IF(H31=0,"",G31/H31-1) -> 0.13676384 | K31: =IFERROR(G31/SUM(G27:G46),"") -> 0.11294952 | L31: =IFERROR(G31/(SUM(G3:G23,G27:G46)),"") -> 0.044884348 | M31: BOUGHT +200sh since 8/5 (300->500sh) -- expanding income sleeve. Reclassified as cash/dry powder per Alan 9/7/26, not a scored Landry position.
A32: Self-Directed (Chase) | B32: AVGO | C32: Broadcom Inc. | D32: Equity | E32: 35.07587 | F32: =IF(IFERROR(INDEX('Monitor & Recheck Triggers'!$H$3:$H$48,MATCH($B32,'Monitor & Recheck Triggers'!$A$3:$A$48,0)),"")="",357.895,INDEX('Monitor & Recheck Triggers'!$H$3:$H$48,MATCH($B32,'Monitor & Recheck Triggers'!$A$3:$A$48,0))) -> 357.895 | G32: =E32*F32 -> 12553.478 | H32: 12653.43 | I32: =G32-H32 -> -99.951506 | J32: =IF(H32=0,"",G32/H32-1) -> -0.007899163 | K32: =IFERROR(G32/SUM(G27:G46),"") -> 0.040674395 | L32: =IFERROR(G32/(SUM(G3:G23,G27:G46)),"") -> 0.016163359
A33: Self-Directed (Chase) | B33: NVDA | C33: NVIDIA Corporation | D33: Equity | E33: 59.02188 | F33: =IF(IFERROR(INDEX('Monitor & Recheck Triggers'!$H$3:$H$48,MATCH($B33,'Monitor & Recheck Triggers'!$A$3:$A$48,0)),"")="",230.36,INDEX('Monitor & Recheck Triggers'!$H$3:$H$48,MATCH($B33,'Monitor & Recheck Triggers'!$A$3:$A$48,0))) -> 230.36 | G33: =E33*F33 -> 13596.28 | H33: 11377.73 | I33: =G33-H33 -> 2218.5503 | J33: =IF(H33=0,"",G33/H33-1) -> 0.19499059 | K33: =IFERROR(G33/SUM(G27:G46),"") -> 0.044053166 | L33: =IFERROR(G33/(SUM(G3:G23,G27:G46)),"") -> 0.017506029
A34: Self-Directed (Chase) | B34: VRTX | C34: Vertex Pharmaceuticals | D34: Equity | E34: 65 | F34: =IF(IFERROR(INDEX('Monitor & Recheck Triggers'!$H$3:$H$48,MATCH($B34,'Monitor & Recheck Triggers'!$A$3:$A$48,0)),"")="",528.64,INDEX('Monitor & Recheck Triggers'!$H$3:$H$48,MATCH($B34,'Monitor & Recheck Triggers'!$A$3:$A$48,0))) -> 528.64 | G34: =E34*F34 -> 34361.6 | H34: 31479.64 | I34: =G34-H34 -> 2881.96 | J34: =IF(H34=0,"",G34/H34-1) -> 0.091549967 | K34: =IFERROR(G34/SUM(G27:G46),"") -> 0.11133466 | L34: =IFERROR(G34/(SUM(G3:G23,G27:G46)),"") -> 0.044242628 | M34: BOUGHT +15sh 9/8/26 @ ~$527.47 ($7,912.09) -- DCA-TRANCHE-2 diversifier add.
A35: Self-Directed (Chase) | B35: SPMO | C35: Invesco S&P 500 Momentum ETF | D35: Equity | E35: 76.93745 | F35: =IF(IFERROR(INDEX('Monitor & Recheck Triggers'!$H$3:$H$48,MATCH($B35,'Monitor & Recheck Triggers'!$A$3:$A$48,0)),"")="",149.72,INDEX('Monitor & Recheck Triggers'!$H$3:$H$48,MATCH($B35,'Monitor & Recheck Triggers'!$A$3:$A$48,0))) -> 149.72 | G35: =E35*F35 -> 11519.075 | H35: 9318.79 | I35: =G35-H35 -> 2200.285 | J35: =IF(H35=0,"",G35/H35-1) -> 0.23611274 | K35: =IFERROR(G35/SUM(G27:G46),"") -> 0.037322835 | L35: =IFERROR(G35/(SUM(G3:G23,G27:G46)),"") -> 0.014831502
A36: Self-Directed (Chase) | B36: VFLO | C36: VictoryShares Free Cash Flow ETF | D36: Equity | E36: 200 | F36: =IF(IFERROR(INDEX('Monitor & Recheck Triggers'!$H$3:$H$48,MATCH($B36,'Monitor & Recheck Triggers'!$A$3:$A$48,0)),"")="",55.29,INDEX('Monitor & Recheck Triggers'!$H$3:$H$48,MATCH($B36,'Monitor & Recheck Triggers'!$A$3:$A$48,0))) -> 55.29 | G36: =E36*F36 -> 11058 | H36: 9257 | I36: =G36-H36 -> 1801 | J36: =IF(H36=0,"",G36/H36-1) -> 0.19455547 | K36: =IFERROR(G36/SUM(G27:G46),"") -> 0.03582891 | L36: =IFERROR(G36/(SUM(G3:G23,G27:G46)),"") -> 0.014237841
A37: Self-Directed (Chase) | B37: ANET | C37: Arista Networks | D37: Equity | E37: 50 | F37: =IF(IFERROR(INDEX('Monitor & Recheck Triggers'!$H$3:$H$48,MATCH($B37,'Monitor & Recheck Triggers'!$A$3:$A$48,0)),"")="",193.78,INDEX('Monitor & Recheck Triggers'!$H$3:$H$48,MATCH($B37,'Monitor & Recheck Triggers'!$A$3:$A$48,0))) -> 193.78 | G37: =E37*F37 -> 9689 | H37: 7394.5 | I37: =G37-H37 -> 2294.5 | J37: =IF(H37=0,"",G37/H37-1) -> 0.31029819 | K37: =IFERROR(G37/SUM(G27:G46),"") -> 0.031393228 | L37: =IFERROR(G37/(SUM(G3:G23,G27:G46)),"") -> 0.012475171
A38: Self-Directed (Chase) | B38: CRWD | C38: CrowdStrike Holdings | D38: Equity | E38: 45 | F38: =IF(IFERROR(INDEX('Monitor & Recheck Triggers'!$H$3:$H$48,MATCH($B38,'Monitor & Recheck Triggers'!$A$3:$A$48,0)),"")="",213.1,INDEX('Monitor & Recheck Triggers'!$H$3:$H$48,MATCH($B38,'Monitor & Recheck Triggers'!$A$3:$A$48,0))) -> 213.1 | G38: =E38*F38 -> 9589.5 | H38: 7099.31 | I38: =G38-H38 -> 2490.19 | J38: =IF(H38=0,"",G38/H38-1) -> 0.35076507 | K38: =IFERROR(G38/SUM(G27:G46),"") -> 0.031070839 | L38: =IFERROR(G38/(SUM(G3:G23,G27:G46)),"") -> 0.012347058
A39: Self-Directed (Chase) | B39: PLD | C39: Prologis Inc. | D39: Equity | E39: 125.44837 | F39: =IF(IFERROR(INDEX('Monitor & Recheck Triggers'!$H$3:$H$48,MATCH($B39,'Monitor & Recheck Triggers'!$A$3:$A$48,0)),"")="",137.34,INDEX('Monitor & Recheck Triggers'!$H$3:$H$48,MATCH($B39,'Monitor & Recheck Triggers'!$A$3:$A$48,0))) -> 137.34 | G39: =E39*F39 -> 17229.079 | H39: 16585.43 | I39: =G39-H39 -> 643.64914 | J39: =IF(H39=0,"",G39/H39-1) -> 0.038808107 | K39: =IFERROR(G39/SUM(G27:G46),"") -> 0.05582376 | L39: =IFERROR(G39/(SUM(G3:G23,G27:G46)),"") -> 0.022183476 | M39: BOUGHT +64sh 8/7/26 @ $139.92 -- DCA tranche 1 diversifier add
A40: Self-Directed (Chase) | B40: SFM | C40: Sprouts Farmers Market | D40: Equity | E40: 0 | F40: =IF(IFERROR(INDEX('Monitor & Recheck Triggers'!$H$3:$H$48,MATCH($B40,'Monitor & Recheck Triggers'!$A$3:$A$48,0)),"")="",86.07,INDEX('Monitor & Recheck Triggers'!$H$3:$H$48,MATCH($B40,'Monitor & Recheck Triggers'!$A$3:$A$48,0))) -> 86.07 | G40: =E40*F40 -> 0 | H40: 0 | I40: =G40-H40 -> 0 | J40: =IF(H40=0,"",G40/H40-1) | K40: =IFERROR(G40/SUM(G27:G46),"") -> 0 | L40: =IFERROR(G40/(SUM(G3:G23,G27:G46)),"") -> 0 | M40: SOLD 08/07/26 -- confirmed: -65 sh, $5,601.58 proceeds. Rule 3 Avoid. Proceeds added to VMFXX.
A41: Self-Directed (Chase) | B41: TSLA | C41: Tesla Inc. | D41: Equity | E41: 0 | F41: =IF(IFERROR(INDEX('Monitor & Recheck Triggers'!$H$3:$H$48,MATCH($B41,'Monitor & Recheck Triggers'!$A$3:$A$48,0)),"")="",327.35,INDEX('Monitor & Recheck Triggers'!$H$3:$H$48,MATCH($B41,'Monitor & Recheck Triggers'!$A$3:$A$48,0))) -> 327.35 | G41: =E41*F41 -> 0 | H41: 0 | I41: =G41-H41 -> 0 | J41: =IF(H41=0,"",G41/H41-1) | K41: =IFERROR(G41/SUM(G27:G46),"") -> 0 | L41: =IFERROR(G41/(SUM(G3:G23,G27:G46)),"") -> 0 | M41: SOLD 08/07/26 -- confirmed: -15 sh, $4,783.25 proceeds. Rule 3 Avoid. Proceeds added to VMFXX.
...

Sheet Monitor & Recheck Triggers
A1: Recheck triggers for every name that's been scored, not just Watch List holdings. Current Price, Insider Activity, and Analyst Shift are Claude-populated (STOCKHISTORY formula + manual recalc for price; SEC EDGAR and yfinance consensus data for the other two, refreshed periodically, not live). Recheck Status calculates automatically from all signals together.
A2: Ticker | B2: Category | C2: Last Score Date | D2: Last Composite | E2: Last Tier 1 Wtd Avg | F2: Last Decision | G2: Price at Last Score | H2: Current Price | I2: % Price Change | J2: Next/Last Earnings Date | K2: Insider Activity? (Y/N) | L2: Insider Note | M2: Analyst Shift? (Y/N) | N2: Analyst Shift Note | O2: Days Since Last Score | P2: Recheck Status | Q2: Notes
A3: ADBE | B3: Owned | C3: 46240 | D3: 85.8 | E3: 4.57 | F3: STRONG BUY | G3: 259.32 | H3: {=IFERROR(INDEX(_xlfn.stockhistory(A3,TODAY()-5,TODAY(),0,0,1),ROWS(_xlfn.stockhistory(A3,TODAY()-5,TODAY(),0,0,1)),1),"")} | I3: =IF(OR(G3="",H3=""),"",H3/G3-1) | J3: 46275 | K3: N | M3: N | O3: =IF(C3="","",TODAY()-C3) -> 55 | P3: =IF(A3="","",IF(O3>180,"DUE — STALE (>180 days)",IF(J3<>"",IF(ABS(J3-TODAY())<=7,"DUE — EARNINGS WINDOW",IF(I3<>"",IF(ABS(I3)>=0.2,"DUE — PRICE MOVE ±20%",IF(K3="Y","DUE — INSIDER ACTIVITY",IF(I3<>"",IF(ABS(I3)>=0.15,"WATCH — PRICE MOVE ±15%",IF(M3="Y","WATCH — ANALYST SHIFT","Monitor Only")),IF(M3="Y","WATCH — ANALYST SHIFT","Monitor Only")))),IF(K3="Y","DUE — INSIDER ACTIVITY",IF(I3<>"",IF(ABS(I3)>=0.15,"WATCH — PRICE MOVE ±15%",IF(M3="Y","WATCH — ANALYST SHIFT","Monitor Only")),IF(M3="Y","WATCH — ANALYST SHIFT","Monitor Only"))))),IF(I3<>"",IF(ABS(I3)>=0.2,"DUE — PRICE MOVE ±20%",IF(K3="Y","DUE — INSIDER ACTIVITY",IF(I3<>"",IF(ABS(I3)>=0.15,"WATCH — PRICE MOVE ±15%",IF(M3="Y","WATCH — ANALYST SHIFT","Monitor Only")),IF(M3="Y","WATCH — ANALYST SHIFT","Monitor Only")))),IF(K3="Y","DUE — INSIDER ACTIVITY",IF(I3<>"",IF(ABS(I3)>=0.15,"WATCH — PRICE MOVE ±15%",IF(M3="Y","WATCH — ANALYST SHIFT","Monitor Only")),IF(M3="Y","WATCH — ANALYST SHIFT","Monitor Only"))))))) -> Monitor Only
A4: ANET | B4: Owned | C4: 46240 | D4: 85 | E4: 4.57 | F4: STRONG BUY | G4: 190.51 | H4: {=IFERROR(INDEX(_xlfn.stockhistory(A4,TODAY()-5,TODAY(),0,0,1),ROWS(_xlfn.stockhistory(A4,TODAY()-5,TODAY(),0,0,1)),1),"")} | I4: =IF(OR(G4="",H4=""),"",H4/G4-1) | J4: 46329 | K4: Y | L4: 2026-09-03: Breithaupt Chantelle Yvette (Senior Vice President, CFO) sold $119,811, 1% of holding (+55 more in last 30d) | M4: N | O4: =IF(C4="","",TODAY()-C4) -> 55 | P4: =IF(A4="","",IF(O4>180,"DUE — STALE (>180 days)",IF(J4<>"",IF(ABS(J4-TODAY())<=7,"DUE — EARNINGS WINDOW",IF(I4<>"",IF(ABS(I4)>=0.2,"DUE — PRICE MOVE ±20%",IF(K4="Y","DUE — INSIDER ACTIVITY",IF(I4<>"",IF(ABS(I4)>=0.15,"WATCH — PRICE MOVE ±15%",IF(M4="Y","WATCH — ANALYST SHIFT","Monitor Only")),IF(M4="Y","WATCH — ANALYST SHIFT","Monitor Only")))),IF(K4="Y","DUE — INSIDER ACTIVITY",IF(I4<>"",IF(ABS(I4)>=0.15,"WATCH — PRICE MOVE ±15%",IF(M4="Y","WATCH — ANALYST SHIFT","Monitor Only")),IF(M4="Y","WATCH — ANALYST SHIFT","Monitor Only"))))),IF(I4<>"",IF(ABS(I4)>=0.2,"DUE — PRICE MOVE ±20%",IF(K4="Y","DUE — INSIDER ACTIVITY",IF(I4<>"",IF(ABS(I4)>=0.15,"WATCH — PRICE MOVE ±15%",IF(M4="Y","WATCH — ANALYST SHIFT","Monitor Only")),IF(M4="Y","WATCH — ANALYST SHIFT","Monitor Only")))),IF(K4="Y","DUE — INSIDER ACTIVITY",IF(I4<>"",IF(ABS(I4)>=0.15,"WATCH — PRICE MOVE ±15%",IF(M4="Y","WATCH — ANALYST SHIFT","Monitor Only")),IF(M4="Y","WATCH — ANALYST SHIFT","Monitor Only"))))))) -> DUE — INSIDER ACTIVITY
A5: ASML | B5: Owned | C5: 46240 | D5: 73.2 | E5: 3.57 | F5: BUY | G5: 1678.22 | H5: {=IFERROR(INDEX(_xlfn.stockhistory(A5,TODAY()-5,TODAY(),0,0,1),ROWS(_xlfn.stockhistory(A5,TODAY()-5,TODAY(),0,0,1)),1),"")} | I5: =IF(OR(G5="",H5=""),"",H5/G5-1) | J5: 46309 | K5: N | M5: N | O5: =IF(C5="","",TODAY()-C5) -> 55 | P5: =IF(A5="","",IF(O5>180,"DUE — STALE (>180 days)",IF(J5<>"",IF(ABS(J5-TODAY())<=7,"DUE — EARNINGS WINDOW",IF(I5<>"",IF(ABS(I5)>=0.2,"DUE — PRICE MOVE ±20%",IF(K5="Y","DUE — INSIDER ACTIVITY",IF(I5<>"",IF(ABS(I5)>=0.15,"WATCH — PRICE MOVE ±15%",IF(M5="Y","WATCH — ANALYST SHIFT","Monitor Only")),IF(M5="Y","WATCH — ANALYST SHIFT","Monitor Only")))),IF(K5="Y","DUE — INSIDER ACTIVITY",IF(I5<>"",IF(ABS(I5)>=0.15,"WATCH — PRICE MOVE ±15%",IF(M5="Y","WATCH — ANALYST SHIFT","Monitor Only")),IF(M5="Y","WATCH — ANALYST SHIFT","Monitor Only"))))),IF(I5<>"",IF(ABS(I5)>=0.2,"DUE — PRICE MOVE ±20%",IF(K5="Y","DUE — INSIDER ACTIVITY",IF(I5<>"",IF(ABS(I5)>=0.15,"WATCH — PRICE MOVE ±15%",IF(M5="Y","WATCH — ANALYST SHIFT","Monitor Only")),IF(M5="Y","WATCH — ANALYST SHIFT","Monitor Only")))),IF(K5="Y","DUE — INSIDER ACTIVITY",IF(I5<>"",IF(ABS(I5)>=0.15,"WATCH — PRICE MOVE ±15%",IF(M5="Y","WATCH — ANALYST SHIFT","Monitor Only")),IF(M5="Y","WATCH — ANALYST SHIFT","Monitor Only"))))))) -> Monitor Only
A6: CRWD | B6: Owned | C6: 46240 | D6: 70.4 | E6: 4 | F6: BUY | G6: 211.22 | H6: {=IFERROR(INDEX(_xlfn.stockhistory(A6,TODAY()-5,TODAY(),0,0,1),ROWS(_xlfn.stockhistory(A6,TODAY()-5,TODAY(),0,0,1)),1),"")} | I6: =IF(OR(G6="",H6=""),"",H6/G6-1) | J6: 46357 | K6: Y | L6: 2026-09-04: Kurtz George (PRESIDENT AND CEO) sold $472,759, 0% of holding (+126 more in last 30d) | M6: N | O6: =IF(C6="","",TODAY()-C6) -> 55 | P6: =IF(A6="","",IF(O6>180,"DUE — STALE (>180 days)",IF(J6<>"",IF(ABS(J6-TODAY())<=7,"DUE — EARNINGS WINDOW",IF(I6<>"",IF(ABS(I6)>=0.2,"DUE — PRICE MOVE ±20%",IF(K6="Y","DUE — INSIDER ACTIVITY",IF(I6<>"",IF(ABS(I6)>=0.15,"WATCH — PRICE MOVE ±15%",IF(M6="Y","WATCH — ANALYST SHIFT","Monitor Only")),IF(M6="Y","WATCH — ANALYST SHIFT","Monitor Only")))),IF(K6="Y","DUE — INSIDER ACTIVITY",IF(I6<>"",IF(ABS(I6)>=0.15,"WATCH — PRICE MOVE ±15%",IF(M6="Y","WATCH — ANALYST SHIFT","Monitor Only")),IF(M6="Y","WATCH — ANALYST SHIFT","Monitor Only"))))),IF(I6<>"",IF(ABS(I6)>=0.2,"DUE — PRICE MOVE ±20%",IF(K6="Y","DUE — INSIDER ACTIVITY",IF(I6<>"",IF(ABS(I6)>=0.15,"WATCH — PRICE MOVE ±15%",IF(M6="Y","WATCH — ANALYST SHIFT","Monitor Only")),IF(M6="Y","WATCH — ANALYST SHIFT","Monitor Only")))),IF(K6="Y","DUE — INSIDER ACTIVITY",IF(I6<>"",IF(ABS(I6)>=0.15,"WATCH — PRICE MOVE ±15%",IF(M6="Y","WATCH — ANALYST SHIFT","Monitor Only")),IF(M6="Y","WATCH — ANALYST SHIFT","Monitor Only"))))))) -> DUE — INSIDER ACTIVITY
A7: KLAC | B7: Owned | C7: 46240 | D7: 68.6 | E7: 3.43 | F7: BUY | G7: 192.8 | H7: {=IFERROR(INDEX(_xlfn.stockhistory(A7,TODAY()-5,TODAY(),0,0,1),ROWS(_xlfn.stockhistory(A7,TODAY()-5,TODAY(),0,0,1)),1),"")} | I7: =IF(OR(G7="",H7=""),"",H7/G7-1) | J7: 46323 | K7: Y | L7: 2026-08-14: Lorig Brian (EVP, KLA Global Services) sold $12,401,634, 43% of holding (+7 more in last 30d) | M7: N | O7: =IF(C7="","",TODAY()-C7) -> 55 | P7: =IF(A7="","",IF(O7>180,"DUE — STALE (>180 days)",IF(J7<>"",IF(ABS(J7-TODAY())<=7,"DUE — EARNINGS WINDOW",IF(I7<>"",IF(ABS(I7)>=0.2,"DUE — PRICE MOVE ±20%",IF(K7="Y","DUE — INSIDER ACTIVITY",IF(I7<>"",IF(ABS(I7)>=0.15,"WATCH — PRICE MOVE ±15%",IF(M7="Y","WATCH — ANALYST SHIFT","Monitor Only")),IF(M7="Y","WATCH — ANALYST SHIFT","Monitor Only")))),IF(K7="Y","DUE — INSIDER ACTIVITY",IF(I7<>"",IF(ABS(I7)>=0.15,"WATCH — PRICE MOVE ±15%",IF(M7="Y","WATCH — ANALYST SHIFT","Monitor Only")),IF(M7="Y","WATCH — ANALYST SHIFT","Monitor Only"))))),IF(I7<>"",IF(ABS(I7)>=0.2,"DUE — PRICE MOVE ±20%",IF(K7="Y","DUE — INSIDER ACTIVITY",IF(I7<>"",IF(ABS(I7)>=0.15,"WATCH — PRICE MOVE ±15%",IF(M7="Y","WATCH — ANALYST SHIFT","Monitor Only")),IF(M7="Y","WATCH — ANALYST SHIFT","Monitor Only")))),IF(K7="Y","DUE — INSIDER ACTIVITY",IF(I7<>"",IF(ABS(I7)>=0.15,"WATCH — PRICE MOVE ±15%",IF(M7="Y","WATCH — ANALYST SHIFT","Monitor Only")),IF(M7="Y","WATCH — ANALYST SHIFT","Monitor Only"))))))) -> DUE — INSIDER ACTIVITY
A8: MU | B8: Owned | C8: 46240 | D8: 71.8 | E8: 3.64 | F8: BUY | G8: 893.19 | H8: {=IFERROR(INDEX(_xlfn.stockhistory(A8,TODAY()-5,TODAY(),0,0,1),ROWS(_xlfn.stockhistory(A8,TODAY()-5,TODAY(),0,0,1)),1),"")} | I8: =IF(OR(G8="",H8=""),"",H8/G8-1) | J8: 46295 | K8: Y | L8: 2026-08-25: MEHROTRA SANJAY (President and CEO) sold $138,116, 0% of holding (+26 more in last 30d) | M8: N | O8: =IF(C8="","",TODAY()-C8) -> 55 | P8: =IF(A8="","",IF(O8>180,"DUE — STALE (>180 days)",IF(J8<>"",IF(ABS(J8-TODAY())<=7,"DUE — EARNINGS WINDOW",IF(I8<>"",IF(ABS(I8)>=0.2,"DUE — PRICE MOVE ±20%",IF(K8="Y","DUE — INSIDER ACTIVITY",IF(I8<>"",IF(ABS(I8)>=0.15,"WATCH — PRICE MOVE ±15%",IF(M8="Y","WATCH — ANALYST SHIFT","Monitor Only")),IF(M8="Y","WATCH — ANALYST SHIFT","Monitor Only")))),IF(K8="Y","DUE — INSIDER ACTIVITY",IF(I8<>"",IF(ABS(I8)>=0.15,"WATCH — PRICE MOVE ±15%",IF(M8="Y","WATCH — ANALYST SHIFT","Monitor Only")),IF(M8="Y","WATCH — ANALYST SHIFT","Monitor Only"))))),IF(I8<>"",IF(ABS(I8)>=0.2,"DUE — PRICE MOVE ±20%",IF(K8="Y","DUE — INSIDER ACTIVITY",IF(I8<>"",IF(ABS(I8)>=0.15,"WATCH — PRICE MOVE ±15%",IF(M8="Y","WATCH — ANALYST SHIFT","Monitor Only")),IF(M8="Y","WATCH — ANALYST SHIFT","Monitor Only")))),IF(K8="Y","DUE — INSIDER ACTIVITY",IF(I8<>"",IF(ABS(I8)>=0.15,"WATCH — PRICE MOVE ±15%",IF(M8="Y","WATCH — ANALYST SHIFT","Monitor Only")),IF(M8="Y","WATCH — ANALYST SHIFT","Monitor Only"))))))) -> DUE — EARNINGS WINDOW
A9: NVDA | B9: Owned | C9: 46240 | D9: 93.2 | E9: 4.57 | F9: STRONG BUY | G9: 211.87 | H9: {=IFERROR(INDEX(_xlfn.stockhistory(A9,TODAY()-5,TODAY(),0,0,1),ROWS(_xlfn.stockhistory(A9,TODAY()-5,TODAY(),0,0,1)),1),"")} | I9: =IF(OR(G9="",H9=""),"",H9/G9-1) | J9: 46343 | K9: Y | L9: 2026-09-02: STEVENS MARK A (Director) sold $98,470,906, 9% of holding (+9 more in last 30d) | M9: N | O9: =IF(C9="","",TODAY()-C9) -> 55 | P9: =IF(A9="","",IF(O9>180,"DUE — STALE (>180 days)",IF(J9<>"",IF(ABS(J9-TODAY())<=7,"DUE — EARNINGS WINDOW",IF(I9<>"",IF(ABS(I9)>=0.2,"DUE — PRICE MOVE ±20%",IF(K9="Y","DUE — INSIDER ACTIVITY",IF(I9<>"",IF(ABS(I9)>=0.15,"WATCH — PRICE MOVE ±15%",IF(M9="Y","WATCH — ANALYST SHIFT","Monitor Only")),IF(M9="Y","WATCH — ANALYST SHIFT","Monitor Only")))),IF(K9="Y","DUE — INSIDER ACTIVITY",IF(I9<>"",IF(ABS(I9)>=0.15,"WATCH — PRICE MOVE ±15%",IF(M9="Y","WATCH — ANALYST SHIFT","Monitor Only")),IF(M9="Y","WATCH — ANALYST SHIFT","Monitor Only"))))),IF(I9<>"",IF(ABS(I9)>=0.2,"DUE — PRICE MOVE ±20%",IF(K9="Y","DUE — INSIDER ACTIVITY",IF(I9<>"",IF(ABS(I9)>=0.15,"WATCH — PRICE MOVE ±15%",IF(M9="Y","WATCH — ANALYST SHIFT","Monitor Only")),IF(M9="Y","WATCH — ANALYST SHIFT","Monitor Only")))),IF(K9="Y","DUE — INSIDER ACTIVITY",IF(I9<>"",IF(ABS(I9)>=0.15,"WATCH — PRICE MOVE ±15%",IF(M9="Y","WATCH — ANALYST SHIFT","Monitor Only")),IF(M9="Y","WATCH — ANALYST SHIFT","Monitor Only"))))))) -> DUE — INSIDER ACTIVITY
A10: PLTR | B10: Owned | C10: 46240 | D10: 75.2 | E10: 4 | F10: BUY | G10: 162.66 | H10: {=IFERROR(INDEX(_xlfn.stockhistory(A10,TODAY()-5,TODAY(),0,0,1),ROWS(_xlfn.stockhistory(A10,TODAY()-5,TODAY(),0,0,1)),1),"")} | I10: =IF(OR(G10="",H10=""),"",H10/G10-1) | J10: 46328 | K10: Y | L10: 2026-09-03: Stat Lauren Elaina Friedman (Director) sold $244,915, 2% of holding (+20 more in last 30d) | M10: N | O10: =IF(C10="","",TODAY()-C10) -> 55 | P10: =IF(A10="","",IF(O10>180,"DUE — STALE (>180 days)",IF(J10<>"",IF(ABS(J10-TODAY())<=7,"DUE — EARNINGS WINDOW",IF(I10<>"",IF(ABS(I10)>=0.2,"DUE — PRICE MOVE ±20%",IF(K10="Y","DUE — INSIDER ACTIVITY",IF(I10<>"",IF(ABS(I10)>=0.15,"WATCH — PRICE MOVE ±15%",IF(M10="Y","WATCH — ANALYST SHIFT","Monitor Only")),IF(M10="Y","WATCH — ANALYST SHIFT","Monitor Only")))),IF(K10="Y","DUE — INSIDER ACTIVITY",IF(I10<>"",IF(ABS(I10)>=0.15,"WATCH — PRICE MOVE ±15%",IF(M10="Y","WATCH — ANALYST SHIFT","Monitor Only")),IF(M10="Y","WATCH — ANALYST SHIFT","Monitor Only"))))),IF(I10<>"",IF(ABS(I10)>=0.2,"DUE — PRICE MOVE ±20%",IF(K10="Y","DUE — INSIDER ACTIVITY",IF(I10<>"",IF(ABS(I10)>=0.15,"WATCH — PRICE MOVE ±15%",IF(M10="Y","WATCH — ANALYST SHIFT","Monitor Only")),IF(M10="Y","WATCH — ANALYST SHIFT","Monitor Only")))),IF(K10="Y","DUE — INSIDER ACTIVITY",IF(I10<>"",IF(ABS(I10)>=0.15,"WATCH — PRICE MOVE ±15%",IF(M10="Y","WATCH — ANALYST SHIFT","Monitor Only")),IF(M10="Y","WATCH — ANALYST SHIFT","Monitor Only"))))))) -> DUE — INSIDER ACTIVITY
A11: TSM | B11: Owned | C11: 46240 | D11: 81 | E11: 4 | F11: STRONG BUY | G11: 414 | H11: {=IFERROR(INDEX(_xlfn.stockhistory(A11,TODAY()-5,TODAY(),0,0,1),ROWS(_xlfn.stockhistory(A11,TODAY()-5,TODAY(),0,0,1)),1),"")} | I11: =IF(OR(G11="",H11=""),"",H11/G11-1) | J11: 46310 | K11: Y | L11: 2026-09-04: Fang Shu-Hua (SVP and GC) bought $77,090, 16% of holding (+11 more in last 30d) | M11: N | O11: =IF(C11="","",TODAY()-C11) -> 55 | P11: =IF(A11="","",IF(O11>180,"DUE — STALE (>180 days)",IF(J11<>"",IF(ABS(J11-TODAY())<=7,"DUE — EARNINGS WINDOW",IF(I11<>"",IF(ABS(I11)>=0.2,"DUE — PRICE MOVE ±20%",IF(K11="Y","DUE — INSIDER ACTIVITY",IF(I11<>"",IF(ABS(I11)>=0.15,"WATCH — PRICE MOVE ±15%",IF(M11="Y","WATCH — ANALYST SHIFT","Monitor Only")),IF(M11="Y","WATCH — ANALYST SHIFT","Monitor Only")))),IF(K11="Y","DUE — INSIDER ACTIVITY",IF(I11<>"",IF(ABS(I11)>=0.15,"WATCH — PRICE MOVE ±15%",IF(M11="Y","WATCH — ANALYST SHIFT","Monitor Only")),IF(M11="Y","WATCH — ANALYST SHIFT","Monitor Only"))))),IF(I11<>"",IF(ABS(I11)>=0.2,"DUE — PRICE MOVE ±20%",IF(K11="Y","DUE — INSIDER ACTIVITY",IF(I11<>"",IF(ABS(I11)>=0.15,"WATCH — PRICE MOVE ±15%",IF(M11="Y","WATCH — ANALYST SHIFT","Monitor Only")),IF(M11="Y","WATCH — ANALYST SHIFT","Monitor Only")))),IF(K11="Y","DUE — INSIDER ACTIVITY",IF(I11<>"",IF(ABS(I11)>=0.15,"WATCH — PRICE MOVE ±15%",IF(M11="Y","WATCH — ANALYST SHIFT","Monitor Only")),IF(M11="Y","WATCH — ANALYST SHIFT","Monitor Only"))))))) -> DUE — INSIDER ACTIVITY
A12: VRT | B12: Owned | C12: 46240 | D12: 82.8 | E12: 4.36 | F12: STRONG BUY | G12: 277.94 | H12: {=IFERROR(INDEX(_xlfn.stockhistory(A12,TODAY()-5,TODAY(),0,0,1),ROWS(_xlfn.stockhistory(A12,TODAY()-5,TODAY(),0,0,1)),1),"")} | I12: =IF(OR(G12="",H12=""),"",H12/G12-1) | J12: 46316 | K12: Y | L12: 2026-09-02: MONSER EDWARD L (Director) sold $219,497, 3% of holding (+7 more in last 30d) | M12: N | O12: =IF(C12="","",TODAY()-C12) -> 55 | P12: =IF(A12="","",IF(O12>180,"DUE — STALE (>180 days)",IF(J12<>"",IF(ABS(J12-TODAY())<=7,"DUE — EARNINGS WINDOW",IF(I12<>"",IF(ABS(I12)>=0.2,"DUE — PRICE MOVE ±20%",IF(K12="Y","DUE — INSIDER ACTIVITY",IF(I12<>"",IF(ABS(I12)>=0.15,"WATCH — PRICE MOVE ±15%",IF(M12="Y","WATCH — ANALYST SHIFT","Monitor Only")),IF(M12="Y","WATCH — ANALYST SHIFT","Monitor Only")))),IF(K12="Y","DUE — INSIDER ACTIVITY",IF(I12<>"",IF(ABS(I12)>=0.15,"WATCH — PRICE MOVE ±15%",IF(M12="Y","WATCH — ANALYST SHIFT","Monitor Only")),IF(M12="Y","WATCH — ANALYST SHIFT","Monitor Only"))))),IF(I12<>"",IF(ABS(I12)>=0.2,"DUE — PRICE MOVE ±20%",IF(K12="Y","DUE — INSIDER ACTIVITY",IF(I12<>"",IF(ABS(I12)>=0.15,"WATCH — PRICE MOVE ±15%",IF(M12="Y","WATCH — ANALYST SHIFT","Monitor Only")),IF(M12="Y","WATCH — ANALYST SHIFT","Monitor Only")))),IF(K12="Y","DUE — INSIDER ACTIVITY",IF(I12<>"",IF(ABS(I12)>=0.15,"WATCH — PRICE MOVE ±15%",IF(M12="Y","WATCH — ANALYST SHIFT","Monitor Only")),IF(M12="Y","WATCH — ANALYST SHIFT","Monitor Only"))))))) -> DUE — INSIDER ACTIVITY
A13: AVGO | B13: Owned | C13: 46240 | D13: 80.8 | E13: 4.07 | F13: STRONG BUY | G13: 418.16 | H13: {=IFERROR(INDEX(_xlfn.stockhistory(A13,TODAY()-5,TODAY(),0,0,1),ROWS(_xlfn.stockhistory(A13,TODAY()-5,TODAY(),0,0,1)),1),"")} | I13: =IF(OR(G13="",H13=""),"",H13/G13-1) | J13: 46267 | K13: N | M13: N | O13: =IF(C13="","",TODAY()-C13) -> 55 | P13: =IF(A13="","",IF(O13>180,"DUE — STALE (>180 days)",IF(J13<>"",IF(ABS(J13-TODAY())<=7,"DUE — EARNINGS WINDOW",IF(I13<>"",IF(ABS(I13)>=0.2,"DUE — PRICE MOVE ±20%",IF(K13="Y","DUE — INSIDER ACTIVITY",IF(I13<>"",IF(ABS(I13)>=0.15,"WATCH — PRICE MOVE ±15%",IF(M13="Y","WATCH — ANALYST SHIFT","Monitor Only")),IF(M13="Y","WATCH — ANALYST SHIFT","Monitor Only")))),IF(K13="Y","DUE — INSIDER ACTIVITY",IF(I13<>"",IF(ABS(I13)>=0.15,"WATCH — PRICE MOVE ±15%",IF(M13="Y","WATCH — ANALYST SHIFT","Monitor Only")),IF(M13="Y","WATCH — ANALYST SHIFT","Monitor Only"))))),IF(I13<>"",IF(ABS(I13)>=0.2,"DUE — PRICE MOVE ±20%",IF(K13="Y","DUE — INSIDER ACTIVITY",IF(I13<>"",IF(ABS(I13)>=0.15,"WATCH — PRICE MOVE ±15%",IF(M13="Y","WATCH — ANALYST SHIFT","Monitor Only")),IF(M13="Y","WATCH — ANALYST SHIFT","Monitor Only")))),IF(K13="Y","DUE — INSIDER ACTIVITY",IF(I13<>"",IF(ABS(I13)>=0.15,"WATCH — PRICE MOVE ±15%",IF(M13="Y","WATCH — ANALYST SHIFT","Monitor Only")),IF(M13="Y","WATCH — ANALYST SHIFT","Monitor Only"))))))) -> Monitor Only
A14: PLD | B14: Owned | C14: 46240 | D14: 82 | E14: 4.36 | F14: STRONG BUY | G14: 139.06 | H14: {=IFERROR(INDEX(_xlfn.stockhistory(A14,TODAY()-5,TODAY(),0,0,1),ROWS(_xlfn.stockhistory(A14,TODAY()-5,TODAY(),0,0,1)),1),"")} | I14: =IF(OR(G14="",H14=""),"",H14/G14-1) | J14: 46310 | K14: N | M14: N | O14: =IF(C14="","",TODAY()-C14) -> 55 | P14: =IF(A14="","",IF(O14>180,"DUE — STALE (>180 days)",IF(J14<>"",IF(ABS(J14-TODAY())<=7,"DUE — EARNINGS WINDOW",IF(I14<>"",IF(ABS(I14)>=0.2,"DUE — PRICE MOVE ±20%",IF(K14="Y","DUE — INSIDER ACTIVITY",IF(I14<>"",IF(ABS(I14)>=0.15,"WATCH — PRICE MOVE ±15%",IF(M14="Y","WATCH — ANALYST SHIFT","Monitor Only")),IF(M14="Y","WATCH — ANALYST SHIFT","Monitor Only")))),IF(K14="Y","DUE — INSIDER ACTIVITY",IF(I14<>"",IF(ABS(I14)>=0.15,"WATCH — PRICE MOVE ±15%",IF(M14="Y","WATCH — ANALYST SHIFT","Monitor Only")),IF(M14="Y","WATCH — ANALYST SHIFT","Monitor Only"))))),IF(I14<>"",IF(ABS(I14)>=0.2,"DUE — PRICE MOVE ±20%",IF(K14="Y","DUE — INSIDER ACTIVITY",IF(I14<>"",IF(ABS(I14)>=0.15,"WATCH — PRICE MOVE ±15%",IF(M14="Y","WATCH — ANALYST SHIFT","Monitor Only")),IF(M14="Y","WATCH — ANALYST SHIFT","Monitor Only")))),IF(K14="Y","DUE — INSIDER ACTIVITY",IF(I14<>"",IF(ABS(I14)>=0.15,"WATCH — PRICE MOVE ±15%",IF(M14="Y","WATCH — ANALYST SHIFT","Monitor Only")),IF(M14="Y","WATCH — ANALYST SHIFT","Monitor Only"))))))) -> Monitor Only
A15: VRTX | B15: Owned | C15: 46241 | D15: 75.6 | E15: 3.79 | F15: BUY | G15: 478.7 | H15: {=IFERROR(INDEX(_xlfn.stockhistory(A15,TODAY()-5,TODAY(),0,0,1),ROWS(_xlfn.stockhistory(A15,TODAY()-5,TODAY(),0,0,1)),1),"")} | I15: =IF(OR(G15="",H15=""),"",H15/G15-1) | J15: 46328 | K15: N | M15: N | O15: =IF(C15="","",TODAY()-C15) -> 54 | P15: =IF(A15="","",IF(O15>180,"DUE — STALE (>180 days)",IF(J15<>"",IF(ABS(J15-TODAY())<=7,"DUE — EARNINGS WINDOW",IF(I15<>"",IF(ABS(I15)>=0.2,"DUE — PRICE MOVE ±20%",IF(K15="Y","DUE — INSIDER ACTIVITY",IF(I15<>"",IF(ABS(I15)>=0.15,"WATCH — PRICE MOVE ±15%",IF(M15="Y","WATCH — ANALYST SHIFT","Monitor Only")),IF(M15="Y","WATCH — ANALYST SHIFT","Monitor Only")))),IF(K15="Y","DUE — INSIDER ACTIVITY",IF(I15<>"",IF(ABS(I15)>=0.15,"WATCH — PRICE MOVE ±15%",IF(M15="Y","WATCH — ANALYST SHIFT","Monitor Only")),IF(M15="Y","WATCH — ANALYST SHIFT","Monitor Only"))))),IF(I15<>"",IF(ABS(I15)>=0.2,"DUE — PRICE MOVE ±20%",IF(K15="Y","DUE — INSIDER ACTIVITY",IF(I15<>"",IF(ABS(I15)>=0.15,"WATCH — PRICE MOVE ±15%",IF(M15="Y","WATCH — ANALYST SHIFT","Monitor Only")),IF(M15="Y","WATCH — ANALYST SHIFT","Monitor Only")))),IF(K15="Y","DUE — INSIDER ACTIVITY",IF(I15<>"",IF(ABS(I15)>=0.15,"WATCH — PRICE MOVE ±15%",IF(M15="Y","WATCH — ANALYST SHIFT","Monitor Only")),IF(M15="Y","WATCH — ANALYST SHIFT","Monitor Only"))))))) -> Monitor Only | Q15: Re-scored 8/7/26: original Avoid was bad source data, corrected. See Journal.
A16: AAP | B16: Tier-1 Avoid (external) | C16: 46246 | E16: 1.36 | G16: 53.52 | H16: {=IFERROR(INDEX(_xlfn.stockhistory(A16,TODAY()-5,TODAY(),0,0,1),ROWS(_xlfn.stockhistory(A16,TODAY()-5,TODAY(),0,0,1)),1),"")} | I16: =IF(OR(G16="",H16=""),"",H16/G16-1) | J16: 46331 | K16: N | M16: N | O16: =IF(C16="","",TODAY()-C16) -> 49 | P16: =IF(A16="","",IF(O16>180,"DUE — STALE (>180 days)",IF(J16<>"",IF(ABS(J16-TODAY())<=7,"DUE — EARNINGS WINDOW",IF(I16<>"",IF(ABS(I16)>=0.2,"DUE — PRICE MOVE ±20%",IF(K16="Y","DUE — INSIDER ACTIVITY",IF(I16<>"",IF(ABS(I16)>=0.15,"WATCH — PRICE MOVE ±15%",IF(M16="Y","WATCH — ANALYST SHIFT","Monitor Only")),IF(M16="Y","WATCH — ANALYST SHIFT","Monitor Only")))),IF(K16="Y","DUE — INSIDER ACTIVITY",IF(I16<>"",IF(ABS(I16)>=0.15,"WATCH — PRICE MOVE ±15%",IF(M16="Y","WATCH — ANALYST SHIFT","Monitor Only")),IF(M16="Y","WATCH — ANALYST SHIFT","Monitor Only"))))),IF(I16<>"",IF(ABS(I16)>=0.2,"DUE — PRICE MOVE ±20%",IF(K16="Y","DUE — INSIDER ACTIVITY",IF(I16<>"",IF(ABS(I16)>=0.15,"WATCH — PRICE MOVE ±15%",IF(M16="Y","WATCH — ANALYST SHIFT","Monitor Only")),IF(M16="Y","WATCH — ANALYST SHIFT","Monitor Only")))),IF(K16="Y","DUE — INSIDER ACTIVITY",IF(I16<>"",IF(ABS(I16)>=0.15,"WATCH — PRICE MOVE ±15%",IF(M16="Y","WATCH — ANALYST SHIFT","Monitor Only")),IF(M16="Y","WATCH — ANALYST SHIFT","Monitor Only"))))))) -> Monitor Only
A17: BABA | B17: Tier-1 Avoid (external) | C17: 46246 | E17: 2.79 | G17: 125.22 | H17: {=IFERROR(INDEX(_xlfn.stockhistory(A17,TODAY()-5,TODAY(),0,0,1),ROWS(_xlfn.stockhistory(A17,TODAY()-5,TODAY(),0,0,1)),1),"")} | I17: =IF(OR(G17="",H17=""),"",H17/G17-1) | J17: 46350 | K17: Y | L17: 2026-08-25: Tsai Joseph C (Other) bought $10,418,400, 1% of holding (+2 more in last 30d) | M17: N | O17: =IF(C17="","",TODAY()-C17) -> 49 | P17: =IF(A17="","",IF(O17>180,"DUE — STALE (>180 days)",IF(J17<>"",IF(ABS(J17-TODAY())<=7,"DUE — EARNINGS WINDOW",IF(I17<>"",IF(ABS(I17)>=0.2,"DUE — PRICE MOVE ±20%",IF(K17="Y","DUE — INSIDER ACTIVITY",IF(I17<>"",IF(ABS(I17)>=0.15,"WATCH — PRICE MOVE ±15%",IF(M17="Y","WATCH — ANALYST SHIFT","Monitor Only")),IF(M17="Y","WATCH — ANALYST SHIFT","Monitor Only")))),IF(K17="Y","DUE — INSIDER ACTIVITY",IF(I17<>"",IF(ABS(I17)>=0.15,"WATCH — PRICE MOVE ±15%",IF(M17="Y","WATCH — ANALYST SHIFT","Monitor Only")),IF(M17="Y","WATCH — ANALYST SHIFT","Monitor Only"))))),IF(I17<>"",IF(ABS(I17)>=0.2,"DUE — PRICE MOVE ±20%",IF(K17="Y","DUE — INSIDER ACTIVITY",IF(I17<>"",IF(ABS(I17)>=0.15,"WATCH — PRICE MOVE ±15%",IF(M17="Y","WATCH — ANALYST SHIFT","Monitor Only")),IF(M17="Y","WATCH — ANALYST SHIFT","Monitor Only")))),IF(K17="Y","DUE — INSIDER ACTIVITY",IF(I17<>"",IF(ABS(I17)>=0.15,"WATCH — PRICE MOVE ±15%",IF(M17="Y","WATCH — ANALYST SHIFT","Monitor Only")),IF(M17="Y","WATCH — ANALYST SHIFT","Monitor Only"))))))) -> DUE — INSIDER ACTIVITY
A18: CE | B18: Tier-1 Avoid (external) | C18: 46245 | E18: 1.79 | G18: 44.84 | H18: {=IFERROR(INDEX(_xlfn.stockhistory(A18,TODAY()-5,TODAY(),0,0,1),ROWS(_xlfn.stockhistory(A18,TODAY()-5,TODAY(),0,0,1)),1),"")} | I18: =IF(OR(G18="",H18=""),"",H18/G18-1) | J18: 46331 | K18: N | M18: N | O18: =IF(C18="","",TODAY()-C18) -> 50 | P18: =IF(A18="","",IF(O18>180,"DUE — STALE (>180 days)",IF(J18<>"",IF(ABS(J18-TODAY())<=7,"DUE — EARNINGS WINDOW",IF(I18<>"",IF(ABS(I18)>=0.2,"DUE — PRICE MOVE ±20%",IF(K18="Y","DUE — INSIDER ACTIVITY",IF(I18<>"",IF(ABS(I18)>=0.15,"WATCH — PRICE MOVE ±15%",IF(M18="Y","WATCH — ANALYST SHIFT","Monitor Only")),IF(M18="Y","WATCH — ANALYST SHIFT","Monitor Only")))),IF(K18="Y","DUE — INSIDER ACTIVITY",IF(I18<>"",IF(ABS(I18)>=0.15,"WATCH — PRICE MOVE ±15%",IF(M18="Y","WATCH — ANALYST SHIFT","Monitor Only")),IF(M18="Y","WATCH — ANALYST SHIFT","Monitor Only"))))),IF(I18<>"",IF(ABS(I18)>=0.2,"DUE — PRICE MOVE ±20%",IF(K18="Y","DUE — INSIDER ACTIVITY",IF(I18<>"",IF(ABS(I18)>=0.15,"WATCH — PRICE MOVE ±15%",IF(M18="Y","WATCH — ANALYST SHIFT","Monitor Only")),IF(M18="Y","WATCH — ANALYST SHIFT","Monitor Only")))),IF(K18="Y","DUE — INSIDER ACTIVITY",IF(I18<>"",IF(ABS(I18)>=0.15,"WATCH — PRICE MOVE ±15%",IF(M18="Y","WATCH — ANALYST SHIFT","Monitor Only")),IF(M18="Y","WATCH — ANALYST SHIFT","Monitor Only"))))))) -> Monitor Only
A19: CLF | B19: Tier-1 Avoid (external) | C19: 46245 | E19: 1.86 | G19: 12.41 | H19: {=IFERROR(INDEX(_xlfn.stockhistory(A19,TODAY()-5,TODAY(),0,0,1),ROWS(_xlfn.stockhistory(A19,TODAY()-5,TODAY(),0,0,1)),1),"")} | I19: =IF(OR(G19="",H19=""),"",H19/G19-1) | J19: 46314 | K19: N | M19: N | O19: =IF(C19="","",TODAY()-C19) -> 50 | P19: =IF(A19="","",IF(O19>180,"DUE — STALE (>180 days)",IF(J19<>"",IF(ABS(J19-TODAY())<=7,"DUE — EARNINGS WINDOW",IF(I19<>"",IF(ABS(I19)>=0.2,"DUE — PRICE MOVE ±20%",IF(K19="Y","DUE — INSIDER ACTIVITY",IF(I19<>"",IF(ABS(I19)>=0.15,"WATCH — PRICE MOVE ±15%",IF(M19="Y","WATCH — ANALYST SHIFT","Monitor Only")),IF(M19="Y","WATCH — ANALYST SHIFT","Monitor Only")))),IF(K19="Y","DUE — INSIDER ACTIVITY",IF(I19<>"",IF(ABS(I19)>=0.15,"WATCH — PRICE MOVE ±15%",IF(M19="Y","WATCH — ANALYST SHIFT","Monitor Only")),IF(M19="Y","WATCH — ANALYST SHIFT","Monitor Only"))))),IF(I19<>"",IF(ABS(I19)>=0.2,"DUE — PRICE MOVE ±20%",IF(K19="Y","DUE — INSIDER ACTIVITY",IF(I19<>"",IF(ABS(I19)>=0.15,"WATCH — PRICE MOVE ±15%",IF(M19="Y","WATCH — ANALYST SHIFT","Monitor Only")),IF(M19="Y","WATCH — ANALYST SHIFT","Monitor Only")))),IF(K19="Y","DUE — INSIDER ACTIVITY",IF(I19<>"",IF(ABS(I19)>=0.15,"WATCH — PRICE MOVE ±15%",IF(M19="Y","WATCH — ANALYST SHIFT","Monitor Only")),IF(M19="Y","WATCH — ANALYST SHIFT","Monitor Only"))))))) -> Monitor Only
A20: CMG | B20: Watch List | C20: 46245 | E20: 3.71 | G20: 32 | H20: {=IFERROR(INDEX(_xlfn.stockhistory(A20,TODAY()-5,TODAY(),0,0,1),ROWS(_xlfn.stockhistory(A20,TODAY()-5,TODAY(),0,0,1)),1),"")} | I20: =IF(OR(G20="",H20=""),"",H20/G20-1) | J20: 46330 | K20: N | M20: N | O20: =IF(C20="","",TODAY()-C20) -> 50 | P20: =IF(A20="","",IF(O20>180,"DUE — STALE (>180 days)",IF(J20<>"",IF(ABS(J20-TODAY())<=7,"DUE — EARNINGS WINDOW",IF(I20<>"",IF(ABS(I20)>=0.2,"DUE — PRICE MOVE ±20%",IF(K20="Y","DUE — INSIDER ACTIVITY",IF(I20<>"",IF(ABS(I20)>=0.15,"WATCH — PRICE MOVE ±15%",IF(M20="Y","WATCH — ANALYST SHIFT","Monitor Only")),IF(M20="Y","WATCH — ANALYST SHIFT","Monitor Only")))),IF(K20="Y","DUE — INSIDER ACTIVITY",IF(I20<>"",IF(ABS(I20)>=0.15,"WATCH — PRICE MOVE ±15%",IF(M20="Y","WATCH — ANALYST SHIFT","Monitor Only")),IF(M20="Y","WATCH — ANALYST SHIFT","Monitor Only"))))),IF(I20<>"",IF(ABS(I20)>=0.2,"DUE — PRICE MOVE ±20%",IF(K20="Y","DUE — INSIDER ACTIVITY",IF(I20<>"",IF(ABS(I20)>=0.15,"WATCH — PRICE MOVE ±15%",IF(M20="Y","WATCH — ANALYST SHIFT","Monitor Only")),IF(M20="Y","WATCH — ANALYST SHIFT","Monitor Only")))),IF(K20="Y","DUE — INSIDER ACTIVITY",IF(I20<>"",IF(ABS(I20)>=0.15,"WATCH — PRICE MOVE ±15%",IF(M20="Y","WATCH — ANALYST SHIFT","Monitor Only")),IF(M20="Y","WATCH — ANALYST SHIFT","Monitor Only"))))))) -> Monitor Only
A21: COST | B21: Watch List | C21: 46245 | D21: 77.4 | E21: 4.14 | F21: BUY | G21: 944.32 | H21: {=IFERROR(INDEX(_xlfn.stockhistory(A21,TODAY()-5,TODAY(),0,0,1),ROWS(_xlfn.stockhistory(A21,TODAY()-5,TODAY(),0,0,1)),1),"")} | I21: =IF(OR(G21="",H21=""),"",H21/G21-1) | J21: 46289 | K21: N | M21: N | O21: =IF(C21="","",TODAY()-C21) -> 50 | P21: =IF(A21="","",IF(O21>180,"DUE — STALE (>180 days)",IF(J21<>"",IF(ABS(J21-TODAY())<=7,"DUE — EARNINGS WINDOW",IF(I21<>"",IF(ABS(I21)>=0.2,"DUE — PRICE MOVE ±20%",IF(K21="Y","DUE — INSIDER ACTIVITY",IF(I21<>"",IF(ABS(I21)>=0.15,"WATCH — PRICE MOVE ±15%",IF(M21="Y","WATCH — ANALYST SHIFT","Monitor Only")),IF(M21="Y","WATCH — ANALYST SHIFT","Monitor Only")))),IF(K21="Y","DUE — INSIDER ACTIVITY",IF(I21<>"",IF(ABS(I21)>=0.15,"WATCH — PRICE MOVE ±15%",IF(M21="Y","WATCH — ANALYST SHIFT","Monitor Only")),IF(M21="Y","WATCH — ANALYST SHIFT","Monitor Only"))))),IF(I21<>"",IF(ABS(I21)>=0.2,"DUE — PRICE MOVE ±20%",IF(K21="Y","DUE — INSIDER ACTIVITY",IF(I21<>"",IF(ABS(I21)>=0.15,"WATCH — PRICE MOVE ±15%",IF(M21="Y","WATCH — ANALYST SHIFT","Monitor Only")),IF(M21="Y","WATCH — ANALYST SHIFT","Monitor Only")))),IF(K21="Y","DUE — INSIDER ACTIVITY",IF(I21<>"",IF(ABS(I21)>=0.15,"WATCH — PRICE MOVE ±15%",IF(M21="Y","WATCH — ANALYST SHIFT","Monitor Only")),IF(M21="Y","WATCH — ANALYST SHIFT","Monitor Only"))))))) -> DUE — EARNINGS WINDOW
A22: CRK | B22: Tier-1 Avoid (external) | C22: 46245 | E22: 1.21 | G22: 14.39 | H22: {=IFERROR(INDEX(_xlfn.stockhistory(A22,TODAY()-5,TODAY(),0,0,1),ROWS(_xlfn.stockhistory(A22,TODAY()-5,TODAY(),0,0,1)),1),"")} | I22: =IF(OR(G22="",H22=""),"",H22/G22-1) | J22: 46328 | K22: N | M22: N | O22: =IF(C22="","",TODAY()-C22) -> 50 | P22: =IF(A22="","",IF(O22>180,"DUE — STALE (>180 days)",IF(J22<>"",IF(ABS(J22-TODAY())<=7,"DUE — EARNINGS WINDOW",IF(I22<>"",IF(ABS(I22)>=0.2,"DUE — PRICE MOVE ±20%",IF(K22="Y","DUE — INSIDER ACTIVITY",IF(I22<>"",IF(ABS(I22)>=0.15,"WATCH — PRICE MOVE ±15%",IF(M22="Y","WATCH — ANALYST SHIFT","Monitor Only")),IF(M22="Y","WATCH — ANALYST SHIFT","Monitor Only")))),IF(K22="Y","DUE — INSIDER ACTIVITY",IF(I22<>"",IF(ABS(I22)>=0.15,"WATCH — PRICE MOVE ±15%",IF(M22="Y","WATCH — ANALYST SHIFT","Monitor Only")),IF(M22="Y","WATCH — ANALYST SHIFT","Monitor Only"))))),IF(I22<>"",IF(ABS(I22)>=0.2,"DUE — PRICE MOVE ±20%",IF(K22="Y","DUE — INSIDER ACTIVITY",IF(I22<>"",IF(ABS(I22)>=0.15,"WATCH — PRICE MOVE ±15%",IF(M22="Y","WATCH — ANALYST SHIFT","Monitor Only")),IF(M22="Y","WATCH — ANALYST SHIFT","Monitor Only")))),IF(K22="Y","DUE — INSIDER ACTIVITY",IF(I22<>"",IF(ABS(I22)>=0.15,"WATCH — PRICE MOVE ±15%",IF(M22="Y","WATCH — ANALYST SHIFT","Monitor Only")),IF(M22="Y","WATCH — ANALYST SHIFT","Monitor Only"))))))) -> Monitor Only
A23: DEO | B23: Tier-1 Avoid (external) | C23: 46245 | E23: 2.36 | G23: 94.94 | H23: {=IFERROR(INDEX(_xlfn.stockhistory(A23,TODAY()-5,TODAY(),0,0,1),ROWS(_xlfn.stockhistory(A23,TODAY()-5,TODAY(),0,0,1)),1),"")} | I23: =IF(OR(G23="",H23=""),"",H23/G23-1) | J23: 46240 | K23: N | M23: N | O23: =IF(C23="","",TODAY()-C23) -> 50 | P23: =IF(A23="","",IF(O23>180,"DUE — STALE (>180 days)",IF(J23<>"",IF(ABS(J23-TODAY())<=7,"DUE — EARNINGS WINDOW",IF(I23<>"",IF(ABS(I23)>=0.2,"DUE — PRICE MOVE ±20%",IF(K23="Y","DUE — INSIDER ACTIVITY",IF(I23<>"",IF(ABS(I23)>=0.15,"WATCH — PRICE MOVE ±15%",IF(M23="Y","WATCH — ANALYST SHIFT","Monitor Only")),IF(M23="Y","WATCH — ANALYST SHIFT","Monitor Only")))),IF(K23="Y","DUE — INSIDER ACTIVITY",IF(I23<>"",IF(ABS(I23)>=0.15,"WATCH — PRICE MOVE ±15%",IF(M23="Y","WATCH — ANALYST SHIFT","Monitor Only")),IF(M23="Y","WATCH — ANALYST SHIFT","Monitor Only"))))),IF(I23<>"",IF(ABS(I23)>=0.2,"DUE — PRICE MOVE ±20%",IF(K23="Y","DUE — INSIDER ACTIVITY",IF(I23<>"",IF(ABS(I23)>=0.15,"WATCH — PRICE MOVE ±15%",IF(M23="Y","WATCH — ANALYST SHIFT","Monitor Only")),IF(M23="Y","WATCH — ANALYST SHIFT","Monitor Only")))),IF(K23="Y","DUE — INSIDER ACTIVITY",IF(I23<>"",IF(ABS(I23)>=0.15,"WATCH — PRICE MOVE ±15%",IF(M23="Y","WATCH — ANALYST SHIFT","Monitor Only")),IF(M23="Y","WATCH — ANALYST SHIFT","Monitor Only"))))))) -> Monitor Only
A24: DIS | B24: Tier-1 Avoid (external) | C24: 46258 | E24: 2.93 | G24: 110.61 | H24: {=IFERROR(INDEX(_xlfn.stockhistory(A24,TODAY()-5,TODAY(),0,0,1),ROWS(_xlfn.stockhistory(A24,TODAY()-5,TODAY(),0,0,1)),1),"")} | I24: =IF(OR(G24="",H24=""),"",H24/G24-1) | J24: 46338 | K24: Y | L24: 2026-08-20: Roeder Paul M (Sr EVP and Chief Comm Officer) sold $382,327, 100% of holding (+1 more in last 30d) | M24: N | O24: =IF(C24="","",TODAY()-C24) -> 37 | P24: =IF(A24="","",IF(O24>180,"DUE — STALE (>180 days)",IF(J24<>"",IF(ABS(J24-TODAY())<=7,"DUE — EARNINGS WINDOW",IF(I24<>"",IF(ABS(I24)>=0.2,"DUE — PRICE MOVE ±20%",IF(K24="Y","DUE — INSIDER ACTIVITY",IF(I24<>"",IF(ABS(I24)>=0.15,"WATCH — PRICE MOVE ±15%",IF(M24="Y","WATCH — ANALYST SHIFT","Monitor Only")),IF(M24="Y","WATCH — ANALYST SHIFT","Monitor Only")))),IF(K24="Y","DUE — INSIDER ACTIVITY",IF(I24<>"",IF(ABS(I24)>=0.15,"WATCH — PRICE MOVE ±15%",IF(M24="Y","WATCH — ANALYST SHIFT","Monitor Only")),IF(M24="Y","WATCH — ANALYST SHIFT","Monitor Only"))))),IF(I24<>"",IF(ABS(I24)>=0.2,"DUE — PRICE MOVE ±20%",IF(K24="Y","DUE — INSIDER ACTIVITY",IF(I24<>"",IF(ABS(I24)>=0.15,"WATCH — PRICE MOVE ±15%",IF(M24="Y","WATCH — ANALYST SHIFT","Monitor Only")),IF(M24="Y","WATCH — ANALYST SHIFT","Monitor Only")))),IF(K24="Y","DUE — INSIDER ACTIVITY",IF(I24<>"",IF(ABS(I24)>=0.15,"WATCH — PRICE MOVE ±15%",IF(M24="Y","WATCH — ANALYST SHIFT","Monitor Only")),IF(M24="Y","WATCH — ANALYST SHIFT","Monitor Only"))))))) -> DUE — INSIDER ACTIVITY
A25: DPZ | B25: Watch List | C25: 46245 | E25: 4.86 | G25: 357.34 | H25: {=IFERROR(INDEX(_xlfn.stockhistory(A25,TODAY()-5,TODAY(),0,0,1),ROWS(_xlfn.stockhistory(A25,TODAY()-5,TODAY(),0,0,1)),1),"")} | I25: =IF(OR(G25="",H25=""),"",H25/G25-1) | J25: 46308 | K25: N | M25: N | O25: =IF(C25="","",TODAY()-C25) -> 50 | P25: =IF(A25="","",IF(O25>180,"DUE — STALE (>180 days)",IF(J25<>"",IF(ABS(J25-TODAY())<=7,"DUE — EARNINGS WINDOW",IF(I25<>"",IF(ABS(I25)>=0.2,"DUE — PRICE MOVE ±20%",IF(K25="Y","DUE — INSIDER ACTIVITY",IF(I25<>"",IF(ABS(I25)>=0.15,"WATCH — PRICE MOVE ±15%",IF(M25="Y","WATCH — ANALYST SHIFT","Monitor Only")),IF(M25="Y","WATCH — ANALYST SHIFT","Monitor Only")))),IF(K25="Y","DUE — INSIDER ACTIVITY",IF(I25<>"",IF(ABS(I25)>=0.15,"WATCH — PRICE MOVE ±15%",IF(M25="Y","WATCH — ANALYST SHIFT","Monitor Only")),IF(M25="Y","WATCH — ANALYST SHIFT","Monitor Only"))))),IF(I25<>"",IF(ABS(I25)>=0.2,"DUE — PRICE MOVE ±20%",IF(K25="Y","DUE — INSIDER ACTIVITY",IF(I25<>"",IF(ABS(I25)>=0.15,"WATCH — PRICE MOVE ±15%",IF(M25="Y","WATCH — ANALYST SHIFT","Monitor Only")),IF(M25="Y","WATCH — ANALYST SHIFT","Monitor Only")))),IF(K25="Y","DUE — INSIDER ACTIVITY",IF(I25<>"",IF(ABS(I25)>=0.15,"WATCH — PRICE MOVE ±15%",IF(M25="Y","WATCH — ANALYST SHIFT","Monitor Only")),IF(M25="Y","WATCH — ANALYST SHIFT","Monitor Only"))))))) -> Monitor Only
