Workbook
Name MON_SignalsAsOf: 'Monitor & Recheck Triggers'!$Q$1
Name PT_AsOf: 'Performance Tracking'!$D$63
Name PT_Inception: 'Performance Tracking'!$D$67
Name PT_SPY_0805: 'Performance Tracking'!$D$65
Name PT_SPY_1231: 'Performance Tracking'!$D$66
Name PT_SPY_Now: 'Performance Tracking'!$D$64

Sheet Instructions
A1: THE LANDRY FAMILY EQUITY INVESTMENT OPERATING SYSTEM — STOCK SCORING & PORTFOLIO RISK WORKBOOK
A3: Companion workbook to Landry System v1.03. Aligned to: Version 1.03 (50 Hard Rules, Parts 1–12).
A4: If the Word document's rule numbers ever change in a future revision, check this line and the rule
A5: references throughout this workbook before relying on them.
A7: HOW TO USE THIS WORKBOOK
A8: 1. Market Data tab — enter or refresh price, volume, market cap, P/E, 52-week range, and dividend
A9: yield for each tracked ticker. Blue cells only. See that tab's note on optional live-data refresh.
A10: 2. Scoring tab — during a scoring session, enter each Tier 1/2/3 indicator's score (1–5) and Confidence
A11: tag (H/M/L) per Part 2's rubrics. The Composite Score, decision classification, and hard-rule flags
A12: (Rules 1–4) calculate automatically.
A13: 3. Dashboard tab — read-only summary of every tracked stock, sortable by Composite Score.
A14: 4. Price History / Returns (Calc) / Correlation Matrix tabs — enter weekly closing prices for current
... A61: Scoring tab, Tier 1 FCF indicators -- basis (policy 10/5/26, Open Items #31, Journal row 94): the scores of record are drafted from fiscal-year statements. At each quarterly review, and before acting on any Rule 1 / Rule 3 trip, Watch List or Exit Review deadline or Part 6 sell trigger, run `python -m landry.sec_ttm --holdings` (one name: `python -m landry.sec_ttm TICKER`) to compare every US-filer holding with its latest 10-Q. Re-score on trailing 12-month windows only where a hard-rule outcome or Decision band differs, in either direction; ASML, TSM, REITs and anything the tool lists as BY HAND are checked from the filings. A Part 10 adjustment for a one-time item (an acquisition, say) is Alan's to approve and is recorded in landry_addbacks.json and the score's adaptation field.

Sheet Action Items
A1: ACTION ITEMS — everything requiring your decision, pulled live from every other tab. Everything else in this workbook is reference; this is what to open.
A2: Refresh by opening the workbook (F9 recalculates); all cells below are live formulas, nothing here is typed.
A4: 1. WATCH LIST — Rules 32-36 (see Watch List Tracker tab for detail)
A5: Deadlines passed (sell required within 30 days): | E5: =COUNTIF('Watch List Tracker'!K3:K22,"*SELL WITHIN 30 DAYS*") -> 1
A6: Deadlines approaching (within 14 days): | E6: =COUNTIF('Watch List Tracker'!K3:K22,"DEADLINE APPROACHING") -> 0
A7: Recovered — ready to remove/reclassify: | E7: =COUNTIF('Watch List Tracker'!K3:K22,"*RECOVERED*") -> 0
A9: 2. ACTIVE SELL TRIGGERS — Rules 22-31 (see Holding Monitor tab for detail)
A10: Holdings with action required within 30 days: | E10: =COUNTIF('Holding Monitor'!AB4:AB23,"*ACTION REQUIRED*") -> 0
A11: Holdings under Hold Through (monitor only, no action): | E11: =COUNTIF('Holding Monitor'!AB4:AB23,"*Hold Through*") -> 0
A13: 3. CORRELATION CAP — Rule 38 (see Correlation Matrix tab for detail)
A14: Rule 38 status: | E14: ='Correlation Matrix'!J3 -> REVIEW REQUIRED
A15: Positions exceeding cap: | E15: ='Correlation Matrix'!J2 -> 11
A17: 4. PORTFOLIO DRAWDOWN STATUS — Rule 39 (see Portfolio Drawdown Log tab for detail)
A18: Most recent recorded status: | E18: =IFERROR(INDEX('Portfolio Drawdown Log'!E3:E42,COUNT('Portfolio Drawdown Log'!D3:D42)),"No entries yet") -> Normal
A19: Most recent drawdown %: | E19: =IFERROR(INDEX('Portfolio Drawdown Log'!D3:D42,COUNT('Portfolio Drawdown Log'!D3:D42)),"") -> -0.012866311
A20: Required cash floor at this level: | E20: =IFERROR(INDEX('Portfolio Drawdown Log'!F3:F42,COUNT('Portfolio Drawdown Log'!D3:D42)),"") -> 5-15%
A22: 5. CANDIDATE SCORING FLAGS — Rules 1-4 (see Scoring tab for detail)
A23: Candidates failing the Tier 1 floor, 3.0 (Rule 1): | E23: =COUNTIF(Scoring!AH3:AH60,"FAIL") -> 19
A24: Stocks flagged Avoid by Rule 3 (candidates and holdings): | E24: =COUNTIF(Scoring!AJ3:AJ60,"AVOID") -> 21
A25: Candidates flagged for mandatory Tier 1 review (Rule 2): | E25: =COUNTIF(Scoring!AI3:AI60,"REVIEW") -> 14
A26: Candidates capped at Buy despite Strong Buy score (Rule 4): | E26: =COUNTIF(Scoring!AK3:AK60,"CAP AT BUY") -> 0
A27: 6. ENTRY AUTHORIZATION — Rules 6-14 (see Entry Checklist tab for detail)
A28: Candidates NOT authorized to enter (failing one or more Entry Rules): | E28: =COUNTIF('Entry Checklist'!R3:R47,"NO*") -> 1
A29: Candidates authorized, staged at reduced size (50%, per Rules 9-10): | E29: =COUNTIF('Entry Checklist'!H3:H47,"*50%*") -> 0
A31: 7. PIOTROSKI CROSS-CHECKS -- RETIRED 9/11/26. Tested on an 8-ticker diagnostic batch, dropped as redundant for how this system is actually used (see Journal row 42-43). Historical data left in place at Scoring cols AN-AS as a record of the experiment; no longer live-tallied here.
A32: Candidates flagged LOW CONF on Accruals (CFO does not exceed Net Income): | E32: =COUNTIF(Scoring!AP3:AP60,"LOW CONF") -> 2
A33: Candidates with Debt/FCF trending up year-over-year: | E33: =COUNTIF(Scoring!AS3:AS60,"Increased") -> 5

Sheet Current Positions
A1: Combined current positions, both accounts, as of the 9/30/2026 statements (GE/NFLX bought 9/30, settled 10/1; prices refresh in Excel) -- JT ULTRA (Fidelity); Self-Directed, Chase — cash sweep custodied at Schwab, swept to VMFXX for yield. Source: uploaded brokerage exports + confirmed trade executions, aggregated by ticker. Update this tab at each quarterly/annual review; use it with Part 5 sizing modifiers and the Holding Monitor tab to prescribe classifications and follow-up actions. | O1: TAX-LOSS CARRYFORWARD (update annually)
A2: Account | B2: Ticker | C2: Description | D2: Asset Class | E2: Quantity | F2: Price ($) | G2: Market Value ($) | H2: Cost Basis ($) | I2: Unrealized G/L ($) | J2: Unrealized G/L (%) | K2: % of Acct | L2: % of Comb. Portfolio | M2: Classification / Notes (fill at review) | O2: Short-Term Loss Carryforward:
A3: JT ULTRA (Fidelity) | B3: ADBE | C3: Adobe Inc. | D3: Equity | E3: 65 | F3: =IF(IFERROR(INDEX('Monitor & Recheck Triggers'!$H$3:$H$51,MATCH($B3,'Monitor & Recheck Triggers'!$A$3:$A$51,0)),"")="",237.69,INDEX('Monitor & Recheck Triggers'!$H$3:$H$51,MATCH($B3,'Monitor & Recheck Triggers'!$A$3:$A$51,0))) -> 238.785 | G3: =E3*F3 -> 15521.025 | H3: 19163.84 | I3: =G3-H3 -> -3642.815 | J3: =IF(H3=0,"",G3/H3-1) -> -0.19008795 | K3: =IFERROR(G3/SUM(G3:G23),"") -> 0.037640147 | L3: =IFERROR(G3/(SUM(G3:G23,G27:G46)),"") -> 0.02129231 | M3: BOUGHT +20sh 8/7/26 @ $266.38 -- DCA tranche 1 diversifier add | O3: Long-Term Loss Carryforward:
A4: JT ULTRA (Fidelity) | B4: ANET | C4: Arista Networks | D4: Equity | E4: 70 | F4: =IF(IFERROR(INDEX('Monitor & Recheck Triggers'!$H$3:$H$51,MATCH($B4,'Monitor & Recheck Triggers'!$A$3:$A$51,0)),"")="",207.35,INDEX('Monitor & Recheck Triggers'!$H$3:$H$51,MATCH($B4,'Monitor & Recheck Triggers'!$A$3:$A$51,0))) -> 206.9 | G4: =E4*F4 -> 14483 | H4: 10182.2 | I4: =G4-H4 -> 4300.8 | J4: =IF(H4=0,"",G4/H4-1) -> 0.42238416 | K4: =IFERROR(G4/SUM(G3:G23),"") -> 0.035122826 | L4: =IFERROR(G4/(SUM(G3:G23,G27:G46)),"") -> 0.01986831
A5: JT ULTRA (Fidelity) | B5: ASML | C5: ASML Holding | D5: Equity | E5: 7 | F5: =IF(IFERROR(INDEX('Monitor & Recheck Triggers'!$H$3:$H$51,MATCH($B5,'Monitor & Recheck Triggers'!$A$3:$A$51,0)),"")="",1867.31,INDEX('Monitor & Recheck Triggers'!$H$3:$H$51,MATCH($B5,'Monitor & Recheck Triggers'!$A$3:$A$51,0))) -> 1859.86 | G5: =E5*F5 -> 13019.02 | H5: 9989.88 | I5: =G5-H5 -> 3029.14 | J5: =IF(H5=0,"",G5/H5-1) -> 0.30322086 | K5: =IFERROR(G5/SUM(G3:G23),"") -> 0.031572517 | L5: =IFERROR(G5/(SUM(G3:G23,G27:G46)),"") -> 0.017859968
A6: JT ULTRA (Fidelity) | B6: CRWD | C6: CrowdStrike Holdings | D6: Equity | E6: 40 | F6: =IF(IFERROR(INDEX('Monitor & Recheck Triggers'!$H$3:$H$51,MATCH($B6,'Monitor & Recheck Triggers'!$A$3:$A$51,0)),"")="",270.04,INDEX('Monitor & Recheck Triggers'!$H$3:$H$51,MATCH($B6,'Monitor & Recheck Triggers'!$A$3:$A$51,0))) -> 272.67 | G6: =E6*F6 -> 10906.8 | H6: 4991.35 | I6: =G6-H6 -> 5915.45 | J6: =IF(H6=0,"",G6/H6-1) -> 1.1851403 | K6: =IFERROR(G6/SUM(G3:G23),"") -> 0.026450158 | L6: =IFERROR(G6/(SUM(G3:G23,G27:G46)),"") -> 0.014962348
A7: JT ULTRA (Fidelity) | B7: KLAC | C7: KLA Corporation | D7: Equity | E7: 100 | F7: =IF(IFERROR(INDEX('Monitor & Recheck Triggers'!$H$3:$H$51,MATCH($B7,'Monitor & Recheck Triggers'!$A$3:$A$51,0)),"")="",206.89,INDEX('Monitor & Recheck Triggers'!$H$3:$H$51,MATCH($B7,'Monitor & Recheck Triggers'!$A$3:$A$51,0))) -> 206.85 | G7: =E7*F7 -> 20685 | H7: 15412.54 | I7: =G7-H7 -> 5272.46 | J7: =IF(H7=0,"",G7/H7-1) -> 0.34208897 | K7: =IFERROR(G7/SUM(G3:G23),"") -> 0.05016334 | L7: =IFERROR(G7/(SUM(G3:G23,G27:G46)),"") -> 0.02837644
A8: JT ULTRA (Fidelity) | B8: MU | C8: Micron Technology | D8: Equity | E8: 7 | F8: =IF(IFERROR(INDEX('Monitor & Recheck Triggers'!$H$3:$H$51,MATCH($B8,'Monitor & Recheck Triggers'!$A$3:$A$51,0)),"")="",1074.89,INDEX('Monitor & Recheck Triggers'!$H$3:$H$51,MATCH($B8,'Monitor & Recheck Triggers'!$A$3:$A$51,0))) -> 1063.96 | G8: =E8*F8 -> 7447.72 | H8: 5836.11 | I8: =G8-H8 -> 1611.61 | J8: =IF(H8=0,"",G8/H8-1) -> 0.27614456 | K8: =IFERROR(G8/SUM(G3:G23),"") -> 0.018061518 | L8: =IFERROR(G8/(SUM(G3:G23,G27:G46)),"") -> 0.010217055
A9: JT ULTRA (Fidelity) | B9: NVDA | C9: NVIDIA Corporation | D9: Equity | E9: 155 | F9: =IF(IFERROR(INDEX('Monitor & Recheck Triggers'!$H$3:$H$51,MATCH($B9,'Monitor & Recheck Triggers'!$A$3:$A$51,0)),"")="",233.95,INDEX('Monitor & Recheck Triggers'!$H$3:$H$51,MATCH($B9,'Monitor & Recheck Triggers'!$A$3:$A$51,0))) -> 238.9 | G9: =E9*F9 -> 37029.5 | H9: 26639.79 | I9: =G9-H9 -> 10389.71 | J9: =IF(H9=0,"",G9/H9-1) -> 0.3900072 | K9: =IFERROR(G9/SUM(G3:G23),"") -> 0.089800502 | L9: =IFERROR(G9/(SUM(G3:G23,G27:G46)),"") -> 0.050798424
A10: JT ULTRA (Fidelity) | B10: PLTR | C10: Palantir Technologies | D10: Equity | E10: 70 | F10: =IF(IFERROR(INDEX('Monitor & Recheck Triggers'!$H$3:$H$51,MATCH($B10,'Monitor & Recheck Triggers'!$A$3:$A$51,0)),"")="",188.75,INDEX('Monitor & Recheck Triggers'!$H$3:$H$51,MATCH($B10,'Monitor & Recheck Triggers'!$A$3:$A$51,0))) -> 189.4 | G10: =E10*F10 -> 13258 | H10: 11612.3 | I10: =G10-H10 -> 1645.7 | J10: =IF(H10=0,"",G10/H10-1) -> 0.14172042 | K10: =IFERROR(G10/SUM(G3:G23),"") -> 0.032152069 | L10: =IFERROR(G10/(SUM(G3:G23,G27:G46)),"") -> 0.01818781
A11: JT ULTRA (Fidelity) | B11: TSM | C11: Taiwan Semiconductor | D11: Equity | E11: 25 | F11: =IF(IFERROR(INDEX('Monitor & Recheck Triggers'!$H$3:$H$51,MATCH($B11,'Monitor & Recheck Triggers'!$A$3:$A$51,0)),"")="",472.78,INDEX('Monitor & Recheck Triggers'!$H$3:$H$51,MATCH($B11,'Monitor & Recheck Triggers'!$A$3:$A$51,0))) -> 485.8 | G11: =E11*F11 -> 12145 | H11: 6069.64 | I11: =G11-H11 -> 6075.36 | J11: =IF(H11=0,"",G11/H11-1) -> 1.0009424 | K11: =IFERROR(G11/SUM(G3:G23),"") -> 0.029452925 | L11: =IFERROR(G11/(SUM(G3:G23,G27:G46)),"") -> 0.016660956
A12: JT ULTRA (Fidelity) | B12: VRT | C12: Vertiv Holdings | D12: Equity | E12: 30 | F12: =IF(IFERROR(INDEX('Monitor & Recheck Triggers'!$H$3:$H$51,MATCH($B12,'Monitor & Recheck Triggers'!$A$3:$A$51,0)),"")="",252.18,INDEX('Monitor & Recheck Triggers'!$H$3:$H$51,MATCH($B12,'Monitor & Recheck Triggers'!$A$3:$A$51,0))) -> 253.62 | G12: =E12*F12 -> 7608.6 | H12: 7876.8 | I12: =G12-H12 -> -268.2 | J12: =IF(H12=0,"",G12/H12-1) -> -0.03404936 | K12: =IFERROR(G12/SUM(G3:G23),"") -> 0.01845167 | L12: =IFERROR(G12/(SUM(G3:G23,G27:G46)),"") -> 0.010437756
A13: JT ULTRA (Fidelity) | B13: V | C13: Visa Inc. | D13: Equity | E13: 50 | F13: =IF(IFERROR(INDEX('Monitor & Recheck Triggers'!$H$3:$H$51,MATCH($B13,'Monitor & Recheck Triggers'!$A$3:$A$51,0)),"")="",360.66,INDEX('Monitor & Recheck Triggers'!$H$3:$H$51,MATCH($B13,'Monitor & Recheck Triggers'!$A$3:$A$51,0))) -> 369.71 | G13: =E13*F13 -> 18485.5 | H13: 18448.63 | I13: =G13-H13 -> 36.87 | J13: =IF(H13=0,"",G13/H13-1) -> 0.0019985224 | K13: =IFERROR(G13/SUM(G3:G23),"") -> 0.044829317 | L13: =IFERROR(G13/(SUM(G3:G23,G27:G46)),"") -> 0.025359086 | M13: NEW position 9/8/26 -- DCA-TRANCHE-2, opened per Entry Checklist authorization (Composite 86.4, STRONG BUY). 2 lots: 25sh @ $368.38 + 25sh @ $369.565.
A14: JT ULTRA (Fidelity) | B14: FZDXX | C14: Fidelity Money Market Premium | D14: Cash | E14: 38154.18 | F14: 1 | G14: =E14*F14 -> 38154.18 | H14: 38154.18 | I14: =G14-H14 -> 0 | J14: =IF(H14=0,"",G14/H14-1) -> 0 | K14: =IFERROR(G14/SUM(G3:G23),"") -> 0.092527972 | L14: =IFERROR(G14/(SUM(G3:G23,G27:G46)),"") -> 0.052341301
A15: JT ULTRA (Fidelity) | B15: FZFXX | C15: Fidelity Core Money Market | D15: Cash | E15: 1174.01 | F15: 1 | G15: =E15*F15 -> 1174.01 | H15: 1174.01 | I15: =G15-H15 -> 0 | J15: =IF(H15=0,"",G15/H15-1) -> 0 | K15: =IFERROR(G15/SUM(G3:G23),"") -> 0.0028470999 | L15: =IFERROR(G15/(SUM(G3:G23,G27:G46)),"") -> 0.0016105499
A16: JT ULTRA (Fidelity) | B16: DVY | C16: iShares Select Dividend ETF | D16: Equity | E16: 150 | F16: =IF(IFERROR(INDEX('Monitor & Recheck Triggers'!$H$3:$H$51,MATCH($B16,'Monitor & Recheck Triggers'!$A$3:$A$51,0)),"")="",153.05,INDEX('Monitor & Recheck Triggers'!$H$3:$H$51,MATCH($B16,'Monitor & Recheck Triggers'!$A$3:$A$51,0))) -> 153.05 | G16: =E16*F16 -> 22957.5 | H16: 24518.25 | I16: =G16-H16 -> -1560.75 | J16: =IF(H16=0,"",G16/H16-1) -> -0.063656664 | K16: =IFERROR(G16/SUM(G3:G23),"") -> 0.055674395 | L16: =IFERROR(G16/(SUM(G3:G23,G27:G46)),"") -> 0.031493939 | M16: NEW position since 8/5/26 -- cash/dry powder per Alan 9/7/26, not a scored Landry position.
A17: JT ULTRA (Fidelity) | B17: VFLO | C17: VictoryShares Free Cash Flow ETF | D17: Equity | E17: 451.304 | F17: =IF(IFERROR(INDEX('Monitor & Recheck Triggers'!$H$3:$H$51,MATCH($B17,'Monitor & Recheck Triggers'!$A$3:$A$51,0)),"")="",51.82,INDEX('Monitor & Recheck Triggers'!$H$3:$H$51,MATCH($B17,'Monitor & Recheck Triggers'!$A$3:$A$51,0))) -> 51.82 | G17: =E17*F17 -> 23386.573 | H17: 24999.99 | I17: =G17-H17 -> -1613.4167 | J17: =IF(H17=0,"",G17/H17-1) -> -0.064536695 | K17: =IFERROR(G17/SUM(G3:G23),"") -> 0.056714944 | L17: =IFERROR(G17/(SUM(G3:G23,G27:G46)),"") -> 0.032082558 | M17: NEW to this account since 8/5/26 (already held in Self-Directed) -- cash/dry powder per Alan 9/7/26, not a scored Landry position.
A18: JT ULTRA (Fidelity) | B18: SCHD | C18: Schwab US Dividend Equity ETF | D18: Equity | E18: 700 | F18: =IF(IFERROR(INDEX('Monitor & Recheck Triggers'!$H$3:$H$51,MATCH($B18,'Monitor & Recheck Triggers'!$A$3:$A$51,0)),"")="",32.72,INDEX('Monitor & Recheck Triggers'!$H$3:$H$51,MATCH($B18,'Monitor & Recheck Triggers'!$A$3:$A$51,0))) -> 32.72 | G18: =E18*F18 -> 22904 | H18: 24377.5 | I18: =G18-H18 -> -1473.5 | J18: =IF(H18=0,"",G18/H18-1) -> -0.060445083 | K18: =IFERROR(G18/SUM(G3:G23),"") -> 0.055544652 | L18: =IFERROR(G18/(SUM(G3:G23,G27:G46)),"") -> 0.031420546 | M18: NEW position since 8/5/26 -- cash/dry powder per Alan 9/7/26, not a scored Landry position.
A19: JT ULTRA (Fidelity) | B19: VYM | C19: Vanguard High Dividend Yield ETF | D19: Equity | E19: 150 | F19: =IF(IFERROR(INDEX('Monitor & Recheck Triggers'!$H$3:$H$51,MATCH($B19,'Monitor & Recheck Triggers'!$A$3:$A$51,0)),"")="",156.46,INDEX('Monitor & Recheck Triggers'!$H$3:$H$51,MATCH($B19,'Monitor & Recheck Triggers'!$A$3:$A$51,0))) -> 156.46 | G19: =E19*F19 -> 23469 | H19: 24598.5 | I19: =G19-H19 -> -1129.5 | J19: =IF(H19=0,"",G19/H19-1) -> -0.045917434 | K19: =IFERROR(G19/SUM(G3:G23),"") -> 0.056914838 | L19: =IFERROR(G19/(SUM(G3:G23,G27:G46)),"") -> 0.032195634 | M19: NEW position since 8/5/26 -- cash/dry powder per Alan 9/7/26, not a scored Landry position.
A20: JT ULTRA (Fidelity) | B20: MLPI | C20: NEOS MLP & Energy Income ETF | D20: Equity | E20: 1000 | F20: =IF(IFERROR(INDEX('Monitor & Recheck Triggers'!$H$3:$H$51,MATCH($B20,'Monitor & Recheck Triggers'!$A$3:$A$51,0)),"")="",51.17,INDEX('Monitor & Recheck Triggers'!$H$3:$H$51,MATCH($B20,'Monitor & Recheck Triggers'!$A$3:$A$51,0))) -> 51.17 | G20: =E20*F20 -> 51170 | H20: 53709 | I20: =G20-H20 -> -2539 | J20: =IF(H20=0,"",G20/H20-1) -> -0.047273269 | K20: =IFERROR(G20/SUM(G3:G23),"") -> 0.12409273 | L20: =IFERROR(G20/(SUM(G3:G23,G27:G46)),"") -> 0.07019688 | M20: NEW position since 8/5/26 -- cash/dry powder per Alan 9/7/26, not a scored Landry position.
A21: JT ULTRA (Fidelity) | B21: SPMO | C21: Invesco S&P 500 Momentum ETF | D21: Equity | E21: 100 | F21: =IF(IFERROR(INDEX('Monitor & Recheck Triggers'!$H$3:$H$51,MATCH($B21,'Monitor & Recheck Triggers'!$A$3:$A$51,0)),"")="",153.23,INDEX('Monitor & Recheck Triggers'!$H$3:$H$51,MATCH($B21,'Monitor & Recheck Triggers'!$A$3:$A$51,0))) -> 153.23 | G21: =E21*F21 -> 15323 | H21: 14696.99 | I21: =G21-H21 -> 626.01 | J21: =IF(H21=0,"",G21/H21-1) -> 0.042594436 | K21: =IFERROR(G21/SUM(G3:G23),"") -> 0.037159916 | L21: =IFERROR(G21/(SUM(G3:G23,G27:G46)),"") -> 0.021020652 | M21: NEW to this account since 8/5/26 (already held in Self-Directed) -- cash/dry powder per Alan 9/7/26, not a scored Landry position.
A22: JT ULTRA (Fidelity) | B22: GE | C22: GE Aerospace | D22: Equity | E22: 75 | F22: =IF(IFERROR(INDEX('Monitor & Recheck Triggers'!$H$3:$H$51,MATCH($B22,'Monitor & Recheck Triggers'!$A$3:$A$51,0)),"")="",309.56,INDEX('Monitor & Recheck Triggers'!$H$3:$H$51,MATCH($B22,'Monitor & Recheck Triggers'!$A$3:$A$51,0))) -> 306.34 | G22: =E22*F22 -> 22975.5 | H22: 23603.25 | I22: =G22-H22 -> -627.75 | J22: =IF(H22=0,"",G22/H22-1) -> -0.026595914 | K22: =IFERROR(G22/SUM(G3:G23),"") -> 0.055718047 | L22: =IFERROR(G22/(SUM(G3:G23,G27:G46)),"") -> 0.031518632 | M22: NEW position 9/30/26 -- DCA-CATCHUP-1, opened per Composite 84.2 STRONG BUY (rescored 9/13/26, reconfirmed fresh 9/29/26, zero Tier 1 drift). 75sh @ $314.71.
A23: JT ULTRA (Fidelity) | B23: NFLX | C23: Netflix, Inc. | D23: Equity | E23: 300 | F23: =IF(IFERROR(INDEX('Monitor & Recheck Triggers'!$H$3:$H$51,MATCH($B23,'Monitor & Recheck Triggers'!$A$3:$A$51,0)),"")="",67.06,INDEX('Monitor & Recheck Triggers'!$H$3:$H$51,MATCH($B23,'Monitor & Recheck Triggers'!$A$3:$A$51,0))) -> 67.5 | G23: =E23*F23 -> 20250 | H23: 20938.5 | I23: =G23-H23 -> -688.5 | J23: =IF(H23=0,"",G23/H23-1) -> -0.032882012 | K23: =IFERROR(G23/SUM(G3:G23),"") -> 0.049108418 | L23: =IFERROR(G23/(SUM(G3:G23,G27:G46)),"") -> 0.027779691 | M23: NEW position 9/30/26 -- DCA-CATCHUP-1, opened per Composite 83.8 STRONG BUY (rescored 9/13/26, reconfirmed fresh 9/29/26, zero Tier 1 drift). 300sh @ $69.795.
A24: Positions | B24: =SUBTOTAL(103,B3:B23) -> 21 | C24: JT ULTRA (Fidelity) SUBTOTAL | G24: =SUM(G3:G23) -> 412352.93 | H24: =SUM(H3:H23) -> 386993.25 | I24: =SUM(I3:I23) -> 25359.678 | J24: =CurrentPositionsTable[[#This Row],[Unrealized G/L ($)]]/CurrentPositionsTable[[#This Row],[Cost Basis ($)]] -> 0.065530027 | K24: =SUM(K3:K23) -> 1 | L24: =SUM(L3:L23) -> 0.56568085
I25: Excluding Cash | J25: =I24/(H24-H14-H13) -> 0.076756695
A27: Self-Directed (Chase) | B27: VMFXX | C27: Vanguard Federal Money Market | D27: Cash | E27: 36854.47 | F27: 1 | G27: =E27*F27 -> 36854.47 | H27: 36854.47 | I27: =G27-H27 -> 0 | J27: =IF(H27=0,"",G27/H27-1) -> 0 | K27: =IFERROR(G27/SUM(G27:G46),"") -> 0.1164082 | L27: =IFERROR(G27/(SUM(G3:G23,G27:G46)),"") -> 0.050558311
A28: Self-Directed (Chase) | B28: JEPQ | C28: JPMorgan Nasdaq Equity Premium Income ETF | D28: Alt. Assets | E28: 850.35693 | F28: =IF(IFERROR(INDEX('Monitor & Recheck Triggers'!$H$3:$H$51,MATCH($B28,'Monitor & Recheck Triggers'!$A$3:$A$51,0)),"")="",61.04,INDEX('Monitor & Recheck Triggers'!$H$3:$H$51,MATCH($B28,'Monitor & Recheck Triggers'!$A$3:$A$51,0))) -> 61.04 | G28: =E28*F28 -> 51905.787 | H28: 43005.36 | I28: =G28-H28 -> 8900.427 | J28: =IF(H28=0,"",G28/H28-1) -> 0.20696088 | K28: =IFERROR(G28/SUM(G27:G46),"") -> 0.16394916 | L28: =IFERROR(G28/(SUM(G3:G23,G27:G46)),"") -> 0.071206259 | M28: Qty 840.4->850.4sh since 8/5, likely DRIP reinvestment. Reclassified as cash/dry powder per Alan 9/7/26, not a scored Landry position.
A29: Self-Directed (Chase) | B29: AVUV | C29: Avantis US Small Cap Value ETF | D29: Equity | E29: 400.00001 | F29: =IF(IFERROR(INDEX('Monitor & Recheck Triggers'!$H$3:$H$51,MATCH($B29,'Monitor & Recheck Triggers'!$A$3:$A$51,0)),"")="",120.03,INDEX('Monitor & Recheck Triggers'!$H$3:$H$51,MATCH($B29,'Monitor & Recheck Triggers'!$A$3:$A$51,0))) -> 120.03 | G29: =E29*F29 -> 48012.001 | H29: 45116.29 | I29: =G29-H29 -> 2895.7112 | J29: =IF(H29=0,"",G29/H29-1) -> 0.064183274 | K29: =IFERROR(G29/SUM(G27:G46),"") -> 0.15165028 | L29: =IFERROR(G29/(SUM(G3:G23,G27:G46)),"") -> 0.065864621 | M29: BOUGHT +193.58sh 8/7/26 @ $126.66 -- consolidation target from CALF
A30: Self-Directed (Chase) | B30: CALF | C30: Pacer US Small Cap Cash Cows ETF | D30: Equity | E30: 0 | F30: =IF(IFERROR(INDEX('Monitor & Recheck Triggers'!$H$3:$H$51,MATCH($B30,'Monitor & Recheck Triggers'!$A$3:$A$51,0)),"")="",56.12,INDEX('Monitor & Recheck Triggers'!$H$3:$H$51,MATCH($B30,'Monitor & Recheck Triggers'!$A$3:$A$51,0))) -> 56.12 | G30: =E30*F30 -> 0 | H30: 0 | I30: =G30-H30 -> 0 | J30: =IF(H30=0,"",G30/H30-1) | K30: =IFERROR(G30/SUM(G27:G46),"") -> 0 | L30: =IFERROR(G30/(SUM(G3:G23,G27:G46)),"") -> 0 | M30: SOLD 8/7/26 -- confirmed: -409.55sh, $23,016.52 proceeds. Consolidated into AVUV.
A31: Self-Directed (Chase) | B31: HELO | C31: JPMorgan Hedged Equity Laddered Overlay ETF | D31: Alt. Assets | E31: 500 | F31: =IF(IFERROR(INDEX('Monitor & Recheck Triggers'!$H$3:$H$51,MATCH($B31,'Monitor & Recheck Triggers'!$A$3:$A$51,0)),"")="",69.42,INDEX('Monitor & Recheck Triggers'!$H$3:$H$51,MATCH($B31,'Monitor & Recheck Triggers'!$A$3:$A$51,0))) -> 69.42 | G31: =E31*F31 -> 34710 | H31: 30666 | I31: =G31-H31 -> 4044 | J31: =IF(H31=0,"",G31/H31-1) -> 0.13187243 | K31: =IFERROR(G31/SUM(G27:G46),"") -> 0.1096347 | L31: =IFERROR(G31/(SUM(G3:G23,G27:G46)),"") -> 0.047616449 | M31: BOUGHT +200sh since 8/5 (300->500sh) -- expanding income sleeve. Reclassified as cash/dry powder per Alan 9/7/26, not a scored Landry position.
A32: Self-Directed (Chase) | B32: AVGO | C32: Broadcom Inc. | D32: Equity | E32: 35.07587 | F32: =IF(IFERROR(INDEX('Monitor & Recheck Triggers'!$H$3:$H$51,MATCH($B32,'Monitor & Recheck Triggers'!$A$3:$A$51,0)),"")="",355.14,INDEX('Monitor & Recheck Triggers'!$H$3:$H$51,MATCH($B32,'Monitor & Recheck Triggers'!$A$3:$A$51,0))) -> 362.51 | G32: =E32*F32 -> 12715.354 | H32: 12653.43 | I32: =G32-H32 -> 61.923634 | J32: =IF(H32=0,"",G32/H32-1) -> 0.004893822 | K32: =IFERROR(G32/SUM(G27:G46),"") -> 0.040162603 | L32: =IFERROR(G32/(SUM(G3:G23,G27:G46)),"") -> 0.017443388
A33: Self-Directed (Chase) | B33: NVDA | C33: NVIDIA Corporation | D33: Equity | E33: 59.02188 | F33: =IF(IFERROR(INDEX('Monitor & Recheck Triggers'!$H$3:$H$51,MATCH($B33,'Monitor & Recheck Triggers'!$A$3:$A$51,0)),"")="",233.95,INDEX('Monitor & Recheck Triggers'!$H$3:$H$51,MATCH($B33,'Monitor & Recheck Triggers'!$A$3:$A$51,0))) -> 238.9 | G33: =E33*F33 -> 14100.327 | H33: 11377.73 | I33: =G33-H33 -> 2722.5971 | J33: =IF(H33=0,"",G33/H33-1) -> 0.23929177 | K33: =IFERROR(G33/SUM(G27:G46),"") -> 0.044537168 | L33: =IFERROR(G33/(SUM(G3:G23,G27:G46)),"") -> 0.019343345
A34: Self-Directed (Chase) | B34: VRTX | C34: Vertex Pharmaceuticals | D34: Equity | E34: 65 | F34: =IF(IFERROR(INDEX('Monitor & Recheck Triggers'!$H$3:$H$51,MATCH($B34,'Monitor & Recheck Triggers'!$A$3:$A$51,0)),"")="",504.73,INDEX('Monitor & Recheck Triggers'!$H$3:$H$51,MATCH($B34,'Monitor & Recheck Triggers'!$A$3:$A$51,0))) -> 503.5 | G34: =E34*F34 -> 32727.5 | H34: 31479.64 | I34: =G34-H34 -> 1247.86 | J34: =IF(H34=0,"",G34/H34-1) -> 0.039640225 | K34: =IFERROR(G34/SUM(G27:G46),"") -> 0.10337279 | L34: =IFERROR(G34/(SUM(G3:G23,G27:G46)),"") -> 0.044896783 | M34: BOUGHT +15sh 9/8/26 @ ~$527.47 ($7,912.09) -- DCA-TRANCHE-2 diversifier add.
A35: Self-Directed (Chase) | B35: SPMO | C35: Invesco S&P 500 Momentum ETF | D35: Equity | E35: 76.93745 | F35: =IF(IFERROR(INDEX('Monitor & Recheck Triggers'!$H$3:$H$51,MATCH($B35,'Monitor & Recheck Triggers'!$A$3:$A$51,0)),"")="",153.23,INDEX('Monitor & Recheck Triggers'!$H$3:$H$51,MATCH($B35,'Monitor & Recheck Triggers'!$A$3:$A$51,0))) -> 153.23 | G35: =E35*F35 -> 11789.125 | H35: 9318.79 | I35: =G35-H35 -> 2470.3355 | J35: =IF(H35=0,"",G35/H35-1) -> 0.26509187 | K35: =IFERROR(G35/SUM(G27:G46),"") -> 0.037237027 | L35: =IFERROR(G35/(SUM(G3:G23,G27:G46)),"") -> 0.016172754
A36: Self-Directed (Chase) | B36: VFLO | C36: VictoryShares Free Cash Flow ETF | D36: Equity | E36: 200 | F36: =IF(IFERROR(INDEX('Monitor & Recheck Triggers'!$H$3:$H$51,MATCH($B36,'Monitor & Recheck Triggers'!$A$3:$A$51,0)),"")="",51.82,INDEX('Monitor & Recheck Triggers'!$H$3:$H$51,MATCH($B36,'Monitor & Recheck Triggers'!$A$3:$A$51,0))) -> 51.82 | G36: =E36*F36 -> 10364 | H36: 9257 | I36: =G36-H36 -> 1107 | J36: =IF(H36=0,"",G36/H36-1) -> 0.11958518 | K36: =IFERROR(G36/SUM(G27:G46),"") -> 0.032735638 | L36: =IFERROR(G36/(SUM(G3:G23,G27:G46)),"") -> 0.014217715
A37: Self-Directed (Chase) | B37: ANET | C37: Arista Networks | D37: Equity | E37: 50 | F37: =IF(IFERROR(INDEX('Monitor & Recheck Triggers'!$H$3:$H$51,MATCH($B37,'Monitor & Recheck Triggers'!$A$3:$A$51,0)),"")="",207.35,INDEX('Monitor & Recheck Triggers'!$H$3:$H$51,MATCH($B37,'Monitor & Recheck Triggers'!$A$3:$A$51,0))) -> 206.9 | G37: =E37*F37 -> 10345 | H37: 7394.5 | I37: =G37-H37 -> 2950.5 | J37: =IF(H37=0,"",G37/H37-1) -> 0.39901278 | K37: =IFERROR(G37/SUM(G27:G46),"") -> 0.032675625 | L37: =IFERROR(G37/(SUM(G3:G23,G27:G46)),"") -> 0.01419165
A38: Self-Directed (Chase) | B38: CRWD | C38: CrowdStrike Holdings | D38: Equity | E38: 45 | F38: =IF(IFERROR(INDEX('Monitor & Recheck Triggers'!$H$3:$H$51,MATCH($B38,'Monitor & Recheck Triggers'!$A$3:$A$51,0)),"")="",270.04,INDEX('Monitor & Recheck Triggers'!$H$3:$H$51,MATCH($B38,'Monitor & Recheck Triggers'!$A$3:$A$51,0))) -> 272.67 | G38: =E38*F38 -> 12270.15 | H38: 7099.31 | I38: =G38-H38 -> 5170.84 | J38: =IF(H38=0,"",G38/H38-1) -> 0.72835811 | K38: =IFERROR(G38/SUM(G27:G46),"") -> 0.038756387 | L38: =IFERROR(G38/(SUM(G3:G23,G27:G46)),"") -> 0.016832641
A39: Self-Directed (Chase) | B39: PLD | C39: Prologis Inc. | D39: Equity | E39: 125.44837 | F39: =IF(IFERROR(INDEX('Monitor & Recheck Triggers'!$H$3:$H$51,MATCH($B39,'Monitor & Recheck Triggers'!$A$3:$A$51,0)),"")="",128.91,INDEX('Monitor & Recheck Triggers'!$H$3:$H$51,MATCH($B39,'Monitor & Recheck Triggers'!$A$3:$A$51,0))) -> 128.08 | G39: =E39*F39 -> 16067.427 | H39: 16585.43 | I39: =G39-H39 -> -518.00277 | J39: =IF(H39=0,"",G39/H39-1) -> -0.031232399 | K39: =IFERROR(G39/SUM(G27:G46),"") -> 0.050750433 | L39: =IFERROR(G39/(SUM(G3:G23,G27:G46)),"") -> 0.022041885 | M39: BOUGHT +64sh 8/7/26 @ $139.92 -- DCA tranche 1 diversifier add
A40: Self-Directed (Chase) | B40: SFM | C40: Sprouts Farmers Market | D40: Equity | E40: 0 | F40: =IF(IFERROR(INDEX('Monitor & Recheck Triggers'!$H$3:$H$51,MATCH($B40,'Monitor & Recheck Triggers'!$A$3:$A$51,0)),"")="",86.07,INDEX('Monitor & Recheck Triggers'!$H$3:$H$51,MATCH($B40,'Monitor & Recheck Triggers'!$A$3:$A$51,0))) -> 64.92 | G40: =E40*F40 -> 0 | H40: 0 | I40: =G40-H40 -> 0 | J40: =IF(H40=0,"",G40/H40-1) | K40: =IFERROR(G40/SUM(G27:G46),"") -> 0 | L40: =IFERROR(G40/(SUM(G3:G23,G27:G46)),"") -> 0 | M40: SOLD 08/07/26 -- confirmed: -65 sh, $5,601.58 proceeds. Rule 3 Avoid. Proceeds added to VMFXX.
A41: Self-Directed (Chase) | B41: TSLA | C41: Tesla Inc. | D41: Equity | E41: 0 | F41: =IF(IFERROR(INDEX('Monitor & Recheck Triggers'!$H$3:$H$51,MATCH($B41,'Monitor & Recheck Triggers'!$A$3:$A$51,0)),"")="",327.35,INDEX('Monitor & Recheck Triggers'!$H$3:$H$51,MATCH($B41,'Monitor & Recheck Triggers'!$A$3:$A$51,0))) -> 378.73 | G41: =E41*F41 -> 0 | H41: 0 | I41: =G41-H41 -> 0 | J41: =IF(H41=0,"",G41/H41-1) | K41: =IFERROR(G41/SUM(G27:G46),"") -> 0 | L41: =IFERROR(G41/(SUM(G3:G23,G27:G46)),"") -> 0 | M41: SOLD 08/07/26 -- confirmed: -15 sh, $4,783.25 proceeds. Rule 3 Avoid. Proceeds added to VMFXX.
...

Sheet Monitor & Recheck Triggers
A1: Recheck triggers for every name that's been scored, not just Watch List holdings. Current Price, Insider Activity, and Analyst Shift are Claude-populated (STOCKHISTORY formula + manual recalc for price; SEC EDGAR and yfinance consensus data for the other two, refreshed periodically, not live). Recheck Status calculates automatically from all signals together. For held positions, Last Score (cols C-G) mirrors the Scoring row -- `python -m landry monitor stamp` does it after any re-score or Decision change -- and the insider / analyst signals (K-N) are refreshed monthly with `python -m landry monitor refresh` (dated in Q1); `landry audit` holds both (Alan, 10/5/26). | P1: Insider / analyst signals refreshed | Q1: 46300
A2: Ticker | B2: Category | C2: Last Score Date | D2: Last Composite | E2: Last Tier 1 Wtd Avg | F2: Last Decision | G2: Price at Last Score | H2: Current Price | I2: % Price Change | J2: Next/Last Earnings Date | K2: Insider Activity? (Y/N) | L2: Insider Note | M2: Analyst Shift? (Y/N) | N2: Analyst Shift Note | O2: Days Since Last Score | P2: Recheck Status | Q2: Notes
A3: ADBE | B3: Owned | C3: 46295 | D3: 85.8 | E3: 4.57 | F3: STRONG BUY | G3: 239.94 | H3: {=IFERROR(INDEX(_xlfn.STOCKHISTORY(A3,TODAY()-5,TODAY(),0,0,1),ROWS(_xlfn.STOCKHISTORY(A3,TODAY()-5,TODAY(),0,0,1)),1),"")} -> 238.785 | I3: =IF(OR(G3="",H3=""),"",H3/G3-1) -> -0.0048137034 | J3: 46365 | K3: Y | L3: 2026-09-18: NARAYEN SHANTANU (Chair and CEO) sold $2,091,376, 2% of holding (+11 more in last 30d) | M3: N | O3: =IF(C3="","",TODAY()-C3) -> 6 | P3: =IF(A3="","",IF(O3>180,"DUE — STALE (>180 days)",IF(J3<>"",IF(ABS(J3-TODAY())<=7,"DUE — EARNINGS WINDOW",IF(I3<>"",IF(ABS(I3)>=0.2,"DUE — PRICE MOVE ±20%",IF(K3="Y","DUE — INSIDER ACTIVITY",IF(I3<>"",IF(ABS(I3)>=0.15,"WATCH — PRICE MOVE ±15%",IF(M3="Y","WATCH — ANALYST SHIFT","Monitor Only")),IF(M3="Y","WATCH — ANALYST SHIFT","Monitor Only")))),IF(K3="Y","DUE — INSIDER ACTIVITY",IF(I3<>"",IF(ABS(I3)>=0.15,"WATCH — PRICE MOVE ±15%",IF(M3="Y","WATCH — ANALYST SHIFT","Monitor Only")),IF(M3="Y","WATCH — ANALYST SHIFT","Monitor Only"))))),IF(I3<>"",IF(ABS(I3)>=0.2,"DUE — PRICE MOVE ±20%",IF(K3="Y","DUE — INSIDER ACTIVITY",IF(I3<>"",IF(ABS(I3)>=0.15,"WATCH — PRICE MOVE ±15%",IF(M3="Y","WATCH — ANALYST SHIFT","Monitor Only")),IF(M3="Y","WATCH — ANALYST SHIFT","Monitor Only")))),IF(K3="Y","DUE — INSIDER ACTIVITY",IF(I3<>"",IF(ABS(I3)>=0.15,"WATCH — PRICE MOVE ±15%",IF(M3="Y","WATCH — ANALYST SHIFT","Monitor Only")),IF(M3="Y","WATCH — ANALYST SHIFT","Monitor Only"))))))) -> DUE — INSIDER ACTIVITY
A4: ANET | B4: Owned | C4: 46278 | D4: 81 | E4: 4.29 | F4: STRONG BUY | G4: 199.59 | H4: {=IFERROR(INDEX(_xlfn.STOCKHISTORY(A4,TODAY()-5,TODAY(),0,0,1),ROWS(_xlfn.STOCKHISTORY(A4,TODAY()-5,TODAY(),0,0,1)),1),"")} -> 206.9 | I4: =IF(OR(G4="",H4=""),"",H4/G4-1) -> 0.036625081 | J4: 46329 | K4: Y | L4: 2026-09-29: Ullal Jayshree (CEO and Chairperson) sold $1,891,569, 0% of holding (+33 more in last 30d) | M4: N | O4: =IF(C4="","",TODAY()-C4) -> 23 | P4: =IF(A4="","",IF(O4>180,"DUE — STALE (>180 days)",IF(J4<>"",IF(ABS(J4-TODAY())<=7,"DUE — EARNINGS WINDOW",IF(I4<>"",IF(ABS(I4)>=0.2,"DUE — PRICE MOVE ±20%",IF(K4="Y","DUE — INSIDER ACTIVITY",IF(I4<>"",IF(ABS(I4)>=0.15,"WATCH — PRICE MOVE ±15%",IF(M4="Y","WATCH — ANALYST SHIFT","Monitor Only")),IF(M4="Y","WATCH — ANALYST SHIFT","Monitor Only")))),IF(K4="Y","DUE — INSIDER ACTIVITY",IF(I4<>"",IF(ABS(I4)>=0.15,"WATCH — PRICE MOVE ±15%",IF(M4="Y","WATCH — ANALYST SHIFT","Monitor Only")),IF(M4="Y","WATCH — ANALYST SHIFT","Monitor Only"))))),IF(I4<>"",IF(ABS(I4)>=0.2,"DUE — PRICE MOVE ±20%",IF(K4="Y","DUE — INSIDER ACTIVITY",IF(I4<>"",IF(ABS(I4)>=0.15,"WATCH — PRICE MOVE ±15%",IF(M4="Y","WATCH — ANALYST SHIFT","Monitor Only")),IF(M4="Y","WATCH — ANALYST SHIFT","Monitor Only")))),IF(K4="Y","DUE — INSIDER ACTIVITY",IF(I4<>"",IF(ABS(I4)>=0.15,"WATCH — PRICE MOVE ±15%",IF(M4="Y","WATCH — ANALYST SHIFT","Monitor Only")),IF(M4="Y","WATCH — ANALYST SHIFT","Monitor Only"))))))) -> DUE — INSIDER ACTIVITY
A5: ASML | B5: Owned | C5: 46278 | D5: 77.2 | E5: 3.86 | F5: BUY | G5: 1698.3 | H5: {=IFERROR(INDEX(_xlfn.STOCKHISTORY(A5,TODAY()-5,TODAY(),0,0,1),ROWS(_xlfn.STOCKHISTORY(A5,TODAY()-5,TODAY(),0,0,1)),1),"")} -> 1859.86 | I5: =IF(OR(G5="",H5=""),"",H5/G5-1) -> 0.095130425 | J5: 46309 | K5: N | M5: N | O5: =IF(C5="","",TODAY()-C5) -> 23 | P5: =IF(A5="","",IF(O5>180,"DUE — STALE (>180 days)",IF(J5<>"",IF(ABS(J5-TODAY())<=7,"DUE — EARNINGS WINDOW",IF(I5<>"",IF(ABS(I5)>=0.2,"DUE — PRICE MOVE ±20%",IF(K5="Y","DUE — INSIDER ACTIVITY",IF(I5<>"",IF(ABS(I5)>=0.15,"WATCH — PRICE MOVE ±15%",IF(M5="Y","WATCH — ANALYST SHIFT","Monitor Only")),IF(M5="Y","WATCH — ANALYST SHIFT","Monitor Only")))),IF(K5="Y","DUE — INSIDER ACTIVITY",IF(I5<>"",IF(ABS(I5)>=0.15,"WATCH — PRICE MOVE ±15%",IF(M5="Y","WATCH — ANALYST SHIFT","Monitor Only")),IF(M5="Y","WATCH — ANALYST SHIFT","Monitor Only"))))),IF(I5<>"",IF(ABS(I5)>=0.2,"DUE — PRICE MOVE ±20%",IF(K5="Y","DUE — INSIDER ACTIVITY",IF(I5<>"",IF(ABS(I5)>=0.15,"WATCH — PRICE MOVE ±15%",IF(M5="Y","WATCH — ANALYST SHIFT","Monitor Only")),IF(M5="Y","WATCH — ANALYST SHIFT","Monitor Only")))),IF(K5="Y","DUE — INSIDER ACTIVITY",IF(I5<>"",IF(ABS(I5)>=0.15,"WATCH — PRICE MOVE ±15%",IF(M5="Y","WATCH — ANALYST SHIFT","Monitor Only")),IF(M5="Y","WATCH — ANALYST SHIFT","Monitor Only"))))))) -> Monitor Only
A6: CRWD | B6: Owned | C6: 46278 | D6: 63.4 | E6: 3.5 | F6: AVOID | G6: 206.74 | H6: {=IFERROR(INDEX(_xlfn.STOCKHISTORY(A6,TODAY()-5,TODAY(),0,0,1),ROWS(_xlfn.STOCKHISTORY(A6,TODAY()-5,TODAY(),0,0,1)),1),"")} -> 272.67 | I6: =IF(OR(G6="",H6=""),"",H6/G6-1) -> 0.31890297 | J6: 46357 | K6: Y | L6: 2026-10-02: Sentonas Michael (PRESIDENT) sold $3,487,213, 1% of holding (+153 more in last 30d) | M6: N | O6: =IF(C6="","",TODAY()-C6) -> 23 | P6: =IF(A6="","",IF(O6>180,"DUE — STALE (>180 days)",IF(J6<>"",IF(ABS(J6-TODAY())<=7,"DUE — EARNINGS WINDOW",IF(I6<>"",IF(ABS(I6)>=0.2,"DUE — PRICE MOVE ±20%",IF(K6="Y","DUE — INSIDER ACTIVITY",IF(I6<>"",IF(ABS(I6)>=0.15,"WATCH — PRICE MOVE ±15%",IF(M6="Y","WATCH — ANALYST SHIFT","Monitor Only")),IF(M6="Y","WATCH — ANALYST SHIFT","Monitor Only")))),IF(K6="Y","DUE — INSIDER ACTIVITY",IF(I6<>"",IF(ABS(I6)>=0.15,"WATCH — PRICE MOVE ±15%",IF(M6="Y","WATCH — ANALYST SHIFT","Monitor Only")),IF(M6="Y","WATCH — ANALYST SHIFT","Monitor Only"))))),IF(I6<>"",IF(ABS(I6)>=0.2,"DUE — PRICE MOVE ±20%",IF(K6="Y","DUE — INSIDER ACTIVITY",IF(I6<>"",IF(ABS(I6)>=0.15,"WATCH — PRICE MOVE ±15%",IF(M6="Y","WATCH — ANALYST SHIFT","Monitor Only")),IF(M6="Y","WATCH — ANALYST SHIFT","Monitor Only")))),IF(K6="Y","DUE — INSIDER ACTIVITY",IF(I6<>"",IF(ABS(I6)>=0.15,"WATCH — PRICE MOVE ±15%",IF(M6="Y","WATCH — ANALYST SHIFT","Monitor Only")),IF(M6="Y","WATCH — ANALYST SHIFT","Monitor Only"))))))) -> DUE — PRICE MOVE ±20%
A7: KLAC | B7: Owned | C7: 46278 | D7: 72.6 | E7: 3.71 | F7: BUY | G7: 180.64 | H7: {=IFERROR(INDEX(_xlfn.STOCKHISTORY(A7,TODAY()-5,TODAY(),0,0,1),ROWS(_xlfn.STOCKHISTORY(A7,TODAY()-5,TODAY(),0,0,1)),1),"")} -> 206.85 | I7: =IF(OR(G7="",H7=""),"",H7/G7-1) -> 0.14509522 | J7: 46323 | K7: Y | L7: 2026-09-16: WALLACE RICHARD P (President and CEO) sold $12,378,626, 9% of holding | M7: N | O7: =IF(C7="","",TODAY()-C7) -> 23 | P7: =IF(A7="","",IF(O7>180,"DUE — STALE (>180 days)",IF(J7<>"",IF(ABS(J7-TODAY())<=7,"DUE — EARNINGS WINDOW",IF(I7<>"",IF(ABS(I7)>=0.2,"DUE — PRICE MOVE ±20%",IF(K7="Y","DUE — INSIDER ACTIVITY",IF(I7<>"",IF(ABS(I7)>=0.15,"WATCH — PRICE MOVE ±15%",IF(M7="Y","WATCH — ANALYST SHIFT","Monitor Only")),IF(M7="Y","WATCH — ANALYST SHIFT","Monitor Only")))),IF(K7="Y","DUE — INSIDER ACTIVITY",IF(I7<>"",IF(ABS(I7)>=0.15,"WATCH — PRICE MOVE ±15%",IF(M7="Y","WATCH — ANALYST SHIFT","Monitor Only")),IF(M7="Y","WATCH — ANALYST SHIFT","Monitor Only"))))),IF(I7<>"",IF(ABS(I7)>=0.2,"DUE — PRICE MOVE ±20%",IF(K7="Y","DUE — INSIDER ACTIVITY",IF(I7<>"",IF(ABS(I7)>=0.15,"WATCH — PRICE MOVE ±15%",IF(M7="Y","WATCH — ANALYST SHIFT","Monitor Only")),IF(M7="Y","WATCH — ANALYST SHIFT","Monitor Only")))),IF(K7="Y","DUE — INSIDER ACTIVITY",IF(I7<>"",IF(ABS(I7)>=0.15,"WATCH — PRICE MOVE ±15%",IF(M7="Y","WATCH — ANALYST SHIFT","Monitor Only")),IF(M7="Y","WATCH — ANALYST SHIFT","Monitor Only"))))))) -> DUE — INSIDER ACTIVITY
A8: MU | B8: Owned | C8: 46278 | D8: 67.8 | E8: 3.36 | F8: BUY | G8: 975.26 | H8: {=IFERROR(INDEX(_xlfn.STOCKHISTORY(A8,TODAY()-5,TODAY(),0,0,1),ROWS(_xlfn.STOCKHISTORY(A8,TODAY()-5,TODAY(),0,0,1)),1),"")} -> 1063.96 | I8: =IF(OR(G8="",H8=""),"",H8/G8-1) -> 0.090950106 | J8: 46379 | K8: N | M8: N | O8: =IF(C8="","",TODAY()-C8) -> 23 | P8: =IF(A8="","",IF(O8>180,"DUE — STALE (>180 days)",IF(J8<>"",IF(ABS(J8-TODAY())<=7,"DUE — EARNINGS WINDOW",IF(I8<>"",IF(ABS(I8)>=0.2,"DUE — PRICE MOVE ±20%",IF(K8="Y","DUE — INSIDER ACTIVITY",IF(I8<>"",IF(ABS(I8)>=0.15,"WATCH — PRICE MOVE ±15%",IF(M8="Y","WATCH — ANALYST SHIFT","Monitor Only")),IF(M8="Y","WATCH — ANALYST SHIFT","Monitor Only")))),IF(K8="Y","DUE — INSIDER ACTIVITY",IF(I8<>"",IF(ABS(I8)>=0.15,"WATCH — PRICE MOVE ±15%",IF(M8="Y","WATCH — ANALYST SHIFT","Monitor Only")),IF(M8="Y","WATCH — ANALYST SHIFT","Monitor Only"))))),IF(I8<>"",IF(ABS(I8)>=0.2,"DUE — PRICE MOVE ±20%",IF(K8="Y","DUE — INSIDER ACTIVITY",IF(I8<>"",IF(ABS(I8)>=0.15,"WATCH — PRICE MOVE ±15%",IF(M8="Y","WATCH — ANALYST SHIFT","Monitor Only")),IF(M8="Y","WATCH — ANALYST SHIFT","Monitor Only")))),IF(K8="Y","DUE — INSIDER ACTIVITY",IF(I8<>"",IF(ABS(I8)>=0.15,"WATCH — PRICE MOVE ±15%",IF(M8="Y","WATCH — ANALYST SHIFT","Monitor Only")),IF(M8="Y","WATCH — ANALYST SHIFT","Monitor Only"))))))) -> Monitor Only
A9: NVDA | B9: Owned | C9: 46278 | D9: 89.2 | E9: 4.29 | F9: STRONG BUY | G9: 218.29 | H9: {=IFERROR(INDEX(_xlfn.STOCKHISTORY(A9,TODAY()-5,TODAY(),0,0,1),ROWS(_xlfn.STOCKHISTORY(A9,TODAY()-5,TODAY(),0,0,1)),1),"")} -> 238.9 | I9: =IF(OR(G9="",H9=""),"",H9/G9-1) -> 0.094415686 | J9: 46343 | K9: Y | L9: 2026-09-23: Teter Timothy S. (EVP, General Counsel and Sec) sold $2,773,638, 0% of holding (+14 more in last 30d) | M9: N | O9: =IF(C9="","",TODAY()-C9) -> 23 | P9: =IF(A9="","",IF(O9>180,"DUE — STALE (>180 days)",IF(J9<>"",IF(ABS(J9-TODAY())<=7,"DUE — EARNINGS WINDOW",IF(I9<>"",IF(ABS(I9)>=0.2,"DUE — PRICE MOVE ±20%",IF(K9="Y","DUE — INSIDER ACTIVITY",IF(I9<>"",IF(ABS(I9)>=0.15,"WATCH — PRICE MOVE ±15%",IF(M9="Y","WATCH — ANALYST SHIFT","Monitor Only")),IF(M9="Y","WATCH — ANALYST SHIFT","Monitor Only")))),IF(K9="Y","DUE — INSIDER ACTIVITY",IF(I9<>"",IF(ABS(I9)>=0.15,"WATCH — PRICE MOVE ±15%",IF(M9="Y","WATCH — ANALYST SHIFT","Monitor Only")),IF(M9="Y","WATCH — ANALYST SHIFT","Monitor Only"))))),IF(I9<>"",IF(ABS(I9)>=0.2,"DUE — PRICE MOVE ±20%",IF(K9="Y","DUE — INSIDER ACTIVITY",IF(I9<>"",IF(ABS(I9)>=0.15,"WATCH — PRICE MOVE ±15%",IF(M9="Y","WATCH — ANALYST SHIFT","Monitor Only")),IF(M9="Y","WATCH — ANALYST SHIFT","Monitor Only")))),IF(K9="Y","DUE — INSIDER ACTIVITY",IF(I9<>"",IF(ABS(I9)>=0.15,"WATCH — PRICE MOVE ±15%",IF(M9="Y","WATCH — ANALYST SHIFT","Monitor Only")),IF(M9="Y","WATCH — ANALYST SHIFT","Monitor Only"))))))) -> DUE — INSIDER ACTIVITY
A10: PLTR | B10: Owned | C10: 46278 | D10: 76.2 | E10: 4.07 | F10: BUY | G10: 167.23 | H10: {=IFERROR(INDEX(_xlfn.STOCKHISTORY(A10,TODAY()-5,TODAY(),0,0,1),ROWS(_xlfn.STOCKHISTORY(A10,TODAY()-5,TODAY(),0,0,1)),1),"")} -> 189.4 | I10: =IF(OR(G10="",H10=""),"",H10/G10-1) -> 0.13257191 | J10: 46328 | K10: Y | L10: 2026-09-17: Moore Alexander D. (Director) sold $222,702, 0% of holding (+5 more in last 30d) | M10: N | O10: =IF(C10="","",TODAY()-C10) -> 23 | P10: =IF(A10="","",IF(O10>180,"DUE — STALE (>180 days)",IF(J10<>"",IF(ABS(J10-TODAY())<=7,"DUE — EARNINGS WINDOW",IF(I10<>"",IF(ABS(I10)>=0.2,"DUE — PRICE MOVE ±20%",IF(K10="Y","DUE — INSIDER ACTIVITY",IF(I10<>"",IF(ABS(I10)>=0.15,"WATCH — PRICE MOVE ±15%",IF(M10="Y","WATCH — ANALYST SHIFT","Monitor Only")),IF(M10="Y","WATCH — ANALYST SHIFT","Monitor Only")))),IF(K10="Y","DUE — INSIDER ACTIVITY",IF(I10<>"",IF(ABS(I10)>=0.15,"WATCH — PRICE MOVE ±15%",IF(M10="Y","WATCH — ANALYST SHIFT","Monitor Only")),IF(M10="Y","WATCH — ANALYST SHIFT","Monitor Only"))))),IF(I10<>"",IF(ABS(I10)>=0.2,"DUE — PRICE MOVE ±20%",IF(K10="Y","DUE — INSIDER ACTIVITY",IF(I10<>"",IF(ABS(I10)>=0.15,"WATCH — PRICE MOVE ±15%",IF(M10="Y","WATCH — ANALYST SHIFT","Monitor Only")),IF(M10="Y","WATCH — ANALYST SHIFT","Monitor Only")))),IF(K10="Y","DUE — INSIDER ACTIVITY",IF(I10<>"",IF(ABS(I10)>=0.15,"WATCH — PRICE MOVE ±15%",IF(M10="Y","WATCH — ANALYST SHIFT","Monitor Only")),IF(M10="Y","WATCH — ANALYST SHIFT","Monitor Only"))))))) -> DUE — INSIDER ACTIVITY
A11: TSM | B11: Owned | C11: 46278 | D11: 84 | E11: 4.21 | F11: STRONG BUY | G11: 433.24 | H11: {=IFERROR(INDEX(_xlfn.STOCKHISTORY(A11,TODAY()-5,TODAY(),0,0,1),ROWS(_xlfn.STOCKHISTORY(A11,TODAY()-5,TODAY(),0,0,1)),1),"")} -> 485.8 | I11: =IF(OR(G11="",H11=""),"",H11/G11-1) -> 0.12131844 | J11: 46310 | K11: Y | L11: 2026-09-09: Wu Yi-Huang (VP) bought $3,048, 33% of holding (+6 more in last 30d) | M11: N | O11: =IF(C11="","",TODAY()-C11) -> 23 | P11: =IF(A11="","",IF(O11>180,"DUE — STALE (>180 days)",IF(J11<>"",IF(ABS(J11-TODAY())<=7,"DUE — EARNINGS WINDOW",IF(I11<>"",IF(ABS(I11)>=0.2,"DUE — PRICE MOVE ±20%",IF(K11="Y","DUE — INSIDER ACTIVITY",IF(I11<>"",IF(ABS(I11)>=0.15,"WATCH — PRICE MOVE ±15%",IF(M11="Y","WATCH — ANALYST SHIFT","Monitor Only")),IF(M11="Y","WATCH — ANALYST SHIFT","Monitor Only")))),IF(K11="Y","DUE — INSIDER ACTIVITY",IF(I11<>"",IF(ABS(I11)>=0.15,"WATCH — PRICE MOVE ±15%",IF(M11="Y","WATCH — ANALYST SHIFT","Monitor Only")),IF(M11="Y","WATCH — ANALYST SHIFT","Monitor Only"))))),IF(I11<>"",IF(ABS(I11)>=0.2,"DUE — PRICE MOVE ±20%",IF(K11="Y","DUE — INSIDER ACTIVITY",IF(I11<>"",IF(ABS(I11)>=0.15,"WATCH — PRICE MOVE ±15%",IF(M11="Y","WATCH — ANALYST SHIFT","Monitor Only")),IF(M11="Y","WATCH — ANALYST SHIFT","Monitor Only")))),IF(K11="Y","DUE — INSIDER ACTIVITY",IF(I11<>"",IF(ABS(I11)>=0.15,"WATCH — PRICE MOVE ±15%",IF(M11="Y","WATCH — ANALYST SHIFT","Monitor Only")),IF(M11="Y","WATCH — ANALYST SHIFT","Monitor Only"))))))) -> DUE — INSIDER ACTIVITY
A12: VRT | B12: Owned | C12: 46278 | D12: 76.8 | E12: 3.93 | F12: BUY | G12: 257.06 | H12: {=IFERROR(INDEX(_xlfn.STOCKHISTORY(A12,TODAY()-5,TODAY(),0,0,1),ROWS(_xlfn.STOCKHISTORY(A12,TODAY()-5,TODAY(),0,0,1)),1),"")} -> 253.62 | I12: =IF(OR(G12="",H12=""),"",H12/G12-1) -> -0.01338209 | J12: 46316 | K12: N | M12: N | O12: =IF(C12="","",TODAY()-C12) -> 23 | P12: =IF(A12="","",IF(O12>180,"DUE — STALE (>180 days)",IF(J12<>"",IF(ABS(J12-TODAY())<=7,"DUE — EARNINGS WINDOW",IF(I12<>"",IF(ABS(I12)>=0.2,"DUE — PRICE MOVE ±20%",IF(K12="Y","DUE — INSIDER ACTIVITY",IF(I12<>"",IF(ABS(I12)>=0.15,"WATCH — PRICE MOVE ±15%",IF(M12="Y","WATCH — ANALYST SHIFT","Monitor Only")),IF(M12="Y","WATCH — ANALYST SHIFT","Monitor Only")))),IF(K12="Y","DUE — INSIDER ACTIVITY",IF(I12<>"",IF(ABS(I12)>=0.15,"WATCH — PRICE MOVE ±15%",IF(M12="Y","WATCH — ANALYST SHIFT","Monitor Only")),IF(M12="Y","WATCH — ANALYST SHIFT","Monitor Only"))))),IF(I12<>"",IF(ABS(I12)>=0.2,"DUE — PRICE MOVE ±20%",IF(K12="Y","DUE — INSIDER ACTIVITY",IF(I12<>"",IF(ABS(I12)>=0.15,"WATCH — PRICE MOVE ±15%",IF(M12="Y","WATCH — ANALYST SHIFT","Monitor Only")),IF(M12="Y","WATCH — ANALYST SHIFT","Monitor Only")))),IF(K12="Y","DUE — INSIDER ACTIVITY",IF(I12<>"",IF(ABS(I12)>=0.15,"WATCH — PRICE MOVE ±15%",IF(M12="Y","WATCH — ANALYST SHIFT","Monitor Only")),IF(M12="Y","WATCH — ANALYST SHIFT","Monitor Only"))))))) -> Monitor Only
A13: AVGO | B13: Owned | C13: 46300 | D13: 74.8 | E13: 3.64 | F13: BUY | G13: 355.14 | H13: {=IFERROR(INDEX(_xlfn.STOCKHISTORY(A13,TODAY()-5,TODAY(),0,0,1),ROWS(_xlfn.STOCKHISTORY(A13,TODAY()-5,TODAY(),0,0,1)),1),"")} -> 362.51 | I13: =IF(OR(G13="",H13=""),"",H13/G13-1) -> 0.020752379 | J13: 46365 | K13: Y | L13: 2026-09-25: SAMUELI HENRY (Director) sold $8,025,864, 0% of holding (+15 more in last 30d) | M13: N | O13: =IF(C13="","",TODAY()-C13) -> 1 | P13: =IF(A13="","",IF(O13>180,"DUE — STALE (>180 days)",IF(J13<>"",IF(ABS(J13-TODAY())<=7,"DUE — EARNINGS WINDOW",IF(I13<>"",IF(ABS(I13)>=0.2,"DUE — PRICE MOVE ±20%",IF(K13="Y","DUE — INSIDER ACTIVITY",IF(I13<>"",IF(ABS(I13)>=0.15,"WATCH — PRICE MOVE ±15%",IF(M13="Y","WATCH — ANALYST SHIFT","Monitor Only")),IF(M13="Y","WATCH — ANALYST SHIFT","Monitor Only")))),IF(K13="Y","DUE — INSIDER ACTIVITY",IF(I13<>"",IF(ABS(I13)>=0.15,"WATCH — PRICE MOVE ±15%",IF(M13="Y","WATCH — ANALYST SHIFT","Monitor Only")),IF(M13="Y","WATCH — ANALYST SHIFT","Monitor Only"))))),IF(I13<>"",IF(ABS(I13)>=0.2,"DUE — PRICE MOVE ±20%",IF(K13="Y","DUE — INSIDER ACTIVITY",IF(I13<>"",IF(ABS(I13)>=0.15,"WATCH — PRICE MOVE ±15%",IF(M13="Y","WATCH — ANALYST SHIFT","Monitor Only")),IF(M13="Y","WATCH — ANALYST SHIFT","Monitor Only")))),IF(K13="Y","DUE — INSIDER ACTIVITY",IF(I13<>"",IF(ABS(I13)>=0.15,"WATCH — PRICE MOVE ±15%",IF(M13="Y","WATCH — ANALYST SHIFT","Monitor Only")),IF(M13="Y","WATCH — ANALYST SHIFT","Monitor Only"))))))) -> DUE — INSIDER ACTIVITY | Q13: Re-scored 10/5/26 on the latest 10-Q figures (Journal row 92): Rule 3 cleared.
A14: PLD | B14: Owned | C14: 46295 | D14: 76 | E14: 3.93 | F14: BUY | G14: 129.84 | H14: {=IFERROR(INDEX(_xlfn.STOCKHISTORY(A14,TODAY()-5,TODAY(),0,0,1),ROWS(_xlfn.STOCKHISTORY(A14,TODAY()-5,TODAY(),0,0,1)),1),"")} -> 128.08 | I14: =IF(OR(G14="",H14=""),"",H14/G14-1) -> -0.013555145 | J14: 46310 | K14: N | M14: N | O14: =IF(C14="","",TODAY()-C14) -> 6 | P14: =IF(A14="","",IF(O14>180,"DUE — STALE (>180 days)",IF(J14<>"",IF(ABS(J14-TODAY())<=7,"DUE — EARNINGS WINDOW",IF(I14<>"",IF(ABS(I14)>=0.2,"DUE — PRICE MOVE ±20%",IF(K14="Y","DUE — INSIDER ACTIVITY",IF(I14<>"",IF(ABS(I14)>=0.15,"WATCH — PRICE MOVE ±15%",IF(M14="Y","WATCH — ANALYST SHIFT","Monitor Only")),IF(M14="Y","WATCH — ANALYST SHIFT","Monitor Only")))),IF(K14="Y","DUE — INSIDER ACTIVITY",IF(I14<>"",IF(ABS(I14)>=0.15,"WATCH — PRICE MOVE ±15%",IF(M14="Y","WATCH — ANALYST SHIFT","Monitor Only")),IF(M14="Y","WATCH — ANALYST SHIFT","Monitor Only"))))),IF(I14<>"",IF(ABS(I14)>=0.2,"DUE — PRICE MOVE ±20%",IF(K14="Y","DUE — INSIDER ACTIVITY",IF(I14<>"",IF(ABS(I14)>=0.15,"WATCH — PRICE MOVE ±15%",IF(M14="Y","WATCH — ANALYST SHIFT","Monitor Only")),IF(M14="Y","WATCH — ANALYST SHIFT","Monitor Only")))),IF(K14="Y","DUE — INSIDER ACTIVITY",IF(I14<>"",IF(ABS(I14)>=0.15,"WATCH — PRICE MOVE ±15%",IF(M14="Y","WATCH — ANALYST SHIFT","Monitor Only")),IF(M14="Y","WATCH — ANALYST SHIFT","Monitor Only"))))))) -> Monitor Only
A15: VRTX | B15: Owned | C15: 46300 | D15: 70.6 | E15: 3.43 | F15: BUY | G15: 504.73 | H15: {=IFERROR(INDEX(_xlfn.STOCKHISTORY(A15,TODAY()-5,TODAY(),0,0,1),ROWS(_xlfn.STOCKHISTORY(A15,TODAY()-5,TODAY(),0,0,1)),1),"")} -> 503.5 | I15: =IF(OR(G15="",H15=""),"",H15/G15-1) -> -0.0024369465 | J15: 46328 | K15: N | M15: N | O15: =IF(C15="","",TODAY()-C15) -> 1 | P15: =IF(A15="","",IF(O15>180,"DUE — STALE (>180 days)",IF(J15<>"",IF(ABS(J15-TODAY())<=7,"DUE — EARNINGS WINDOW",IF(I15<>"",IF(ABS(I15)>=0.2,"DUE — PRICE MOVE ±20%",IF(K15="Y","DUE — INSIDER ACTIVITY",IF(I15<>"",IF(ABS(I15)>=0.15,"WATCH — PRICE MOVE ±15%",IF(M15="Y","WATCH — ANALYST SHIFT","Monitor Only")),IF(M15="Y","WATCH — ANALYST SHIFT","Monitor Only")))),IF(K15="Y","DUE — INSIDER ACTIVITY",IF(I15<>"",IF(ABS(I15)>=0.15,"WATCH — PRICE MOVE ±15%",IF(M15="Y","WATCH — ANALYST SHIFT","Monitor Only")),IF(M15="Y","WATCH — ANALYST SHIFT","Monitor Only"))))),IF(I15<>"",IF(ABS(I15)>=0.2,"DUE — PRICE MOVE ±20%",IF(K15="Y","DUE — INSIDER ACTIVITY",IF(I15<>"",IF(ABS(I15)>=0.15,"WATCH — PRICE MOVE ±15%",IF(M15="Y","WATCH — ANALYST SHIFT","Monitor Only")),IF(M15="Y","WATCH — ANALYST SHIFT","Monitor Only")))),IF(K15="Y","DUE — INSIDER ACTIVITY",IF(I15<>"",IF(ABS(I15)>=0.15,"WATCH — PRICE MOVE ±15%",IF(M15="Y","WATCH — ANALYST SHIFT","Monitor Only")),IF(M15="Y","WATCH — ANALYST SHIFT","Monitor Only"))))))) -> Monitor Only | Q15: Re-scored 8/7/26: original Avoid was bad source data, corrected. See Journal. Re-scored 10/5/26 on the latest 10-Q figures (Journal row 92): Rule 3 cleared.
A16: AAP | B16: Tier-1 Avoid (external) | C16: 46246 | E16: 1.36 | G16: 53.52 | H16: {=IFERROR(INDEX(_xlfn.STOCKHISTORY(A16,TODAY()-5,TODAY(),0,0,1),ROWS(_xlfn.STOCKHISTORY(A16,TODAY()-5,TODAY(),0,0,1)),1),"")} -> 39.65 | I16: =IF(OR(G16="",H16=""),"",H16/G16-1) -> -0.25915546 | J16: 46331 | K16: N | M16: N | O16: =IF(C16="","",TODAY()-C16) -> 55 | P16: =IF(A16="","",IF(O16>180,"DUE — STALE (>180 days)",IF(J16<>"",IF(ABS(J16-TODAY())<=7,"DUE — EARNINGS WINDOW",IF(I16<>"",IF(ABS(I16)>=0.2,"DUE — PRICE MOVE ±20%",IF(K16="Y","DUE — INSIDER ACTIVITY",IF(I16<>"",IF(ABS(I16)>=0.15,"WATCH — PRICE MOVE ±15%",IF(M16="Y","WATCH — ANALYST SHIFT","Monitor Only")),IF(M16="Y","WATCH — ANALYST SHIFT","Monitor Only")))),IF(K16="Y","DUE — INSIDER ACTIVITY",IF(I16<>"",IF(ABS(I16)>=0.15,"WATCH — PRICE MOVE ±15%",IF(M16="Y","WATCH — ANALYST SHIFT","Monitor Only")),IF(M16="Y","WATCH — ANALYST SHIFT","Monitor Only"))))),IF(I16<>"",IF(ABS(I16)>=0.2,"DUE — PRICE MOVE ±20%",IF(K16="Y","DUE — INSIDER ACTIVITY",IF(I16<>"",IF(ABS(I16)>=0.15,"WATCH — PRICE MOVE ±15%",IF(M16="Y","WATCH — ANALYST SHIFT","Monitor Only")),IF(M16="Y","WATCH — ANALYST SHIFT","Monitor Only")))),IF(K16="Y","DUE — INSIDER ACTIVITY",IF(I16<>"",IF(ABS(I16)>=0.15,"WATCH — PRICE MOVE ±15%",IF(M16="Y","WATCH — ANALYST SHIFT","Monitor Only")),IF(M16="Y","WATCH — ANALYST SHIFT","Monitor Only"))))))) -> DUE — PRICE MOVE ±20%
A17: BABA | B17: Tier-1 Avoid (external) | C17: 46246 | E17: 2.79 | G17: 125.22 | H17: {=IFERROR(INDEX(_xlfn.STOCKHISTORY(A17,TODAY()-5,TODAY(),0,0,1),ROWS(_xlfn.STOCKHISTORY(A17,TODAY()-5,TODAY(),0,0,1)),1),"")} -> 110.8 | I17: =IF(OR(G17="",H17=""),"",H17/G17-1) -> -0.11515732 | J17: 46350 | K17: Y | L17: 2026-08-25: Tsai Joseph C (Other) bought $10,418,400, 1% of holding (+2 more in last 30d) | M17: N | O17: =IF(C17="","",TODAY()-C17) -> 55 | P17: =IF(A17="","",IF(O17>180,"DUE — STALE (>180 days)",IF(J17<>"",IF(ABS(J17-TODAY())<=7,"DUE — EARNINGS WINDOW",IF(I17<>"",IF(ABS(I17)>=0.2,"DUE — PRICE MOVE ±20%",IF(K17="Y","DUE — INSIDER ACTIVITY",IF(I17<>"",IF(ABS(I17)>=0.15,"WATCH — PRICE MOVE ±15%",IF(M17="Y","WATCH — ANALYST SHIFT","Monitor Only")),IF(M17="Y","WATCH — ANALYST SHIFT","Monitor Only")))),IF(K17="Y","DUE — INSIDER ACTIVITY",IF(I17<>"",IF(ABS(I17)>=0.15,"WATCH — PRICE MOVE ±15%",IF(M17="Y","WATCH — ANALYST SHIFT","Monitor Only")),IF(M17="Y","WATCH — ANALYST SHIFT","Monitor Only"))))),IF(I17<>"",IF(ABS(I17)>=0.2,"DUE — PRICE MOVE ±20%",IF(K17="Y","DUE — INSIDER ACTIVITY",IF(I17<>"",IF(ABS(I17)>=0.15,"WATCH — PRICE MOVE ±15%",IF(M17="Y","WATCH — ANALYST SHIFT","Monitor Only")),IF(M17="Y","WATCH — ANALYST SHIFT","Monitor Only")))),IF(K17="Y","DUE — INSIDER ACTIVITY",IF(I17<>"",IF(ABS(I17)>=0.15,"WATCH — PRICE MOVE ±15%",IF(M17="Y","WATCH — ANALYST SHIFT","Monitor Only")),IF(M17="Y","WATCH — ANALYST SHIFT","Monitor Only"))))))) -> DUE — INSIDER ACTIVITY
A18: CE | B18: Tier-1 Avoid (external) | C18: 46245 | E18: 1.79 | G18: 44.84 | H18: {=IFERROR(INDEX(_xlfn.STOCKHISTORY(A18,TODAY()-5,TODAY(),0,0,1),ROWS(_xlfn.STOCKHISTORY(A18,TODAY()-5,TODAY(),0,0,1)),1),"")} -> 45.53 | I18: =IF(OR(G18="",H18=""),"",H18/G18-1) -> 0.015388046 | J18: 46328 | K18: N | M18: N | O18: =IF(C18="","",TODAY()-C18) -> 56 | P18: =IF(A18="","",IF(O18>180,"DUE — STALE (>180 days)",IF(J18<>"",IF(ABS(J18-TODAY())<=7,"DUE — EARNINGS WINDOW",IF(I18<>"",IF(ABS(I18)>=0.2,"DUE — PRICE MOVE ±20%",IF(K18="Y","DUE — INSIDER ACTIVITY",IF(I18<>"",IF(ABS(I18)>=0.15,"WATCH — PRICE MOVE ±15%",IF(M18="Y","WATCH — ANALYST SHIFT","Monitor Only")),IF(M18="Y","WATCH — ANALYST SHIFT","Monitor Only")))),IF(K18="Y","DUE — INSIDER ACTIVITY",IF(I18<>"",IF(ABS(I18)>=0.15,"WATCH — PRICE MOVE ±15%",IF(M18="Y","WATCH — ANALYST SHIFT","Monitor Only")),IF(M18="Y","WATCH — ANALYST SHIFT","Monitor Only"))))),IF(I18<>"",IF(ABS(I18)>=0.2,"DUE — PRICE MOVE ±20%",IF(K18="Y","DUE — INSIDER ACTIVITY",IF(I18<>"",IF(ABS(I18)>=0.15,"WATCH — PRICE MOVE ±15%",IF(M18="Y","WATCH — ANALYST SHIFT","Monitor Only")),IF(M18="Y","WATCH — ANALYST SHIFT","Monitor Only")))),IF(K18="Y","DUE — INSIDER ACTIVITY",IF(I18<>"",IF(ABS(I18)>=0.15,"WATCH — PRICE MOVE ±15%",IF(M18="Y","WATCH — ANALYST SHIFT","Monitor Only")),IF(M18="Y","WATCH — ANALYST SHIFT","Monitor Only"))))))) -> Monitor Only
A19: CLF | B19: Tier-1 Avoid (external) | C19: 46245 | E19: 1.86 | G19: 12.41 | H19: {=IFERROR(INDEX(_xlfn.STOCKHISTORY(A19,TODAY()-5,TODAY(),0,0,1),ROWS(_xlfn.STOCKHISTORY(A19,TODAY()-5,TODAY(),0,0,1)),1),"")} -> 12.2 | I19: =IF(OR(G19="",H19=""),"",H19/G19-1) -> -0.016921837 | J19: 46314 | K19: N | M19: N | O19: =IF(C19="","",TODAY()-C19) -> 56 | P19: =IF(A19="","",IF(O19>180,"DUE — STALE (>180 days)",IF(J19<>"",IF(ABS(J19-TODAY())<=7,"DUE — EARNINGS WINDOW",IF(I19<>"",IF(ABS(I19)>=0.2,"DUE — PRICE MOVE ±20%",IF(K19="Y","DUE — INSIDER ACTIVITY",IF(I19<>"",IF(ABS(I19)>=0.15,"WATCH — PRICE MOVE ±15%",IF(M19="Y","WATCH — ANALYST SHIFT","Monitor Only")),IF(M19="Y","WATCH — ANALYST SHIFT","Monitor Only")))),IF(K19="Y","DUE — INSIDER ACTIVITY",IF(I19<>"",IF(ABS(I19)>=0.15,"WATCH — PRICE MOVE ±15%",IF(M19="Y","WATCH — ANALYST SHIFT","Monitor Only")),IF(M19="Y","WATCH — ANALYST SHIFT","Monitor Only"))))),IF(I19<>"",IF(ABS(I19)>=0.2,"DUE — PRICE MOVE ±20%",IF(K19="Y","DUE — INSIDER ACTIVITY",IF(I19<>"",IF(ABS(I19)>=0.15,"WATCH — PRICE MOVE ±15%",IF(M19="Y","WATCH — ANALYST SHIFT","Monitor Only")),IF(M19="Y","WATCH — ANALYST SHIFT","Monitor Only")))),IF(K19="Y","DUE — INSIDER ACTIVITY",IF(I19<>"",IF(ABS(I19)>=0.15,"WATCH — PRICE MOVE ±15%",IF(M19="Y","WATCH — ANALYST SHIFT","Monitor Only")),IF(M19="Y","WATCH — ANALYST SHIFT","Monitor Only"))))))) -> Monitor Only
A20: CMG | B20: Watch List | C20: 46245 | E20: 3.71 | G20: 32 | H20: {=IFERROR(INDEX(_xlfn.STOCKHISTORY(A20,TODAY()-5,TODAY(),0,0,1),ROWS(_xlfn.STOCKHISTORY(A20,TODAY()-5,TODAY(),0,0,1)),1),"")} -> 30.85 | I20: =IF(OR(G20="",H20=""),"",H20/G20-1) -> -0.0359375 | J20: 46323 | K20: N | M20: N | O20: =IF(C20="","",TODAY()-C20) -> 56 | P20: =IF(A20="","",IF(O20>180,"DUE — STALE (>180 days)",IF(J20<>"",IF(ABS(J20-TODAY())<=7,"DUE — EARNINGS WINDOW",IF(I20<>"",IF(ABS(I20)>=0.2,"DUE — PRICE MOVE ±20%",IF(K20="Y","DUE — INSIDER ACTIVITY",IF(I20<>"",IF(ABS(I20)>=0.15,"WATCH — PRICE MOVE ±15%",IF(M20="Y","WATCH — ANALYST SHIFT","Monitor Only")),IF(M20="Y","WATCH — ANALYST SHIFT","Monitor Only")))),IF(K20="Y","DUE — INSIDER ACTIVITY",IF(I20<>"",IF(ABS(I20)>=0.15,"WATCH — PRICE MOVE ±15%",IF(M20="Y","WATCH — ANALYST SHIFT","Monitor Only")),IF(M20="Y","WATCH — ANALYST SHIFT","Monitor Only"))))),IF(I20<>"",IF(ABS(I20)>=0.2,"DUE — PRICE MOVE ±20%",IF(K20="Y","DUE — INSIDER ACTIVITY",IF(I20<>"",IF(ABS(I20)>=0.15,"WATCH — PRICE MOVE ±15%",IF(M20="Y","WATCH — ANALYST SHIFT","Monitor Only")),IF(M20="Y","WATCH — ANALYST SHIFT","Monitor Only")))),IF(K20="Y","DUE — INSIDER ACTIVITY",IF(I20<>"",IF(ABS(I20)>=0.15,"WATCH — PRICE MOVE ±15%",IF(M20="Y","WATCH — ANALYST SHIFT","Monitor Only")),IF(M20="Y","WATCH — ANALYST SHIFT","Monitor Only"))))))) -> Monitor Only
A21: COST | B21: Watch List | C21: 46245 | D21: 77.4 | E21: 4.14 | F21: BUY | G21: 944.32 | H21: {=IFERROR(INDEX(_xlfn.STOCKHISTORY(A21,TODAY()-5,TODAY(),0,0,1),ROWS(_xlfn.STOCKHISTORY(A21,TODAY()-5,TODAY(),0,0,1)),1),"")} -> 923.52 | I21: =IF(OR(G21="",H21=""),"",H21/G21-1) -> -0.022026432 | J21: 46366 | K21: N | M21: N | O21: =IF(C21="","",TODAY()-C21) -> 56 | P21: =IF(A21="","",IF(O21>180,"DUE — STALE (>180 days)",IF(J21<>"",IF(ABS(J21-TODAY())<=7,"DUE — EARNINGS WINDOW",IF(I21<>"",IF(ABS(I21)>=0.2,"DUE — PRICE MOVE ±20%",IF(K21="Y","DUE — INSIDER ACTIVITY",IF(I21<>"",IF(ABS(I21)>=0.15,"WATCH — PRICE MOVE ±15%",IF(M21="Y","WATCH — ANALYST SHIFT","Monitor Only")),IF(M21="Y","WATCH — ANALYST SHIFT","Monitor Only")))),IF(K21="Y","DUE — INSIDER ACTIVITY",IF(I21<>"",IF(ABS(I21)>=0.15,"WATCH — PRICE MOVE ±15%",IF(M21="Y","WATCH — ANALYST SHIFT","Monitor Only")),IF(M21="Y","WATCH — ANALYST SHIFT","Monitor Only"))))),IF(I21<>"",IF(ABS(I21)>=0.2,"DUE — PRICE MOVE ±20%",IF(K21="Y","DUE — INSIDER ACTIVITY",IF(I21<>"",IF(ABS(I21)>=0.15,"WATCH — PRICE MOVE ±15%",IF(M21="Y","WATCH — ANALYST SHIFT","Monitor Only")),IF(M21="Y","WATCH — ANALYST SHIFT","Monitor Only")))),IF(K21="Y","DUE — INSIDER ACTIVITY",IF(I21<>"",IF(ABS(I21)>=0.15,"WATCH — PRICE MOVE ±15%",IF(M21="Y","WATCH — ANALYST SHIFT","Monitor Only")),IF(M21="Y","WATCH — ANALYST SHIFT","Monitor Only"))))))) -> Monitor Only
A22: CRK | B22: Tier-1 Avoid (external) | C22: 46245 | E22: 1.21 | G22: 14.39 | H22: {=IFERROR(INDEX(_xlfn.STOCKHISTORY(A22,TODAY()-5,TODAY(),0,0,1),ROWS(_xlfn.STOCKHISTORY(A22,TODAY()-5,TODAY(),0,0,1)),1),"")} -> 13.06 | I22: =IF(OR(G22="",H22=""),"",H22/G22-1) -> -0.092425295 | J22: 46328 | K22: N | M22: N | O22: =IF(C22="","",TODAY()-C22) -> 56 | P22: =IF(A22="","",IF(O22>180,"DUE — STALE (>180 days)",IF(J22<>"",IF(ABS(J22-TODAY())<=7,"DUE — EARNINGS WINDOW",IF(I22<>"",IF(ABS(I22)>=0.2,"DUE — PRICE MOVE ±20%",IF(K22="Y","DUE — INSIDER ACTIVITY",IF(I22<>"",IF(ABS(I22)>=0.15,"WATCH — PRICE MOVE ±15%",IF(M22="Y","WATCH — ANALYST SHIFT","Monitor Only")),IF(M22="Y","WATCH — ANALYST SHIFT","Monitor Only")))),IF(K22="Y","DUE — INSIDER ACTIVITY",IF(I22<>"",IF(ABS(I22)>=0.15,"WATCH — PRICE MOVE ±15%",IF(M22="Y","WATCH — ANALYST SHIFT","Monitor Only")),IF(M22="Y","WATCH — ANALYST SHIFT","Monitor Only"))))),IF(I22<>"",IF(ABS(I22)>=0.2,"DUE — PRICE MOVE ±20%",IF(K22="Y","DUE — INSIDER ACTIVITY",IF(I22<>"",IF(ABS(I22)>=0.15,"WATCH — PRICE MOVE ±15%",IF(M22="Y","WATCH — ANALYST SHIFT","Monitor Only")),IF(M22="Y","WATCH — ANALYST SHIFT","Monitor Only")))),IF(K22="Y","DUE — INSIDER ACTIVITY",IF(I22<>"",IF(ABS(I22)>=0.15,"WATCH — PRICE MOVE ±15%",IF(M22="Y","WATCH — ANALYST SHIFT","Monitor Only")),IF(M22="Y","WATCH — ANALYST SHIFT","Monitor Only"))))))) -> Monitor Only
A23: DEO | B23: Tier-1 Avoid (external) | C23: 46245 | E23: 2.36 | G23: 94.94 | H23: {=IFERROR(INDEX(_xlfn.STOCKHISTORY(A23,TODAY()-5,TODAY(),0,0,1),ROWS(_xlfn.STOCKHISTORY(A23,TODAY()-5,TODAY(),0,0,1)),1),"")} -> 83.97 | I23: =IF(OR(G23="",H23=""),"",H23/G23-1) -> -0.11554666 | J23: 46240 | K23: N | M23: N | O23: =IF(C23="","",TODAY()-C23) -> 56 | P23: =IF(A23="","",IF(O23>180,"DUE — STALE (>180 days)",IF(J23<>"",IF(ABS(J23-TODAY())<=7,"DUE — EARNINGS WINDOW",IF(I23<>"",IF(ABS(I23)>=0.2,"DUE — PRICE MOVE ±20%",IF(K23="Y","DUE — INSIDER ACTIVITY",IF(I23<>"",IF(ABS(I23)>=0.15,"WATCH — PRICE MOVE ±15%",IF(M23="Y","WATCH — ANALYST SHIFT","Monitor Only")),IF(M23="Y","WATCH — ANALYST SHIFT","Monitor Only")))),IF(K23="Y","DUE — INSIDER ACTIVITY",IF(I23<>"",IF(ABS(I23)>=0.15,"WATCH — PRICE MOVE ±15%",IF(M23="Y","WATCH — ANALYST SHIFT","Monitor Only")),IF(M23="Y","WATCH — ANALYST SHIFT","Monitor Only"))))),IF(I23<>"",IF(ABS(I23)>=0.2,"DUE — PRICE MOVE ±20%",IF(K23="Y","DUE — INSIDER ACTIVITY",IF(I23<>"",IF(ABS(I23)>=0.15,"WATCH — PRICE MOVE ±15%",IF(M23="Y","WATCH — ANALYST SHIFT","Monitor Only")),IF(M23="Y","WATCH — ANALYST SHIFT","Monitor Only")))),IF(K23="Y","DUE — INSIDER ACTIVITY",IF(I23<>"",IF(ABS(I23)>=0.15,"WATCH — PRICE MOVE ±15%",IF(M23="Y","WATCH — ANALYST SHIFT","Monitor Only")),IF(M23="Y","WATCH — ANALYST SHIFT","Monitor Only"))))))) -> Monitor Only
